<?xml version="1.0" ?>
<sdf version="1.7">
	<model name="mirror_cube_2x2">
		<link name="center"/>
		<link name="cubie_0_0_0">
			<pose>-0.00755 -0.01255 -0.017550000000000003 0.0 0.0 0.0</pose>
			<inertial>
				<mass>0.005118750000000002</mass>
				<inertia>
					<ixx>7.891406250000004e-07</ixx>
					<ixy>0.0</ixy>
					<ixz>0.0</ixz>
					<iyy>6.185156250000003e-07</iyy>
					<iyz>0.0</iyz>
					<izz>3.625781250000002e-07</izz>
				</inertia>
			</inertial>
			<collision name="collision">
				<geometry>
					<box>
						<size>0.015000000000000001 0.025 0.035</size>
					</box>
				</geometry>
				<surface>
					<friction>
						<ode>
							<mu>0.6</mu>
							<mu2>0.6</mu2>
						</ode>
					</friction>
				</surface>
			</collision>
			<visual name="black">
				<geometry>
					<box>
						<size>0.015000000000000001 0.025 0.035</size>
					</box>
				</geometry>
				<material>
					<diffuse>0 0 0 1</diffuse>
				</material>
			</visual>
			<visual name="red">
				<pose>-0.007500000000000001 0.0 0.0 0.0 0.0 0.0</pose>
				<geometry>
					<box>
						<size>0.0001 0.02 0.03</size>
					</box>
				</geometry>
				<material>
					<diffuse>1 0 0 1</diffuse>
				</material>
			</visual>
			<visual name="green">
				<pose>0.0 -0.0125 0.0 0.0 0.0 0.0</pose>
				<geometry>
					<box>
						<size>0.01 0.0002 0.03</size>
					</box>
				</geometry>
				<material>
					<diffuse>0 1 0 1</diffuse>
				</material>
			</visual>
			<visual name="white">
				<pose>0.0 0.0 -0.0175 0.0 0.0 0.0</pose>
				<geometry>
					<box>
						<size>0.01 0.02 0.0003</size>
					</box>
				</geometry>
				<material>
					<diffuse>1 1 1 1</diffuse>
				</material>
			</visual>
		</link>
		<joint name="ball_0_0_0" type="ball">
			<pose>0.00755 0.01255 0.017550000000000003 -0.0 -0.0 -0.0</pose>
			<parent>center</parent>
			<child>cubie_0_0_0</child>
			<axis>
				<dynamics>
					<damping>0.1</damping>
				</dynamics>
				<limit>
					<effort>0</effort>
				</limit>
			</axis>
		</joint>
		<link name="cubie_0_0_1">
			<pose>-0.00755 -0.01255 0.007549999999999999 0.0 0.0 0.0</pose>
			<inertial>
				<mass>0.00219375</mass>
				<inertia>
					<ixx>1.55390625e-07</ixx>
					<ixy>0.0</ixy>
					<ixz>0.0</ixz>
					<iyy>8.2265625e-08</iyy>
					<iyz>0.0</iyz>
					<izz>1.5539062500000003e-07</izz>
				</inertia>
			</inertial>
			<collision name="collision">
				<geometry>
					<box>
						<size>0.015000000000000001 0.025 0.015</size>
					</box>
				</geometry>
				<surface>
					<friction>
						<ode>
							<mu>0.6</mu>
							<mu2>0.6</mu2>
						</ode>
					</friction>
				</surface>
			</collision>
			<visual name="black">
				<geometry>
					<box>
						<size>0.015000000000000001 0.025 0.015</size>
					</box>
				</geometry>
				<material>
					<diffuse>0 0 0 1</diffuse>
				</material>
			</visual>
			<visual name="red">
				<pose>-0.007500000000000001 0.0 0.0 0.0 0.0 0.0</pose>
				<geometry>
					<box>
						<size>0.0001 0.02 0.01</size>
					</box>
				</geometry>
				<material>
					<diffuse>1 0 0 1</diffuse>
				</material>
			</visual>
			<visual name="green">
				<pose>0.0 -0.0125 0.0 0.0 0.0 0.0</pose>
				<geometry>
					<box>
						<size>0.01 0.0002 0.01</size>
					</box>
				</geometry>
				<material>
					<diffuse>0 1 0 1</diffuse>
				</material>
			</visual>
			<visual name="yellow">
				<pose>0.0 0.0 0.0075 0.0 0.0 0.0</pose>
				<geometry>
					<box>
						<size>0.01 0.02 0.0001</size>
					</box>
				</geometry>
				<material>
					<diffuse>1 1 0 1</diffuse>
				</material>
			</visual>
		</link>
		<joint name="ball_0_0_1" type="ball">
			<pose>0.00755 0.01255 -0.007549999999999999 -0.0 -0.0 -0.0</pose>
			<parent>center</parent>
			<child>cubie_0_0_1</child>
			<axis>
				<dynamics>
					<damping>0.1</damping>
				</dynamics>
				<limit>
					<effort>0</effort>
				</limit>
			</axis>
		</joint>
		<link name="cubie_0_1_0">
			<pose>-0.00755 0.01255 -0.017550000000000003 0.0 0.0 0.0</pose>
			<inertial>
				<mass>0.005118750000000002</mass>
				<inertia>
					<ixx>7.891406250000004e-07</ixx>
					<ixy>0.0</ixy>
					<ixz>0.0</ixz>
					<iyy>6.185156250000003e-07</iyy>
					<iyz>0.0</iyz>
					<izz>3.625781250000002e-07</izz>
				</inertia>
			</inertial>
			<collision name="collision">
				<geometry>
					<box>
						<size>0.015000000000000001 0.025 0.035</size>
					</box>
				</geometry>
				<surface>
					<friction>
						<ode>
							<mu>0.6</mu>
							<mu2>0.6</mu2>
						</ode>
					</friction>
				</surface>
			</collision>
			<visual name="black">
				<geometry>
					<box>
						<size>0.015000000000000001 0.025 0.035</size>
					</box>
				</geometry>
				<material>
					<diffuse>0 0 0 1</diffuse>
				</material>
			</visual>
			<visual name="red">
				<pose>-0.007500000000000001 0.0 0.0 0.0 0.0 0.0</pose>
				<geometry>
					<box>
						<size>0.0001 0.02 0.03</size>
					</box>
				</geometry>
				<material>
					<diffuse>1 0 0 1</diffuse>
				</material>
			</visual>
			<visual name="blue">
				<pose>0.0 0.0125 0.0 0.0 0.0 0.0</pose>
				<geometry>
					<box>
						<size>0.01 0.0002 0.03</size>
					</box>
				</geometry>
				<material>
					<diffuse>0 0 1 1</diffuse>
				</material>
			</visual>
			<visual name="white">
				<pose>0.0 0.0 -0.0175 0.0 0.0 0.0</pose>
				<geometry>
					<box>
						<size>0.01 0.02 0.0003</size>
					</box>
				</geometry>
				<material>
					<diffuse>1 1 1 1</diffuse>
				</material>
			</visual>
		</link>
		<joint name="ball_0_1_0" type="ball">
			<pose>0.00755 -0.01255 0.017550000000000003 -0.0 -0.0 -0.0</pose>
			<parent>center</parent>
			<child>cubie_0_1_0</child>
			<axis>
				<dynamics>
					<damping>0.1</damping>
				</dynamics>
				<limit>
					<effort>0</effort>
				</limit>
			</axis>
		</joint>
		<link name="cubie_0_1_1">
			<pose>-0.00755 0.01255 0.007549999999999999 0.0 0.0 0.0</pose>
			<inertial>
				<mass>0.00219375</mass>
				<inertia>
					<ixx>1.55390625e-07</ixx>
					<ixy>0.0</ixy>
					<ixz>0.0</ixz>
					<iyy>8.2265625e-08</iyy>
					<iyz>0.0</iyz>
					<izz>1.5539062500000003e-07</izz>
				</inertia>
			</inertial>
			<collision name="collision">
				<geometry>
					<box>
						<size>0.015000000000000001 0.025 0.015</size>
					</box>
				</geometry>
				<surface>
					<friction>
						<ode>
							<mu>0.6</mu>
							<mu2>0.6</mu2>
						</ode>
					</friction>
				</surface>
			</collision>
			<visual name="black">
				<geometry>
					<box>
						<size>0.015000000000000001 0.025 0.015</size>
					</box>
				</geometry>
				<material>
					<diffuse>0 0 0 1</diffuse>
				</material>
			</visual>
			<visual name="red">
				<pose>-0.007500000000000001 0.0 0.0 0.0 0.0 0.0</pose>
				<geometry>
					<box>
						<size>0.0001 0.02 0.01</size>
					</box>
				</geometry>
				<material>
					<diffuse>1 0 0 1</diffuse>
				</material>
			</visual>
			<visual name="blue">
				<pose>0.0 0.0125 0.0 0.0 0.0 0.0</pose>
				<geometry>
					<box>
						<size>0.01 0.0002 0.01</size>
					</box>
				</geometry>
				<material>
					<diffuse>0 0 1 1</diffuse>
				</material>
			</visual>
			<visual name="yellow">
				<pose>0.0 0.0 0.0075 0.0 0.0 0.0</pose>
				<geometry>
					<box>
						<size>0.01 0.02 0.0001</size>
					</box>
				</geometry>
				<material>
					<diffuse>1 1 0 1</diffuse>
				</material>
			</visual>
		</link>
		<joint name="ball_0_1_1" type="ball">
			<pose>0.00755 -0.01255 -0.007549999999999999 -0.0 -0.0 -0.0</pose>
			<parent>center</parent>
			<child>cubie_0_1_1</child>
			<axis>
				<dynamics>
					<damping>0.1</damping>
				</dynamics>
				<limit>
					<effort>0</effort>
				</limit>
			</axis>
		</joint>
		<link name="cubie_1_0_0">
			<pose>0.017550000000000003 -0.01255 -0.017550000000000003 0.0 0.0 0.0</pose>
			<inertial>
				<mass>0.011943750000000003</mass>
				<inertia>
					<ixx>1.841328125000001e-06</ixx>
					<ixy>0.0</ixy>
					<ixz>0.0</ixz>
					<iyy>2.438515625000001e-06</iyy>
					<iyz>0.0</iyz>
					<izz>1.841328125000001e-06</izz>
				</inertia>
			</inertial>
			<collision name="collision">
				<geometry>
					<box>
						<size>0.035 0.025 0.035</size>
					</box>
				</geometry>
				<surface>
					<friction>
						<ode>
							<mu>0.6</mu>
							<mu2>0.6</mu2>
						</ode>
					</friction>
				</surface>
			</collision>
			<visual name="black">
				<geometry>
					<box>
						<size>0.035 0.025 0.035</size>
					</box>
				</geometry>
				<material>
					<diffuse>0 0 0 1</diffuse>
				</material>
			</visual>
			<visual name="orange">
				<pose>0.0175 0.0 0.0 0.0 0.0 0.0</pose>
				<geometry>
					<box>
						<size>0.0003 0.02 0.03</size>
					</box>
				</geometry>
				<material>
					<diffuse>1.0 0.5 0.0 1.0</diffuse>
				</material>
			</visual>
			<visual name="green">
				<pose>0.0 -0.0125 0.0 0.0 0.0 0.0</pose>
				<geometry>
					<box>
						<size>0.03 0.0002 0.03</size>
					</box>
				</geometry>
				<material>
					<diffuse>0 1 0 1</diffuse>
				</material>
			</visual>
			<visual name="white">
				<pose>0.0 0.0 -0.0175 0.0 0.0 0.0</pose>
				<geometry>
					<box>
						<size>0.03 0.02 0.0003</size>
					</box>
				</geometry>
				<material>
					<diffuse>1 1 1 1</diffuse>
				</material>
			</visual>
		</link>
		<joint name="ball_1_0_0" type="ball">
			<pose>-0.017550000000000003 0.01255 0.017550000000000003 -0.0 -0.0 -0.0</pose>
			<parent>center</parent>
			<child>cubie_1_0_0</child>
			<axis>
				<dynamics>
					<damping>0.1</damping>
				</dynamics>
				<limit>
					<effort>0</effort>
				</limit>
			</axis>
		</joint>
		<link name="cubie_1_0_1">
			<pose>0.017550000000000003 -0.01255 0.007549999999999999 0.0 0.0 0.0</pose>
			<inertial>
				<mass>0.005118750000000001</mass>
				<inertia>
					<ixx>3.625781250000001e-07</ixx>
					<ixy>0.0</ixy>
					<ixz>0.0</ixz>
					<iyy>6.185156250000001e-07</iyy>
					<iyz>0.0</iyz>
					<izz>7.891406250000003e-07</izz>
				</inertia>
			</inertial>
			<collision name="collision">
				<geometry>
					<box>
						<size>0.035 0.025 0.015</size>
					</box>
				</geometry>
				<surface>
					<friction>
						<ode>
							<mu>0.6</mu>
							<mu2>0.6</mu2>
						</ode>
					</friction>
				</surface>
			</collision>
			<visual name="black">
				<geometry>
					<box>
						<size>0.035 0.025 0.015</size>
					</box>
				</geometry>
				<material>
					<diffuse>0 0 0 1</diffuse>
				</material>
			</visual>
			<visual name="orange">
				<pose>0.0175 0.0 0.0 0.0 0.0 0.0</pose>
				<geometry>
					<box>
						<size>0.0003 0.02 0.01</size>
					</box>
				</geometry>
				<material>
					<diffuse>1.0 0.5 0.0 1.0</diffuse>
				</material>
			</visual>
			<visual name="green">
				<pose>0.0 -0.0125 0.0 0.0 0.0 0.0</pose>
				<geometry>
					<box>
						<size>0.03 0.0002 0.01</size>
					</box>
				</geometry>
				<material>
					<diffuse>0 1 0 1</diffuse>
				</material>
			</visual>
			<visual name="yellow">
				<pose>0.0 0.0 0.0075 0.0 0.0 0.0</pose>
				<geometry>
					<box>
						<size>0.03 0.02 0.0001</size>
					</box>
				</geometry>
				<material>
					<diffuse>1 1 0 1</diffuse>
				</material>
			</visual>
		</link>
		<joint name="ball_1_0_1" type="ball">
			<pose>-0.017550000000000003 0.01255 -0.007549999999999999 -0.0 -0.0 -0.0</pose>
			<parent>center</parent>
			<child>cubie_1_0_1</child>
			<axis>
				<dynamics>
					<damping>0.1</damping>
				</dynamics>
				<limit>
					<effort>0</effort>
				</limit>
			</axis>
		</joint>
		<link name="cubie_1_1_0">
			<pose>0.017550000000000003 0.01255 -0.017550000000000003 0.0 0.0 0.0</pose>
			<inertial>
				<mass>0.011943750000000003</mass>
				<inertia>
					<ixx>1.841328125000001e-06</ixx>
					<ixy>0.0</ixy>
					<ixz>0.0</ixz>
					<iyy>2.438515625000001e-06</iyy>
					<iyz>0.0</iyz>
					<izz>1.841328125000001e-06</izz>
				</inertia>
			</inertial>
			<collision name="collision">
				<geometry>
					<box>
						<size>0.035 0.025 0.035</size>
					</box>
				</geometry>
				<surface>
					<friction>
						<ode>
							<mu>0.6</mu>
							<mu2>0.6</mu2>
						</ode>
					</friction>
				</surface>
			</collision>
			<visual name="black">
				<geometry>
					<box>
						<size>0.035 0.025 0.035</size>
					</box>
				</geometry>
				<material>
					<diffuse>0 0 0 1</diffuse>
				</material>
			</visual>
			<visual name="orange">
				<pose>0.0175 0.0 0.0 0.0 0.0 0.0</pose>
				<geometry>
					<box>
						<size>0.0003 0.02 0.03</size>
					</box>
				</geometry>
				<material>
					<diffuse>1.0 0.5 0.0 1.0</diffuse>
				</material>
			</visual>
			<visual name="blue">
				<pose>0.0 0.0125 0.0 0.0 0.0 0.0</pose>
				<geometry>
					<box>
						<size>0.03 0.0002 0.03</size>
					</box>
				</geometry>
				<material>
					<diffuse>0 0 1 1</diffuse>
				</material>
			</visual>
			<visual name="white">
				<pose>0.0 0.0 -0.0175 0.0 0.0 0.0</pose>
				<geometry>
					<box>
						<size>0.03 0.02 0.0003</size>
					</box>
				</geometry>
				<material>
					<diffuse>1 1 1 1</diffuse>
				</material>
			</visual>
		</link>
		<joint name="ball_1_1_0" type="ball">
			<pose>-0.017550000000000003 -0.01255 0.017550000000000003 -0.0 -0.0 -0.0</pose>
			<parent>center</parent>
			<child>cubie_1_1_0</child>
			<axis>
				<dynamics>
					<damping>0.1</damping>
				</dynamics>
				<limit>
					<effort>0</effort>
				</limit>
			</axis>
		</joint>
		<link name="cubie_1_1_1">
			<pose>0.017550000000000003 0.01255 0.007549999999999999 0.0 0.0 0.0</pose>
			<inertial>
				<mass>0.005118750000000001</mass>
				<inertia>
					<ixx>3.625781250000001e-07</ixx>
					<ixy>0.0</ixy>
					<ixz>0.0</ixz>
					<iyy>6.185156250000001e-07</iyy>
					<iyz>0.0</iyz>
					<izz>7.891406250000003e-07</izz>
				</inertia>
			</inertial>
			<collision name="collision">
				<geometry>
					<box>
						<size>0.035 0.025 0.015</size>
					</box>
				</geometry>
				<surface>
					<friction>
						<ode>
							<mu>0.6</mu>
							<mu2>0.6</mu2>
						</ode>
					</friction>
				</surface>
			</collision>
			<visual name="black">
				<geometry>
					<box>
						<size>0.035 0.025 0.015</size>
					</box>
				</geometry>
				<material>
					<diffuse>0 0 0 1</diffuse>
				</material>
			</visual>
			<visual name="orange">
				<pose>0.0175 0.0 0.0 0.0 0.0 0.0</pose>
				<geometry>
					<box>
						<size>0.0003 0.02 0.01</size>
					</box>
				</geometry>
				<material>
					<diffuse>1.0 0.5 0.0 1.0</diffuse>
				</material>
			</visual>
			<visual name="blue">
				<pose>0.0 0.0125 0.0 0.0 0.0 0.0</pose>
				<geometry>
					<box>
						<size>0.03 0.0002 0.01</size>
					</box>
				</geometry>
				<material>
					<diffuse>0 0 1 1</diffuse>
				</material>
			</visual>
			<visual name="yellow">
				<pose>0.0 0.0 0.0075 0.0 0.0 0.0</pose>
				<geometry>
					<box>
						<size>0.03 0.02 0.0001</size>
					</box>
				</geometry>
				<material>
					<diffuse>1 1 0 1</diffuse>
				</material>
			</visual>
		</link>
		<joint name="ball_1_1_1" type="ball">
			<pose>-0.017550000000000003 -0.01255 -0.007549999999999999 -0.0 -0.0 -0.0</pose>
			<parent>center</parent>
			<child>cubie_1_1_1</child>
			<axis>
				<dynamics>
					<damping>0.1</damping>
				</dynamics>
				<limit>
					<effort>0</effort>
				</limit>
			</axis>
		</joint>
	</model>
</sdf>
