<?xml version="1.0" ?>
<sdf version="1.7">
	<model name="mirror_cube_2x2">
		<link name="center"/>
		<link name="cubie_0_0_0">
			<pose>-0.005050000000000001 -0.01255 -0.020050000000000002 0.0 0.0 0.0</pose>
			<inertial>
				<mass>0.003900000000000001</mass>
				<inertia>
					<ixx>7.231250000000004e-07</ixx>
					<ixy>0.0</ixy>
					<ixz>0.0</ixz>
					<iyy>5.525000000000002e-07</iyy>
					<iyz>0.0</iyz>
					<izz>2.3562500000000013e-07</izz>
				</inertia>
			</inertial>
			<collision name="collision">
				<geometry>
					<box>
						<size>0.010000000000000002 0.025 0.04</size>
					</box>
				</geometry>
				<surface>
					<friction>
						<ode>
							<mu>0.6</mu>
							<mu2>0.6</mu2>
						</ode>
					</friction>
				</surface>
			</collision>
			<visual name="black">
				<geometry>
					<box>
						<size>0.010000000000000002 0.025 0.04</size>
					</box>
				</geometry>
				<material>
					<diffuse>0 0 0 1</diffuse>
				</material>
			</visual>
			<visual name="red">
				<pose>-0.005000000000000001 0.0 0.0 0.0 0.0 0.0</pose>
				<geometry>
					<box>
						<size>5e-05 0.02 0.035</size>
					</box>
				</geometry>
				<material>
					<diffuse>1 0 0 1</diffuse>
				</material>
			</visual>
			<visual name="green">
				<pose>0.0 -0.0125 0.0 0.0 0.0 0.0</pose>
				<geometry>
					<box>
						<size>0.005 0.0002 0.035</size>
					</box>
				</geometry>
				<material>
					<diffuse>0 1 0 1</diffuse>
				</material>
			</visual>
			<visual name="white">
				<pose>0.0 0.0 -0.02 0.0 0.0 0.0</pose>
				<geometry>
					<box>
						<size>0.005 0.02 0.00035</size>
					</box>
				</geometry>
				<material>
					<diffuse>1 1 1 1</diffuse>
				</material>
			</visual>
		</link>
		<joint name="ball_0_0_0" type="ball">
			<pose>0.005050000000000001 0.01255 0.020050000000000002 -0.0 -0.0 -0.0</pose>
			<parent>center</parent>
			<child>cubie_0_0_0</child>
			<axis>
				<dynamics>
					<damping>0.1</damping>
				</dynamics>
				<limit>
					<effort>0</effort>
				</limit>
			</axis>
		</joint>
		<link name="cubie_0_0_1">
			<pose>-0.005050000000000001 -0.01255 0.005050000000000001 0.0 0.0 0.0</pose>
			<inertial>
				<mass>0.0009750000000000004</mass>
				<inertia>
					<ixx>5.890625000000004e-08</ixx>
					<ixy>0.0</ixy>
					<ixz>0.0</ixz>
					<iyy>1.6250000000000013e-08</iyy>
					<iyz>0.0</iyz>
					<izz>5.890625000000004e-08</izz>
				</inertia>
			</inertial>
			<collision name="collision">
				<geometry>
					<box>
						<size>0.010000000000000002 0.025 0.010000000000000002</size>
					</box>
				</geometry>
				<surface>
					<friction>
						<ode>
							<mu>0.6</mu>
							<mu2>0.6</mu2>
						</ode>
					</friction>
				</surface>
			</collision>
			<visual name="black">
				<geometry>
					<box>
						<size>0.010000000000000002 0.025 0.010000000000000002</size>
					</box>
				</geometry>
				<material>
					<diffuse>0 0 0 1</diffuse>
				</material>
			</visual>
			<visual name="red">
				<pose>-0.005000000000000001 0.0 0.0 0.0 0.0 0.0</pose>
				<geometry>
					<box>
						<size>5e-05 0.02 0.005</size>
					</box>
				</geometry>
				<material>
					<diffuse>1 0 0 1</diffuse>
				</material>
			</visual>
			<visual name="green">
				<pose>0.0 -0.0125 0.0 0.0 0.0 0.0</pose>
				<geometry>
					<box>
						<size>0.005 0.0002 0.005</size>
					</box>
				</geometry>
				<material>
					<diffuse>0 1 0 1</diffuse>
				</material>
			</visual>
			<visual name="yellow">
				<pose>0.0 0.0 0.005000000000000001 0.0 0.0 0.0</pose>
				<geometry>
					<box>
						<size>0.005 0.02 5e-05</size>
					</box>
				</geometry>
				<material>
					<diffuse>1 1 0 1</diffuse>
				</material>
			</visual>
		</link>
		<joint name="ball_0_0_1" type="ball">
			<pose>0.005050000000000001 0.01255 -0.005050000000000001 -0.0 -0.0 -0.0</pose>
			<parent>center</parent>
			<child>cubie_0_0_1</child>
			<axis>
				<dynamics>
					<damping>0.1</damping>
				</dynamics>
				<limit>
					<effort>0</effort>
				</limit>
			</axis>
		</joint>
		<link name="cubie_0_1_0">
			<pose>-0.005050000000000001 0.01255 -0.020050000000000002 0.0 0.0 0.0</pose>
			<inertial>
				<mass>0.003900000000000001</mass>
				<inertia>
					<ixx>7.231250000000004e-07</ixx>
					<ixy>0.0</ixy>
					<ixz>0.0</ixz>
					<iyy>5.525000000000002e-07</iyy>
					<iyz>0.0</iyz>
					<izz>2.3562500000000013e-07</izz>
				</inertia>
			</inertial>
			<collision name="collision">
				<geometry>
					<box>
						<size>0.010000000000000002 0.025 0.04</size>
					</box>
				</geometry>
				<surface>
					<friction>
						<ode>
							<mu>0.6</mu>
							<mu2>0.6</mu2>
						</ode>
					</friction>
				</surface>
			</collision>
			<visual name="black">
				<geometry>
					<box>
						<size>0.010000000000000002 0.025 0.04</size>
					</box>
				</geometry>
				<material>
					<diffuse>0 0 0 1</diffuse>
				</material>
			</visual>
			<visual name="red">
				<pose>-0.005000000000000001 0.0 0.0 0.0 0.0 0.0</pose>
				<geometry>
					<box>
						<size>5e-05 0.02 0.035</size>
					</box>
				</geometry>
				<material>
					<diffuse>1 0 0 1</diffuse>
				</material>
			</visual>
			<visual name="blue">
				<pose>0.0 0.0125 0.0 0.0 0.0 0.0</pose>
				<geometry>
					<box>
						<size>0.005 0.0002 0.035</size>
					</box>
				</geometry>
				<material>
					<diffuse>0 0 1 1</diffuse>
				</material>
			</visual>
			<visual name="white">
				<pose>0.0 0.0 -0.02 0.0 0.0 0.0</pose>
				<geometry>
					<box>
						<size>0.005 0.02 0.00035</size>
					</box>
				</geometry>
				<material>
					<diffuse>1 1 1 1</diffuse>
				</material>
			</visual>
		</link>
		<joint name="ball_0_1_0" type="ball">
			<pose>0.005050000000000001 -0.01255 0.020050000000000002 -0.0 -0.0 -0.0</pose>
			<parent>center</parent>
			<child>cubie_0_1_0</child>
			<axis>
				<dynamics>
					<damping>0.1</damping>
				</dynamics>
				<limit>
					<effort>0</effort>
				</limit>
			</axis>
		</joint>
		<link name="cubie_0_1_1">
			<pose>-0.005050000000000001 0.01255 0.005050000000000001 0.0 0.0 0.0</pose>
			<inertial>
				<mass>0.0009750000000000004</mass>
				<inertia>
					<ixx>5.890625000000004e-08</ixx>
					<ixy>0.0</ixy>
					<ixz>0.0</ixz>
					<iyy>1.6250000000000013e-08</iyy>
					<iyz>0.0</iyz>
					<izz>5.890625000000004e-08</izz>
				</inertia>
			</inertial>
			<collision name="collision">
				<geometry>
					<box>
						<size>0.010000000000000002 0.025 0.010000000000000002</size>
					</box>
				</geometry>
				<surface>
					<friction>
						<ode>
							<mu>0.6</mu>
							<mu2>0.6</mu2>
						</ode>
					</friction>
				</surface>
			</collision>
			<visual name="black">
				<geometry>
					<box>
						<size>0.010000000000000002 0.025 0.010000000000000002</size>
					</box>
				</geometry>
				<material>
					<diffuse>0 0 0 1</diffuse>
				</material>
			</visual>
			<visual name="red">
				<pose>-0.005000000000000001 0.0 0.0 0.0 0.0 0.0</pose>
				<geometry>
					<box>
						<size>5e-05 0.02 0.005</size>
					</box>
				</geometry>
				<material>
					<diffuse>1 0 0 1</diffuse>
				</material>
			</visual>
			<visual name="blue">
				<pose>0.0 0.0125 0.0 0.0 0.0 0.0</pose>
				<geometry>
					<box>
						<size>0.005 0.0002 0.005</size>
					</box>
				</geometry>
				<material>
					<diffuse>0 0 1 1</diffuse>
				</material>
			</visual>
			<visual name="yellow">
				<pose>0.0 0.0 0.005000000000000001 0.0 0.0 0.0</pose>
				<geometry>
					<box>
						<size>0.005 0.02 5e-05</size>
					</box>
				</geometry>
				<material>
					<diffuse>1 1 0 1</diffuse>
				</material>
			</visual>
		</link>
		<joint name="ball_0_1_1" type="ball">
			<pose>0.005050000000000001 -0.01255 -0.005050000000000001 -0.0 -0.0 -0.0</pose>
			<parent>center</parent>
			<child>cubie_0_1_1</child>
			<axis>
				<dynamics>
					<damping>0.1</damping>
				</dynamics>
				<limit>
					<effort>0</effort>
				</limit>
			</axis>
		</joint>
		<link name="cubie_1_0_0">
			<pose>0.020050000000000002 -0.01255 -0.020050000000000002 0.0 0.0 0.0</pose>
			<inertial>
				<mass>0.015600000000000001</mass>
				<inertia>
					<ixx>2.8925000000000007e-06</ixx>
					<ixy>0.0</ixy>
					<ixz>0.0</ixz>
					<iyy>4.160000000000001e-06</iyy>
					<iyz>0.0</iyz>
					<izz>2.8925000000000007e-06</izz>
				</inertia>
			</inertial>
			<collision name="collision">
				<geometry>
					<box>
						<size>0.04 0.025 0.04</size>
					</box>
				</geometry>
				<surface>
					<friction>
						<ode>
							<mu>0.6</mu>
							<mu2>0.6</mu2>
						</ode>
					</friction>
				</surface>
			</collision>
			<visual name="black">
				<geometry>
					<box>
						<size>0.04 0.025 0.04</size>
					</box>
				</geometry>
				<material>
					<diffuse>0 0 0 1</diffuse>
				</material>
			</visual>
			<visual name="orange">
				<pose>0.02 0.0 0.0 0.0 0.0 0.0</pose>
				<geometry>
					<box>
						<size>0.00035 0.02 0.035</size>
					</box>
				</geometry>
				<material>
					<diffuse>1.0 0.5 0.0 1.0</diffuse>
				</material>
			</visual>
			<visual name="green">
				<pose>0.0 -0.0125 0.0 0.0 0.0 0.0</pose>
				<geometry>
					<box>
						<size>0.035 0.0002 0.035</size>
					</box>
				</geometry>
				<material>
					<diffuse>0 1 0 1</diffuse>
				</material>
			</visual>
			<visual name="white">
				<pose>0.0 0.0 -0.02 0.0 0.0 0.0</pose>
				<geometry>
					<box>
						<size>0.035 0.02 0.00035</size>
					</box>
				</geometry>
				<material>
					<diffuse>1 1 1 1</diffuse>
				</material>
			</visual>
		</link>
		<joint name="ball_1_0_0" type="ball">
			<pose>-0.020050000000000002 0.01255 0.020050000000000002 -0.0 -0.0 -0.0</pose>
			<parent>center</parent>
			<child>cubie_1_0_0</child>
			<axis>
				<dynamics>
					<damping>0.1</damping>
				</dynamics>
				<limit>
					<effort>0</effort>
				</limit>
			</axis>
		</joint>
		<link name="cubie_1_0_1">
			<pose>0.020050000000000002 -0.01255 0.005050000000000001 0.0 0.0 0.0</pose>
			<inertial>
				<mass>0.003900000000000001</mass>
				<inertia>
					<ixx>2.3562500000000013e-07</ixx>
					<ixy>0.0</ixy>
					<ixz>0.0</ixz>
					<iyy>5.525000000000002e-07</iyy>
					<iyz>0.0</iyz>
					<izz>7.231250000000004e-07</izz>
				</inertia>
			</inertial>
			<collision name="collision">
				<geometry>
					<box>
						<size>0.04 0.025 0.010000000000000002</size>
					</box>
				</geometry>
				<surface>
					<friction>
						<ode>
							<mu>0.6</mu>
							<mu2>0.6</mu2>
						</ode>
					</friction>
				</surface>
			</collision>
			<visual name="black">
				<geometry>
					<box>
						<size>0.04 0.025 0.010000000000000002</size>
					</box>
				</geometry>
				<material>
					<diffuse>0 0 0 1</diffuse>
				</material>
			</visual>
			<visual name="orange">
				<pose>0.02 0.0 0.0 0.0 0.0 0.0</pose>
				<geometry>
					<box>
						<size>0.00035 0.02 0.005</size>
					</box>
				</geometry>
				<material>
					<diffuse>1.0 0.5 0.0 1.0</diffuse>
				</material>
			</visual>
			<visual name="green">
				<pose>0.0 -0.0125 0.0 0.0 0.0 0.0</pose>
				<geometry>
					<box>
						<size>0.035 0.0002 0.005</size>
					</box>
				</geometry>
				<material>
					<diffuse>0 1 0 1</diffuse>
				</material>
			</visual>
			<visual name="yellow">
				<pose>0.0 0.0 0.005000000000000001 0.0 0.0 0.0</pose>
				<geometry>
					<box>
						<size>0.035 0.02 5e-05</size>
					</box>
				</geometry>
				<material>
					<diffuse>1 1 0 1</diffuse>
				</material>
			</visual>
		</link>
		<joint name="ball_1_0_1" type="ball">
			<pose>-0.020050000000000002 0.01255 -0.005050000000000001 -0.0 -0.0 -0.0</pose>
			<parent>center</parent>
			<child>cubie_1_0_1</child>
			<axis>
				<dynamics>
					<damping>0.1</damping>
				</dynamics>
				<limit>
					<effort>0</effort>
				</limit>
			</axis>
		</joint>
		<link name="cubie_1_1_0">
			<pose>0.020050000000000002 0.01255 -0.020050000000000002 0.0 0.0 0.0</pose>
			<inertial>
				<mass>0.015600000000000001</mass>
				<inertia>
					<ixx>2.8925000000000007e-06</ixx>
					<ixy>0.0</ixy>
					<ixz>0.0</ixz>
					<iyy>4.160000000000001e-06</iyy>
					<iyz>0.0</iyz>
					<izz>2.8925000000000007e-06</izz>
				</inertia>
			</inertial>
			<collision name="collision">
				<geometry>
					<box>
						<size>0.04 0.025 0.04</size>
					</box>
				</geometry>
				<surface>
					<friction>
						<ode>
							<mu>0.6</mu>
							<mu2>0.6</mu2>
						</ode>
					</friction>
				</surface>
			</collision>
			<visual name="black">
				<geometry>
					<box>
						<size>0.04 0.025 0.04</size>
					</box>
				</geometry>
				<material>
					<diffuse>0 0 0 1</diffuse>
				</material>
			</visual>
			<visual name="orange">
				<pose>0.02 0.0 0.0 0.0 0.0 0.0</pose>
				<geometry>
					<box>
						<size>0.00035 0.02 0.035</size>
					</box>
				</geometry>
				<material>
					<diffuse>1.0 0.5 0.0 1.0</diffuse>
				</material>
			</visual>
			<visual name="blue">
				<pose>0.0 0.0125 0.0 0.0 0.0 0.0</pose>
				<geometry>
					<box>
						<size>0.035 0.0002 0.035</size>
					</box>
				</geometry>
				<material>
					<diffuse>0 0 1 1</diffuse>
				</material>
			</visual>
			<visual name="white">
				<pose>0.0 0.0 -0.02 0.0 0.0 0.0</pose>
				<geometry>
					<box>
						<size>0.035 0.02 0.00035</size>
					</box>
				</geometry>
				<material>
					<diffuse>1 1 1 1</diffuse>
				</material>
			</visual>
		</link>
		<joint name="ball_1_1_0" type="ball">
			<pose>-0.020050000000000002 -0.01255 0.020050000000000002 -0.0 -0.0 -0.0</pose>
			<parent>center</parent>
			<child>cubie_1_1_0</child>
			<axis>
				<dynamics>
					<damping>0.1</damping>
				</dynamics>
				<limit>
					<effort>0</effort>
				</limit>
			</axis>
		</joint>
		<link name="cubie_1_1_1">
			<pose>0.020050000000000002 0.01255 0.005050000000000001 0.0 0.0 0.0</pose>
			<inertial>
				<mass>0.003900000000000001</mass>
				<inertia>
					<ixx>2.3562500000000013e-07</ixx>
					<ixy>0.0</ixy>
					<ixz>0.0</ixz>
					<iyy>5.525000000000002e-07</iyy>
					<iyz>0.0</iyz>
					<izz>7.231250000000004e-07</izz>
				</inertia>
			</inertial>
			<collision name="collision">
				<geometry>
					<box>
						<size>0.04 0.025 0.010000000000000002</size>
					</box>
				</geometry>
				<surface>
					<friction>
						<ode>
							<mu>0.6</mu>
							<mu2>0.6</mu2>
						</ode>
					</friction>
				</surface>
			</collision>
			<visual name="black">
				<geometry>
					<box>
						<size>0.04 0.025 0.010000000000000002</size>
					</box>
				</geometry>
				<material>
					<diffuse>0 0 0 1</diffuse>
				</material>
			</visual>
			<visual name="orange">
				<pose>0.02 0.0 0.0 0.0 0.0 0.0</pose>
				<geometry>
					<box>
						<size>0.00035 0.02 0.005</size>
					</box>
				</geometry>
				<material>
					<diffuse>1.0 0.5 0.0 1.0</diffuse>
				</material>
			</visual>
			<visual name="blue">
				<pose>0.0 0.0125 0.0 0.0 0.0 0.0</pose>
				<geometry>
					<box>
						<size>0.035 0.0002 0.005</size>
					</box>
				</geometry>
				<material>
					<diffuse>0 0 1 1</diffuse>
				</material>
			</visual>
			<visual name="yellow">
				<pose>0.0 0.0 0.005000000000000001 0.0 0.0 0.0</pose>
				<geometry>
					<box>
						<size>0.035 0.02 5e-05</size>
					</box>
				</geometry>
				<material>
					<diffuse>1 1 0 1</diffuse>
				</material>
			</visual>
		</link>
		<joint name="ball_1_1_1" type="ball">
			<pose>-0.020050000000000002 -0.01255 -0.005050000000000001 -0.0 -0.0 -0.0</pose>
			<parent>center</parent>
			<child>cubie_1_1_1</child>
			<axis>
				<dynamics>
					<damping>0.1</damping>
				</dynamics>
				<limit>
					<effort>0</effort>
				</limit>
			</axis>
		</joint>
	</model>
</sdf>
