<?xml version="1.0" ?>
<sdf version="1.7">
	<model name="mirror_cube_2x2">
		<link name="center"/>
		<link name="cubie_0_0_0">
			<pose>-0.01255 -0.020050000000000002 -0.02755 0.0 0.0 0.0</pose>
			<inertial>
				<mass>0.02145</mass>
				<inertia>
					<ixx>8.2671875e-06</ixx>
					<ixy>0.0</ixy>
					<ixz>0.0</ixz>
					<iyy>6.5243750000000005e-06</iyy>
					<iyz>0.0</iyz>
					<izz>3.977187500000001e-06</izz>
				</inertia>
			</inertial>
			<collision name="collision">
				<geometry>
					<box>
						<size>0.025 0.04 0.055</size>
					</box>
				</geometry>
				<surface>
					<friction>
						<ode>
							<mu>0.6</mu>
							<mu2>0.6</mu2>
						</ode>
					</friction>
				</surface>
			</collision>
			<visual name="black">
				<geometry>
					<box>
						<size>0.025 0.04 0.055</size>
					</box>
				</geometry>
				<material>
					<diffuse>0 0 0 1</diffuse>
				</material>
			</visual>
			<visual name="red">
				<pose>-0.0125 0.0 0.0 0.0 0.0 0.0</pose>
				<geometry>
					<box>
						<size>0.0002 0.035 0.05</size>
					</box>
				</geometry>
				<material>
					<diffuse>1 0 0 1</diffuse>
				</material>
			</visual>
			<visual name="green">
				<pose>0.0 -0.02 0.0 0.0 0.0 0.0</pose>
				<geometry>
					<box>
						<size>0.02 0.00035 0.05</size>
					</box>
				</geometry>
				<material>
					<diffuse>0 1 0 1</diffuse>
				</material>
			</visual>
			<visual name="white">
				<pose>0.0 0.0 -0.0275 0.0 0.0 0.0</pose>
				<geometry>
					<box>
						<size>0.02 0.035 0.0005</size>
					</box>
				</geometry>
				<material>
					<diffuse>1 1 1 1</diffuse>
				</material>
			</visual>
		</link>
		<joint name="ball_0_0_0" type="ball">
			<pose>0.01255 0.020050000000000002 0.02755 -0.0 -0.0 -0.0</pose>
			<parent>center</parent>
			<child>cubie_0_0_0</child>
			<axis>
				<dynamics>
					<damping>0.1</damping>
				</dynamics>
				<limit>
					<effort>0</effort>
				</limit>
			</axis>
		</joint>
		<link name="cubie_0_0_1">
			<pose>-0.01255 -0.020050000000000002 0.01255 0.0 0.0 0.0</pose>
			<inertial>
				<mass>0.00975</mass>
				<inertia>
					<ixx>1.8078125000000003e-06</ixx>
					<ixy>0.0</ixy>
					<ixz>0.0</ixz>
					<iyy>1.0156250000000001e-06</iyy>
					<iyz>0.0</iyz>
					<izz>1.8078125000000003e-06</izz>
				</inertia>
			</inertial>
			<collision name="collision">
				<geometry>
					<box>
						<size>0.025 0.04 0.025</size>
					</box>
				</geometry>
				<surface>
					<friction>
						<ode>
							<mu>0.6</mu>
							<mu2>0.6</mu2>
						</ode>
					</friction>
				</surface>
			</collision>
			<visual name="black">
				<geometry>
					<box>
						<size>0.025 0.04 0.025</size>
					</box>
				</geometry>
				<material>
					<diffuse>0 0 0 1</diffuse>
				</material>
			</visual>
			<visual name="red">
				<pose>-0.0125 0.0 0.0 0.0 0.0 0.0</pose>
				<geometry>
					<box>
						<size>0.0002 0.035 0.02</size>
					</box>
				</geometry>
				<material>
					<diffuse>1 0 0 1</diffuse>
				</material>
			</visual>
			<visual name="green">
				<pose>0.0 -0.02 0.0 0.0 0.0 0.0</pose>
				<geometry>
					<box>
						<size>0.02 0.00035 0.02</size>
					</box>
				</geometry>
				<material>
					<diffuse>0 1 0 1</diffuse>
				</material>
			</visual>
			<visual name="yellow">
				<pose>0.0 0.0 0.0125 0.0 0.0 0.0</pose>
				<geometry>
					<box>
						<size>0.02 0.035 0.0002</size>
					</box>
				</geometry>
				<material>
					<diffuse>1 1 0 1</diffuse>
				</material>
			</visual>
		</link>
		<joint name="ball_0_0_1" type="ball">
			<pose>0.01255 0.020050000000000002 -0.01255 -0.0 -0.0 -0.0</pose>
			<parent>center</parent>
			<child>cubie_0_0_1</child>
			<axis>
				<dynamics>
					<damping>0.1</damping>
				</dynamics>
				<limit>
					<effort>0</effort>
				</limit>
			</axis>
		</joint>
		<link name="cubie_0_1_0">
			<pose>-0.01255 0.020050000000000002 -0.02755 0.0 0.0 0.0</pose>
			<inertial>
				<mass>0.02145</mass>
				<inertia>
					<ixx>8.2671875e-06</ixx>
					<ixy>0.0</ixy>
					<ixz>0.0</ixz>
					<iyy>6.5243750000000005e-06</iyy>
					<iyz>0.0</iyz>
					<izz>3.977187500000001e-06</izz>
				</inertia>
			</inertial>
			<collision name="collision">
				<geometry>
					<box>
						<size>0.025 0.04 0.055</size>
					</box>
				</geometry>
				<surface>
					<friction>
						<ode>
							<mu>0.6</mu>
							<mu2>0.6</mu2>
						</ode>
					</friction>
				</surface>
			</collision>
			<visual name="black">
				<geometry>
					<box>
						<size>0.025 0.04 0.055</size>
					</box>
				</geometry>
				<material>
					<diffuse>0 0 0 1</diffuse>
				</material>
			</visual>
			<visual name="red">
				<pose>-0.0125 0.0 0.0 0.0 0.0 0.0</pose>
				<geometry>
					<box>
						<size>0.0002 0.035 0.05</size>
					</box>
				</geometry>
				<material>
					<diffuse>1 0 0 1</diffuse>
				</material>
			</visual>
			<visual name="blue">
				<pose>0.0 0.02 0.0 0.0 0.0 0.0</pose>
				<geometry>
					<box>
						<size>0.02 0.00035 0.05</size>
					</box>
				</geometry>
				<material>
					<diffuse>0 0 1 1</diffuse>
				</material>
			</visual>
			<visual name="white">
				<pose>0.0 0.0 -0.0275 0.0 0.0 0.0</pose>
				<geometry>
					<box>
						<size>0.02 0.035 0.0005</size>
					</box>
				</geometry>
				<material>
					<diffuse>1 1 1 1</diffuse>
				</material>
			</visual>
		</link>
		<joint name="ball_0_1_0" type="ball">
			<pose>0.01255 -0.020050000000000002 0.02755 -0.0 -0.0 -0.0</pose>
			<parent>center</parent>
			<child>cubie_0_1_0</child>
			<axis>
				<dynamics>
					<damping>0.1</damping>
				</dynamics>
				<limit>
					<effort>0</effort>
				</limit>
			</axis>
		</joint>
		<link name="cubie_0_1_1">
			<pose>-0.01255 0.020050000000000002 0.01255 0.0 0.0 0.0</pose>
			<inertial>
				<mass>0.00975</mass>
				<inertia>
					<ixx>1.8078125000000003e-06</ixx>
					<ixy>0.0</ixy>
					<ixz>0.0</ixz>
					<iyy>1.0156250000000001e-06</iyy>
					<iyz>0.0</iyz>
					<izz>1.8078125000000003e-06</izz>
				</inertia>
			</inertial>
			<collision name="collision">
				<geometry>
					<box>
						<size>0.025 0.04 0.025</size>
					</box>
				</geometry>
				<surface>
					<friction>
						<ode>
							<mu>0.6</mu>
							<mu2>0.6</mu2>
						</ode>
					</friction>
				</surface>
			</collision>
			<visual name="black">
				<geometry>
					<box>
						<size>0.025 0.04 0.025</size>
					</box>
				</geometry>
				<material>
					<diffuse>0 0 0 1</diffuse>
				</material>
			</visual>
			<visual name="red">
				<pose>-0.0125 0.0 0.0 0.0 0.0 0.0</pose>
				<geometry>
					<box>
						<size>0.0002 0.035 0.02</size>
					</box>
				</geometry>
				<material>
					<diffuse>1 0 0 1</diffuse>
				</material>
			</visual>
			<visual name="blue">
				<pose>0.0 0.02 0.0 0.0 0.0 0.0</pose>
				<geometry>
					<box>
						<size>0.02 0.00035 0.02</size>
					</box>
				</geometry>
				<material>
					<diffuse>0 0 1 1</diffuse>
				</material>
			</visual>
			<visual name="yellow">
				<pose>0.0 0.0 0.0125 0.0 0.0 0.0</pose>
				<geometry>
					<box>
						<size>0.02 0.035 0.0002</size>
					</box>
				</geometry>
				<material>
					<diffuse>1 1 0 1</diffuse>
				</material>
			</visual>
		</link>
		<joint name="ball_0_1_1" type="ball">
			<pose>0.01255 -0.020050000000000002 -0.01255 -0.0 -0.0 -0.0</pose>
			<parent>center</parent>
			<child>cubie_0_1_1</child>
			<axis>
				<dynamics>
					<damping>0.1</damping>
				</dynamics>
				<limit>
					<effort>0</effort>
				</limit>
			</axis>
		</joint>
		<link name="cubie_1_0_0">
			<pose>0.02755 -0.020050000000000002 -0.02755 0.0 0.0 0.0</pose>
			<inertial>
				<mass>0.04719</mass>
				<inertia>
					<ixx>1.81878125e-05</ixx>
					<ixy>0.0</ixy>
					<ixz>0.0</ixz>
					<iyy>2.3791625e-05</iyy>
					<iyz>0.0</iyz>
					<izz>1.81878125e-05</izz>
				</inertia>
			</inertial>
			<collision name="collision">
				<geometry>
					<box>
						<size>0.055 0.04 0.055</size>
					</box>
				</geometry>
				<surface>
					<friction>
						<ode>
							<mu>0.6</mu>
							<mu2>0.6</mu2>
						</ode>
					</friction>
				</surface>
			</collision>
			<visual name="black">
				<geometry>
					<box>
						<size>0.055 0.04 0.055</size>
					</box>
				</geometry>
				<material>
					<diffuse>0 0 0 1</diffuse>
				</material>
			</visual>
			<visual name="orange">
				<pose>0.0275 0.0 0.0 0.0 0.0 0.0</pose>
				<geometry>
					<box>
						<size>0.0005 0.035 0.05</size>
					</box>
				</geometry>
				<material>
					<diffuse>1.0 0.5 0.0 1.0</diffuse>
				</material>
			</visual>
			<visual name="green">
				<pose>0.0 -0.02 0.0 0.0 0.0 0.0</pose>
				<geometry>
					<box>
						<size>0.05 0.00035 0.05</size>
					</box>
				</geometry>
				<material>
					<diffuse>0 1 0 1</diffuse>
				</material>
			</visual>
			<visual name="white">
				<pose>0.0 0.0 -0.0275 0.0 0.0 0.0</pose>
				<geometry>
					<box>
						<size>0.05 0.035 0.0005</size>
					</box>
				</geometry>
				<material>
					<diffuse>1 1 1 1</diffuse>
				</material>
			</visual>
		</link>
		<joint name="ball_1_0_0" type="ball">
			<pose>-0.02755 0.020050000000000002 0.02755 -0.0 -0.0 -0.0</pose>
			<parent>center</parent>
			<child>cubie_1_0_0</child>
			<axis>
				<dynamics>
					<damping>0.1</damping>
				</dynamics>
				<limit>
					<effort>0</effort>
				</limit>
			</axis>
		</joint>
		<link name="cubie_1_0_1">
			<pose>0.02755 -0.020050000000000002 0.01255 0.0 0.0 0.0</pose>
			<inertial>
				<mass>0.021450000000000004</mass>
				<inertia>
					<ixx>3.9771875000000015e-06</ixx>
					<ixy>0.0</ixy>
					<ixz>0.0</ixz>
					<iyy>6.5243750000000005e-06</iyy>
					<iyz>0.0</iyz>
					<izz>8.2671875e-06</izz>
				</inertia>
			</inertial>
			<collision name="collision">
				<geometry>
					<box>
						<size>0.055 0.04 0.025</size>
					</box>
				</geometry>
				<surface>
					<friction>
						<ode>
							<mu>0.6</mu>
							<mu2>0.6</mu2>
						</ode>
					</friction>
				</surface>
			</collision>
			<visual name="black">
				<geometry>
					<box>
						<size>0.055 0.04 0.025</size>
					</box>
				</geometry>
				<material>
					<diffuse>0 0 0 1</diffuse>
				</material>
			</visual>
			<visual name="orange">
				<pose>0.0275 0.0 0.0 0.0 0.0 0.0</pose>
				<geometry>
					<box>
						<size>0.0005 0.035 0.02</size>
					</box>
				</geometry>
				<material>
					<diffuse>1.0 0.5 0.0 1.0</diffuse>
				</material>
			</visual>
			<visual name="green">
				<pose>0.0 -0.02 0.0 0.0 0.0 0.0</pose>
				<geometry>
					<box>
						<size>0.05 0.00035 0.02</size>
					</box>
				</geometry>
				<material>
					<diffuse>0 1 0 1</diffuse>
				</material>
			</visual>
			<visual name="yellow">
				<pose>0.0 0.0 0.0125 0.0 0.0 0.0</pose>
				<geometry>
					<box>
						<size>0.05 0.035 0.0002</size>
					</box>
				</geometry>
				<material>
					<diffuse>1 1 0 1</diffuse>
				</material>
			</visual>
		</link>
		<joint name="ball_1_0_1" type="ball">
			<pose>-0.02755 0.020050000000000002 -0.01255 -0.0 -0.0 -0.0</pose>
			<parent>center</parent>
			<child>cubie_1_0_1</child>
			<axis>
				<dynamics>
					<damping>0.1</damping>
				</dynamics>
				<limit>
					<effort>0</effort>
				</limit>
			</axis>
		</joint>
		<link name="cubie_1_1_0">
			<pose>0.02755 0.020050000000000002 -0.02755 0.0 0.0 0.0</pose>
			<inertial>
				<mass>0.04719</mass>
				<inertia>
					<ixx>1.81878125e-05</ixx>
					<ixy>0.0</ixy>
					<ixz>0.0</ixz>
					<iyy>2.3791625e-05</iyy>
					<iyz>0.0</iyz>
					<izz>1.81878125e-05</izz>
				</inertia>
			</inertial>
			<collision name="collision">
				<geometry>
					<box>
						<size>0.055 0.04 0.055</size>
					</box>
				</geometry>
				<surface>
					<friction>
						<ode>
							<mu>0.6</mu>
							<mu2>0.6</mu2>
						</ode>
					</friction>
				</surface>
			</collision>
			<visual name="black">
				<geometry>
					<box>
						<size>0.055 0.04 0.055</size>
					</box>
				</geometry>
				<material>
					<diffuse>0 0 0 1</diffuse>
				</material>
			</visual>
			<visual name="orange">
				<pose>0.0275 0.0 0.0 0.0 0.0 0.0</pose>
				<geometry>
					<box>
						<size>0.0005 0.035 0.05</size>
					</box>
				</geometry>
				<material>
					<diffuse>1.0 0.5 0.0 1.0</diffuse>
				</material>
			</visual>
			<visual name="blue">
				<pose>0.0 0.02 0.0 0.0 0.0 0.0</pose>
				<geometry>
					<box>
						<size>0.05 0.00035 0.05</size>
					</box>
				</geometry>
				<material>
					<diffuse>0 0 1 1</diffuse>
				</material>
			</visual>
			<visual name="white">
				<pose>0.0 0.0 -0.0275 0.0 0.0 0.0</pose>
				<geometry>
					<box>
						<size>0.05 0.035 0.0005</size>
					</box>
				</geometry>
				<material>
					<diffuse>1 1 1 1</diffuse>
				</material>
			</visual>
		</link>
		<joint name="ball_1_1_0" type="ball">
			<pose>-0.02755 -0.020050000000000002 0.02755 -0.0 -0.0 -0.0</pose>
			<parent>center</parent>
			<child>cubie_1_1_0</child>
			<axis>
				<dynamics>
					<damping>0.1</damping>
				</dynamics>
				<limit>
					<effort>0</effort>
				</limit>
			</axis>
		</joint>
		<link name="cubie_1_1_1">
			<pose>0.02755 0.020050000000000002 0.01255 0.0 0.0 0.0</pose>
			<inertial>
				<mass>0.021450000000000004</mass>
				<inertia>
					<ixx>3.9771875000000015e-06</ixx>
					<ixy>0.0</ixy>
					<ixz>0.0</ixz>
					<iyy>6.5243750000000005e-06</iyy>
					<iyz>0.0</iyz>
					<izz>8.2671875e-06</izz>
				</inertia>
			</inertial>
			<collision name="collision">
				<geometry>
					<box>
						<size>0.055 0.04 0.025</size>
					</box>
				</geometry>
				<surface>
					<friction>
						<ode>
							<mu>0.6</mu>
							<mu2>0.6</mu2>
						</ode>
					</friction>
				</surface>
			</collision>
			<visual name="black">
				<geometry>
					<box>
						<size>0.055 0.04 0.025</size>
					</box>
				</geometry>
				<material>
					<diffuse>0 0 0 1</diffuse>
				</material>
			</visual>
			<visual name="orange">
				<pose>0.0275 0.0 0.0 0.0 0.0 0.0</pose>
				<geometry>
					<box>
						<size>0.0005 0.035 0.02</size>
					</box>
				</geometry>
				<material>
					<diffuse>1.0 0.5 0.0 1.0</diffuse>
				</material>
			</visual>
			<visual name="blue">
				<pose>0.0 0.02 0.0 0.0 0.0 0.0</pose>
				<geometry>
					<box>
						<size>0.05 0.00035 0.02</size>
					</box>
				</geometry>
				<material>
					<diffuse>0 0 1 1</diffuse>
				</material>
			</visual>
			<visual name="yellow">
				<pose>0.0 0.0 0.0125 0.0 0.0 0.0</pose>
				<geometry>
					<box>
						<size>0.05 0.035 0.0002</size>
					</box>
				</geometry>
				<material>
					<diffuse>1 1 0 1</diffuse>
				</material>
			</visual>
		</link>
		<joint name="ball_1_1_1" type="ball">
			<pose>-0.02755 -0.020050000000000002 -0.01255 -0.0 -0.0 -0.0</pose>
			<parent>center</parent>
			<child>cubie_1_1_1</child>
			<axis>
				<dynamics>
					<damping>0.1</damping>
				</dynamics>
				<limit>
					<effort>0</effort>
				</limit>
			</axis>
		</joint>
	</model>
</sdf>
