<?xml version="1.0" ?>
<sdf version="1.7">
	<model name="mirror_cube_2x2">
		<link name="center"/>
		<link name="cubie_0_0_0">
			<pose>-0.01255 -0.017550000000000003 -0.022550000000000004 0.0 0.0 0.0</pose>
			<inertial>
				<mass>0.015356250000000004</mass>
				<inertia>
					<ixx>4.158984375000001e-06</ixx>
					<ixy>0.0</ixy>
					<ixz>0.0</ixz>
					<iyy>3.3911718750000012e-06</iyy>
					<iyz>0.0</iyz>
					<izz>2.3674218750000007e-06</izz>
				</inertia>
			</inertial>
			<collision name="collision">
				<geometry>
					<box>
						<size>0.025 0.035 0.045000000000000005</size>
					</box>
				</geometry>
				<surface>
					<friction>
						<ode>
							<mu>0.6</mu>
							<mu2>0.6</mu2>
						</ode>
					</friction>
				</surface>
			</collision>
			<visual name="black">
				<geometry>
					<box>
						<size>0.025 0.035 0.045000000000000005</size>
					</box>
				</geometry>
				<material>
					<diffuse>0 0 0 1</diffuse>
				</material>
			</visual>
			<visual name="red">
				<pose>-0.0125 0.0 0.0 0.0 0.0 0.0</pose>
				<geometry>
					<box>
						<size>0.0002 0.03 0.04</size>
					</box>
				</geometry>
				<material>
					<diffuse>1 0 0 1</diffuse>
				</material>
			</visual>
			<visual name="green">
				<pose>0.0 -0.0175 0.0 0.0 0.0 0.0</pose>
				<geometry>
					<box>
						<size>0.02 0.0003 0.04</size>
					</box>
				</geometry>
				<material>
					<diffuse>0 1 0 1</diffuse>
				</material>
			</visual>
			<visual name="white">
				<pose>0.0 0.0 -0.022500000000000003 0.0 0.0 0.0</pose>
				<geometry>
					<box>
						<size>0.02 0.03 0.0004</size>
					</box>
				</geometry>
				<material>
					<diffuse>1 1 1 1</diffuse>
				</material>
			</visual>
		</link>
		<joint name="ball_0_0_0" type="ball">
			<pose>0.01255 0.017550000000000003 0.022550000000000004 -0.0 -0.0 -0.0</pose>
			<parent>center</parent>
			<child>cubie_0_0_0</child>
			<axis>
				<dynamics>
					<damping>0.1</damping>
				</dynamics>
				<limit>
					<effort>0</effort>
				</limit>
			</axis>
		</joint>
		<link name="cubie_0_0_1">
			<pose>-0.01255 -0.017550000000000003 0.01255 0.0 0.0 0.0</pose>
			<inertial>
				<mass>0.00853125</mass>
				<inertia>
					<ixx>1.3152343750000004e-06</ixx>
					<ixy>0.0</ixy>
					<ixz>0.0</ixz>
					<iyy>8.886718750000003e-07</iyy>
					<iyz>0.0</iyz>
					<izz>1.3152343750000004e-06</izz>
				</inertia>
			</inertial>
			<collision name="collision">
				<geometry>
					<box>
						<size>0.025 0.035 0.025</size>
					</box>
				</geometry>
				<surface>
					<friction>
						<ode>
							<mu>0.6</mu>
							<mu2>0.6</mu2>
						</ode>
					</friction>
				</surface>
			</collision>
			<visual name="black">
				<geometry>
					<box>
						<size>0.025 0.035 0.025</size>
					</box>
				</geometry>
				<material>
					<diffuse>0 0 0 1</diffuse>
				</material>
			</visual>
			<visual name="red">
				<pose>-0.0125 0.0 0.0 0.0 0.0 0.0</pose>
				<geometry>
					<box>
						<size>0.0002 0.03 0.02</size>
					</box>
				</geometry>
				<material>
					<diffuse>1 0 0 1</diffuse>
				</material>
			</visual>
			<visual name="green">
				<pose>0.0 -0.0175 0.0 0.0 0.0 0.0</pose>
				<geometry>
					<box>
						<size>0.02 0.0003 0.02</size>
					</box>
				</geometry>
				<material>
					<diffuse>0 1 0 1</diffuse>
				</material>
			</visual>
			<visual name="yellow">
				<pose>0.0 0.0 0.0125 0.0 0.0 0.0</pose>
				<geometry>
					<box>
						<size>0.02 0.03 0.0002</size>
					</box>
				</geometry>
				<material>
					<diffuse>1 1 0 1</diffuse>
				</material>
			</visual>
		</link>
		<joint name="ball_0_0_1" type="ball">
			<pose>0.01255 0.017550000000000003 -0.01255 -0.0 -0.0 -0.0</pose>
			<parent>center</parent>
			<child>cubie_0_0_1</child>
			<axis>
				<dynamics>
					<damping>0.1</damping>
				</dynamics>
				<limit>
					<effort>0</effort>
				</limit>
			</axis>
		</joint>
		<link name="cubie_0_1_0">
			<pose>-0.01255 0.017550000000000003 -0.022550000000000004 0.0 0.0 0.0</pose>
			<inertial>
				<mass>0.015356250000000004</mass>
				<inertia>
					<ixx>4.158984375000001e-06</ixx>
					<ixy>0.0</ixy>
					<ixz>0.0</ixz>
					<iyy>3.3911718750000012e-06</iyy>
					<iyz>0.0</iyz>
					<izz>2.3674218750000007e-06</izz>
				</inertia>
			</inertial>
			<collision name="collision">
				<geometry>
					<box>
						<size>0.025 0.035 0.045000000000000005</size>
					</box>
				</geometry>
				<surface>
					<friction>
						<ode>
							<mu>0.6</mu>
							<mu2>0.6</mu2>
						</ode>
					</friction>
				</surface>
			</collision>
			<visual name="black">
				<geometry>
					<box>
						<size>0.025 0.035 0.045000000000000005</size>
					</box>
				</geometry>
				<material>
					<diffuse>0 0 0 1</diffuse>
				</material>
			</visual>
			<visual name="red">
				<pose>-0.0125 0.0 0.0 0.0 0.0 0.0</pose>
				<geometry>
					<box>
						<size>0.0002 0.03 0.04</size>
					</box>
				</geometry>
				<material>
					<diffuse>1 0 0 1</diffuse>
				</material>
			</visual>
			<visual name="blue">
				<pose>0.0 0.0175 0.0 0.0 0.0 0.0</pose>
				<geometry>
					<box>
						<size>0.02 0.0003 0.04</size>
					</box>
				</geometry>
				<material>
					<diffuse>0 0 1 1</diffuse>
				</material>
			</visual>
			<visual name="white">
				<pose>0.0 0.0 -0.022500000000000003 0.0 0.0 0.0</pose>
				<geometry>
					<box>
						<size>0.02 0.03 0.0004</size>
					</box>
				</geometry>
				<material>
					<diffuse>1 1 1 1</diffuse>
				</material>
			</visual>
		</link>
		<joint name="ball_0_1_0" type="ball">
			<pose>0.01255 -0.017550000000000003 0.022550000000000004 -0.0 -0.0 -0.0</pose>
			<parent>center</parent>
			<child>cubie_0_1_0</child>
			<axis>
				<dynamics>
					<damping>0.1</damping>
				</dynamics>
				<limit>
					<effort>0</effort>
				</limit>
			</axis>
		</joint>
		<link name="cubie_0_1_1">
			<pose>-0.01255 0.017550000000000003 0.01255 0.0 0.0 0.0</pose>
			<inertial>
				<mass>0.00853125</mass>
				<inertia>
					<ixx>1.3152343750000004e-06</ixx>
					<ixy>0.0</ixy>
					<ixz>0.0</ixz>
					<iyy>8.886718750000003e-07</iyy>
					<iyz>0.0</iyz>
					<izz>1.3152343750000004e-06</izz>
				</inertia>
			</inertial>
			<collision name="collision">
				<geometry>
					<box>
						<size>0.025 0.035 0.025</size>
					</box>
				</geometry>
				<surface>
					<friction>
						<ode>
							<mu>0.6</mu>
							<mu2>0.6</mu2>
						</ode>
					</friction>
				</surface>
			</collision>
			<visual name="black">
				<geometry>
					<box>
						<size>0.025 0.035 0.025</size>
					</box>
				</geometry>
				<material>
					<diffuse>0 0 0 1</diffuse>
				</material>
			</visual>
			<visual name="red">
				<pose>-0.0125 0.0 0.0 0.0 0.0 0.0</pose>
				<geometry>
					<box>
						<size>0.0002 0.03 0.02</size>
					</box>
				</geometry>
				<material>
					<diffuse>1 0 0 1</diffuse>
				</material>
			</visual>
			<visual name="blue">
				<pose>0.0 0.0175 0.0 0.0 0.0 0.0</pose>
				<geometry>
					<box>
						<size>0.02 0.0003 0.02</size>
					</box>
				</geometry>
				<material>
					<diffuse>0 0 1 1</diffuse>
				</material>
			</visual>
			<visual name="yellow">
				<pose>0.0 0.0 0.0125 0.0 0.0 0.0</pose>
				<geometry>
					<box>
						<size>0.02 0.03 0.0002</size>
					</box>
				</geometry>
				<material>
					<diffuse>1 1 0 1</diffuse>
				</material>
			</visual>
		</link>
		<joint name="ball_0_1_1" type="ball">
			<pose>0.01255 -0.017550000000000003 -0.01255 -0.0 -0.0 -0.0</pose>
			<parent>center</parent>
			<child>cubie_0_1_1</child>
			<axis>
				<dynamics>
					<damping>0.1</damping>
				</dynamics>
				<limit>
					<effort>0</effort>
				</limit>
			</axis>
		</joint>
		<link name="cubie_1_0_0">
			<pose>0.022550000000000004 -0.017550000000000003 -0.022550000000000004 0.0 0.0 0.0</pose>
			<inertial>
				<mass>0.027641250000000006</mass>
				<inertia>
					<ixx>7.486171875000002e-06</ixx>
					<ixy>0.0</ixy>
					<ixz>0.0</ixz>
					<iyy>9.328921875000004e-06</iyy>
					<iyz>0.0</iyz>
					<izz>7.486171875000002e-06</izz>
				</inertia>
			</inertial>
			<collision name="collision">
				<geometry>
					<box>
						<size>0.045000000000000005 0.035 0.045000000000000005</size>
					</box>
				</geometry>
				<surface>
					<friction>
						<ode>
							<mu>0.6</mu>
							<mu2>0.6</mu2>
						</ode>
					</friction>
				</surface>
			</collision>
			<visual name="black">
				<geometry>
					<box>
						<size>0.045000000000000005 0.035 0.045000000000000005</size>
					</box>
				</geometry>
				<material>
					<diffuse>0 0 0 1</diffuse>
				</material>
			</visual>
			<visual name="orange">
				<pose>0.022500000000000003 0.0 0.0 0.0 0.0 0.0</pose>
				<geometry>
					<box>
						<size>0.0004 0.03 0.04</size>
					</box>
				</geometry>
				<material>
					<diffuse>1.0 0.5 0.0 1.0</diffuse>
				</material>
			</visual>
			<visual name="green">
				<pose>0.0 -0.0175 0.0 0.0 0.0 0.0</pose>
				<geometry>
					<box>
						<size>0.04 0.0003 0.04</size>
					</box>
				</geometry>
				<material>
					<diffuse>0 1 0 1</diffuse>
				</material>
			</visual>
			<visual name="white">
				<pose>0.0 0.0 -0.022500000000000003 0.0 0.0 0.0</pose>
				<geometry>
					<box>
						<size>0.04 0.03 0.0004</size>
					</box>
				</geometry>
				<material>
					<diffuse>1 1 1 1</diffuse>
				</material>
			</visual>
		</link>
		<joint name="ball_1_0_0" type="ball">
			<pose>-0.022550000000000004 0.017550000000000003 0.022550000000000004 -0.0 -0.0 -0.0</pose>
			<parent>center</parent>
			<child>cubie_1_0_0</child>
			<axis>
				<dynamics>
					<damping>0.1</damping>
				</dynamics>
				<limit>
					<effort>0</effort>
				</limit>
			</axis>
		</joint>
		<link name="cubie_1_0_1">
			<pose>0.022550000000000004 -0.017550000000000003 0.01255 0.0 0.0 0.0</pose>
			<inertial>
				<mass>0.015356250000000004</mass>
				<inertia>
					<ixx>2.3674218750000007e-06</ixx>
					<ixy>0.0</ixy>
					<ixz>0.0</ixz>
					<iyy>3.3911718750000012e-06</iyy>
					<iyz>0.0</iyz>
					<izz>4.158984375000001e-06</izz>
				</inertia>
			</inertial>
			<collision name="collision">
				<geometry>
					<box>
						<size>0.045000000000000005 0.035 0.025</size>
					</box>
				</geometry>
				<surface>
					<friction>
						<ode>
							<mu>0.6</mu>
							<mu2>0.6</mu2>
						</ode>
					</friction>
				</surface>
			</collision>
			<visual name="black">
				<geometry>
					<box>
						<size>0.045000000000000005 0.035 0.025</size>
					</box>
				</geometry>
				<material>
					<diffuse>0 0 0 1</diffuse>
				</material>
			</visual>
			<visual name="orange">
				<pose>0.022500000000000003 0.0 0.0 0.0 0.0 0.0</pose>
				<geometry>
					<box>
						<size>0.0004 0.03 0.02</size>
					</box>
				</geometry>
				<material>
					<diffuse>1.0 0.5 0.0 1.0</diffuse>
				</material>
			</visual>
			<visual name="green">
				<pose>0.0 -0.0175 0.0 0.0 0.0 0.0</pose>
				<geometry>
					<box>
						<size>0.04 0.0003 0.02</size>
					</box>
				</geometry>
				<material>
					<diffuse>0 1 0 1</diffuse>
				</material>
			</visual>
			<visual name="yellow">
				<pose>0.0 0.0 0.0125 0.0 0.0 0.0</pose>
				<geometry>
					<box>
						<size>0.04 0.03 0.0002</size>
					</box>
				</geometry>
				<material>
					<diffuse>1 1 0 1</diffuse>
				</material>
			</visual>
		</link>
		<joint name="ball_1_0_1" type="ball">
			<pose>-0.022550000000000004 0.017550000000000003 -0.01255 -0.0 -0.0 -0.0</pose>
			<parent>center</parent>
			<child>cubie_1_0_1</child>
			<axis>
				<dynamics>
					<damping>0.1</damping>
				</dynamics>
				<limit>
					<effort>0</effort>
				</limit>
			</axis>
		</joint>
		<link name="cubie_1_1_0">
			<pose>0.022550000000000004 0.017550000000000003 -0.022550000000000004 0.0 0.0 0.0</pose>
			<inertial>
				<mass>0.027641250000000006</mass>
				<inertia>
					<ixx>7.486171875000002e-06</ixx>
					<ixy>0.0</ixy>
					<ixz>0.0</ixz>
					<iyy>9.328921875000004e-06</iyy>
					<iyz>0.0</iyz>
					<izz>7.486171875000002e-06</izz>
				</inertia>
			</inertial>
			<collision name="collision">
				<geometry>
					<box>
						<size>0.045000000000000005 0.035 0.045000000000000005</size>
					</box>
				</geometry>
				<surface>
					<friction>
						<ode>
							<mu>0.6</mu>
							<mu2>0.6</mu2>
						</ode>
					</friction>
				</surface>
			</collision>
			<visual name="black">
				<geometry>
					<box>
						<size>0.045000000000000005 0.035 0.045000000000000005</size>
					</box>
				</geometry>
				<material>
					<diffuse>0 0 0 1</diffuse>
				</material>
			</visual>
			<visual name="orange">
				<pose>0.022500000000000003 0.0 0.0 0.0 0.0 0.0</pose>
				<geometry>
					<box>
						<size>0.0004 0.03 0.04</size>
					</box>
				</geometry>
				<material>
					<diffuse>1.0 0.5 0.0 1.0</diffuse>
				</material>
			</visual>
			<visual name="blue">
				<pose>0.0 0.0175 0.0 0.0 0.0 0.0</pose>
				<geometry>
					<box>
						<size>0.04 0.0003 0.04</size>
					</box>
				</geometry>
				<material>
					<diffuse>0 0 1 1</diffuse>
				</material>
			</visual>
			<visual name="white">
				<pose>0.0 0.0 -0.022500000000000003 0.0 0.0 0.0</pose>
				<geometry>
					<box>
						<size>0.04 0.03 0.0004</size>
					</box>
				</geometry>
				<material>
					<diffuse>1 1 1 1</diffuse>
				</material>
			</visual>
		</link>
		<joint name="ball_1_1_0" type="ball">
			<pose>-0.022550000000000004 -0.017550000000000003 0.022550000000000004 -0.0 -0.0 -0.0</pose>
			<parent>center</parent>
			<child>cubie_1_1_0</child>
			<axis>
				<dynamics>
					<damping>0.1</damping>
				</dynamics>
				<limit>
					<effort>0</effort>
				</limit>
			</axis>
		</joint>
		<link name="cubie_1_1_1">
			<pose>0.022550000000000004 0.017550000000000003 0.01255 0.0 0.0 0.0</pose>
			<inertial>
				<mass>0.015356250000000004</mass>
				<inertia>
					<ixx>2.3674218750000007e-06</ixx>
					<ixy>0.0</ixy>
					<ixz>0.0</ixz>
					<iyy>3.3911718750000012e-06</iyy>
					<iyz>0.0</iyz>
					<izz>4.158984375000001e-06</izz>
				</inertia>
			</inertial>
			<collision name="collision">
				<geometry>
					<box>
						<size>0.045000000000000005 0.035 0.025</size>
					</box>
				</geometry>
				<surface>
					<friction>
						<ode>
							<mu>0.6</mu>
							<mu2>0.6</mu2>
						</ode>
					</friction>
				</surface>
			</collision>
			<visual name="black">
				<geometry>
					<box>
						<size>0.045000000000000005 0.035 0.025</size>
					</box>
				</geometry>
				<material>
					<diffuse>0 0 0 1</diffuse>
				</material>
			</visual>
			<visual name="orange">
				<pose>0.022500000000000003 0.0 0.0 0.0 0.0 0.0</pose>
				<geometry>
					<box>
						<size>0.0004 0.03 0.02</size>
					</box>
				</geometry>
				<material>
					<diffuse>1.0 0.5 0.0 1.0</diffuse>
				</material>
			</visual>
			<visual name="blue">
				<pose>0.0 0.0175 0.0 0.0 0.0 0.0</pose>
				<geometry>
					<box>
						<size>0.04 0.0003 0.02</size>
					</box>
				</geometry>
				<material>
					<diffuse>0 0 1 1</diffuse>
				</material>
			</visual>
			<visual name="yellow">
				<pose>0.0 0.0 0.0125 0.0 0.0 0.0</pose>
				<geometry>
					<box>
						<size>0.04 0.03 0.0002</size>
					</box>
				</geometry>
				<material>
					<diffuse>1 1 0 1</diffuse>
				</material>
			</visual>
		</link>
		<joint name="ball_1_1_1" type="ball">
			<pose>-0.022550000000000004 -0.017550000000000003 -0.01255 -0.0 -0.0 -0.0</pose>
			<parent>center</parent>
			<child>cubie_1_1_1</child>
			<axis>
				<dynamics>
					<damping>0.1</damping>
				</dynamics>
				<limit>
					<effort>0</effort>
				</limit>
			</axis>
		</joint>
	</model>
</sdf>
