<?xml version="1.0" ?>
<sdf version="1.7">
	<model name="mirror_cube_2x2">
		<link name="center"/>
		<link name="cubie_0_0_0">
			<pose>-0.01505 -0.02255 -0.03005 0.0 0.0 0.0</pose>
			<inertial>
				<mass>0.03158999999999999</mass>
				<inertia>
					<ixx>1.4807812499999997e-05</ixx>
					<ixy>0.0</ixy>
					<ixz>0.0</ixz>
					<iyy>1.1846249999999997e-05</iyy>
					<iyz>0.0</iyz>
					<izz>7.700062499999997e-06</izz>
				</inertia>
			</inertial>
			<collision name="collision">
				<geometry>
					<box>
						<size>0.03 0.045 0.06</size>
					</box>
				</geometry>
				<surface>
					<friction>
						<ode>
							<mu>0.6</mu>
							<mu2>0.6</mu2>
						</ode>
					</friction>
				</surface>
			</collision>
			<visual name="black">
				<geometry>
					<box>
						<size>0.03 0.045 0.06</size>
					</box>
				</geometry>
				<material>
					<diffuse>0 0 0 1</diffuse>
				</material>
			</visual>
			<visual name="red">
				<pose>-0.015 0.0 0.0 0.0 0.0 0.0</pose>
				<geometry>
					<box>
						<size>0.00025 0.04 0.055</size>
					</box>
				</geometry>
				<material>
					<diffuse>1 0 0 1</diffuse>
				</material>
			</visual>
			<visual name="green">
				<pose>0.0 -0.0225 0.0 0.0 0.0 0.0</pose>
				<geometry>
					<box>
						<size>0.025 0.0004 0.055</size>
					</box>
				</geometry>
				<material>
					<diffuse>0 1 0 1</diffuse>
				</material>
			</visual>
			<visual name="white">
				<pose>0.0 0.0 -0.03 0.0 0.0 0.0</pose>
				<geometry>
					<box>
						<size>0.025 0.04 0.00055</size>
					</box>
				</geometry>
				<material>
					<diffuse>1 1 1 1</diffuse>
				</material>
			</visual>
		</link>
		<joint name="ball_0_0_0" type="ball">
			<pose>0.01505 0.02255 0.03005 -0.0 -0.0 -0.0</pose>
			<parent>center</parent>
			<child>cubie_0_0_0</child>
			<axis>
				<dynamics>
					<damping>0.1</damping>
				</dynamics>
				<limit>
					<effort>0</effort>
				</limit>
			</axis>
		</joint>
		<link name="cubie_0_0_1">
			<pose>-0.01505 -0.02255 0.01505 0.0 0.0 0.0</pose>
			<inertial>
				<mass>0.015794999999999997</mass>
				<inertia>
					<ixx>3.850031249999998e-06</ixx>
					<ixy>0.0</ixy>
					<ixz>0.0</ixz>
					<iyy>2.3692499999999994e-06</iyy>
					<iyz>0.0</iyz>
					<izz>3.850031249999998e-06</izz>
				</inertia>
			</inertial>
			<collision name="collision">
				<geometry>
					<box>
						<size>0.03 0.045 0.03</size>
					</box>
				</geometry>
				<surface>
					<friction>
						<ode>
							<mu>0.6</mu>
							<mu2>0.6</mu2>
						</ode>
					</friction>
				</surface>
			</collision>
			<visual name="black">
				<geometry>
					<box>
						<size>0.03 0.045 0.03</size>
					</box>
				</geometry>
				<material>
					<diffuse>0 0 0 1</diffuse>
				</material>
			</visual>
			<visual name="red">
				<pose>-0.015 0.0 0.0 0.0 0.0 0.0</pose>
				<geometry>
					<box>
						<size>0.00025 0.04 0.025</size>
					</box>
				</geometry>
				<material>
					<diffuse>1 0 0 1</diffuse>
				</material>
			</visual>
			<visual name="green">
				<pose>0.0 -0.0225 0.0 0.0 0.0 0.0</pose>
				<geometry>
					<box>
						<size>0.025 0.0004 0.025</size>
					</box>
				</geometry>
				<material>
					<diffuse>0 1 0 1</diffuse>
				</material>
			</visual>
			<visual name="yellow">
				<pose>0.0 0.0 0.015 0.0 0.0 0.0</pose>
				<geometry>
					<box>
						<size>0.025 0.04 0.00025</size>
					</box>
				</geometry>
				<material>
					<diffuse>1 1 0 1</diffuse>
				</material>
			</visual>
		</link>
		<joint name="ball_0_0_1" type="ball">
			<pose>0.01505 0.02255 -0.01505 -0.0 -0.0 -0.0</pose>
			<parent>center</parent>
			<child>cubie_0_0_1</child>
			<axis>
				<dynamics>
					<damping>0.1</damping>
				</dynamics>
				<limit>
					<effort>0</effort>
				</limit>
			</axis>
		</joint>
		<link name="cubie_0_1_0">
			<pose>-0.01505 0.02255 -0.03005 0.0 0.0 0.0</pose>
			<inertial>
				<mass>0.03158999999999999</mass>
				<inertia>
					<ixx>1.4807812499999997e-05</ixx>
					<ixy>0.0</ixy>
					<ixz>0.0</ixz>
					<iyy>1.1846249999999997e-05</iyy>
					<iyz>0.0</iyz>
					<izz>7.700062499999997e-06</izz>
				</inertia>
			</inertial>
			<collision name="collision">
				<geometry>
					<box>
						<size>0.03 0.045 0.06</size>
					</box>
				</geometry>
				<surface>
					<friction>
						<ode>
							<mu>0.6</mu>
							<mu2>0.6</mu2>
						</ode>
					</friction>
				</surface>
			</collision>
			<visual name="black">
				<geometry>
					<box>
						<size>0.03 0.045 0.06</size>
					</box>
				</geometry>
				<material>
					<diffuse>0 0 0 1</diffuse>
				</material>
			</visual>
			<visual name="red">
				<pose>-0.015 0.0 0.0 0.0 0.0 0.0</pose>
				<geometry>
					<box>
						<size>0.00025 0.04 0.055</size>
					</box>
				</geometry>
				<material>
					<diffuse>1 0 0 1</diffuse>
				</material>
			</visual>
			<visual name="blue">
				<pose>0.0 0.0225 0.0 0.0 0.0 0.0</pose>
				<geometry>
					<box>
						<size>0.025 0.0004 0.055</size>
					</box>
				</geometry>
				<material>
					<diffuse>0 0 1 1</diffuse>
				</material>
			</visual>
			<visual name="white">
				<pose>0.0 0.0 -0.03 0.0 0.0 0.0</pose>
				<geometry>
					<box>
						<size>0.025 0.04 0.00055</size>
					</box>
				</geometry>
				<material>
					<diffuse>1 1 1 1</diffuse>
				</material>
			</visual>
		</link>
		<joint name="ball_0_1_0" type="ball">
			<pose>0.01505 -0.02255 0.03005 -0.0 -0.0 -0.0</pose>
			<parent>center</parent>
			<child>cubie_0_1_0</child>
			<axis>
				<dynamics>
					<damping>0.1</damping>
				</dynamics>
				<limit>
					<effort>0</effort>
				</limit>
			</axis>
		</joint>
		<link name="cubie_0_1_1">
			<pose>-0.01505 0.02255 0.01505 0.0 0.0 0.0</pose>
			<inertial>
				<mass>0.015794999999999997</mass>
				<inertia>
					<ixx>3.850031249999998e-06</ixx>
					<ixy>0.0</ixy>
					<ixz>0.0</ixz>
					<iyy>2.3692499999999994e-06</iyy>
					<iyz>0.0</iyz>
					<izz>3.850031249999998e-06</izz>
				</inertia>
			</inertial>
			<collision name="collision">
				<geometry>
					<box>
						<size>0.03 0.045 0.03</size>
					</box>
				</geometry>
				<surface>
					<friction>
						<ode>
							<mu>0.6</mu>
							<mu2>0.6</mu2>
						</ode>
					</friction>
				</surface>
			</collision>
			<visual name="black">
				<geometry>
					<box>
						<size>0.03 0.045 0.03</size>
					</box>
				</geometry>
				<material>
					<diffuse>0 0 0 1</diffuse>
				</material>
			</visual>
			<visual name="red">
				<pose>-0.015 0.0 0.0 0.0 0.0 0.0</pose>
				<geometry>
					<box>
						<size>0.00025 0.04 0.025</size>
					</box>
				</geometry>
				<material>
					<diffuse>1 0 0 1</diffuse>
				</material>
			</visual>
			<visual name="blue">
				<pose>0.0 0.0225 0.0 0.0 0.0 0.0</pose>
				<geometry>
					<box>
						<size>0.025 0.0004 0.025</size>
					</box>
				</geometry>
				<material>
					<diffuse>0 0 1 1</diffuse>
				</material>
			</visual>
			<visual name="yellow">
				<pose>0.0 0.0 0.015 0.0 0.0 0.0</pose>
				<geometry>
					<box>
						<size>0.025 0.04 0.00025</size>
					</box>
				</geometry>
				<material>
					<diffuse>1 1 0 1</diffuse>
				</material>
			</visual>
		</link>
		<joint name="ball_0_1_1" type="ball">
			<pose>0.01505 -0.02255 -0.01505 -0.0 -0.0 -0.0</pose>
			<parent>center</parent>
			<child>cubie_0_1_1</child>
			<axis>
				<dynamics>
					<damping>0.1</damping>
				</dynamics>
				<limit>
					<effort>0</effort>
				</limit>
			</axis>
		</joint>
		<link name="cubie_1_0_0">
			<pose>0.03005 -0.02255 -0.03005 0.0 0.0 0.0</pose>
			<inertial>
				<mass>0.06317999999999999</mass>
				<inertia>
					<ixx>2.9615624999999993e-05</ixx>
					<ixy>0.0</ixy>
					<ixz>0.0</ixz>
					<iyy>3.790799999999999e-05</iyy>
					<iyz>0.0</iyz>
					<izz>2.9615624999999993e-05</izz>
				</inertia>
			</inertial>
			<collision name="collision">
				<geometry>
					<box>
						<size>0.06 0.045 0.06</size>
					</box>
				</geometry>
				<surface>
					<friction>
						<ode>
							<mu>0.6</mu>
							<mu2>0.6</mu2>
						</ode>
					</friction>
				</surface>
			</collision>
			<visual name="black">
				<geometry>
					<box>
						<size>0.06 0.045 0.06</size>
					</box>
				</geometry>
				<material>
					<diffuse>0 0 0 1</diffuse>
				</material>
			</visual>
			<visual name="orange">
				<pose>0.03 0.0 0.0 0.0 0.0 0.0</pose>
				<geometry>
					<box>
						<size>0.00055 0.04 0.055</size>
					</box>
				</geometry>
				<material>
					<diffuse>1.0 0.5 0.0 1.0</diffuse>
				</material>
			</visual>
			<visual name="green">
				<pose>0.0 -0.0225 0.0 0.0 0.0 0.0</pose>
				<geometry>
					<box>
						<size>0.055 0.0004 0.055</size>
					</box>
				</geometry>
				<material>
					<diffuse>0 1 0 1</diffuse>
				</material>
			</visual>
			<visual name="white">
				<pose>0.0 0.0 -0.03 0.0 0.0 0.0</pose>
				<geometry>
					<box>
						<size>0.055 0.04 0.00055</size>
					</box>
				</geometry>
				<material>
					<diffuse>1 1 1 1</diffuse>
				</material>
			</visual>
		</link>
		<joint name="ball_1_0_0" type="ball">
			<pose>-0.03005 0.02255 0.03005 -0.0 -0.0 -0.0</pose>
			<parent>center</parent>
			<child>cubie_1_0_0</child>
			<axis>
				<dynamics>
					<damping>0.1</damping>
				</dynamics>
				<limit>
					<effort>0</effort>
				</limit>
			</axis>
		</joint>
		<link name="cubie_1_0_1">
			<pose>0.03005 -0.02255 0.01505 0.0 0.0 0.0</pose>
			<inertial>
				<mass>0.03158999999999999</mass>
				<inertia>
					<ixx>7.700062499999997e-06</ixx>
					<ixy>0.0</ixy>
					<ixz>0.0</ixz>
					<iyy>1.1846249999999997e-05</iyy>
					<iyz>0.0</iyz>
					<izz>1.4807812499999997e-05</izz>
				</inertia>
			</inertial>
			<collision name="collision">
				<geometry>
					<box>
						<size>0.06 0.045 0.03</size>
					</box>
				</geometry>
				<surface>
					<friction>
						<ode>
							<mu>0.6</mu>
							<mu2>0.6</mu2>
						</ode>
					</friction>
				</surface>
			</collision>
			<visual name="black">
				<geometry>
					<box>
						<size>0.06 0.045 0.03</size>
					</box>
				</geometry>
				<material>
					<diffuse>0 0 0 1</diffuse>
				</material>
			</visual>
			<visual name="orange">
				<pose>0.03 0.0 0.0 0.0 0.0 0.0</pose>
				<geometry>
					<box>
						<size>0.00055 0.04 0.025</size>
					</box>
				</geometry>
				<material>
					<diffuse>1.0 0.5 0.0 1.0</diffuse>
				</material>
			</visual>
			<visual name="green">
				<pose>0.0 -0.0225 0.0 0.0 0.0 0.0</pose>
				<geometry>
					<box>
						<size>0.055 0.0004 0.025</size>
					</box>
				</geometry>
				<material>
					<diffuse>0 1 0 1</diffuse>
				</material>
			</visual>
			<visual name="yellow">
				<pose>0.0 0.0 0.015 0.0 0.0 0.0</pose>
				<geometry>
					<box>
						<size>0.055 0.04 0.00025</size>
					</box>
				</geometry>
				<material>
					<diffuse>1 1 0 1</diffuse>
				</material>
			</visual>
		</link>
		<joint name="ball_1_0_1" type="ball">
			<pose>-0.03005 0.02255 -0.01505 -0.0 -0.0 -0.0</pose>
			<parent>center</parent>
			<child>cubie_1_0_1</child>
			<axis>
				<dynamics>
					<damping>0.1</damping>
				</dynamics>
				<limit>
					<effort>0</effort>
				</limit>
			</axis>
		</joint>
		<link name="cubie_1_1_0">
			<pose>0.03005 0.02255 -0.03005 0.0 0.0 0.0</pose>
			<inertial>
				<mass>0.06317999999999999</mass>
				<inertia>
					<ixx>2.9615624999999993e-05</ixx>
					<ixy>0.0</ixy>
					<ixz>0.0</ixz>
					<iyy>3.790799999999999e-05</iyy>
					<iyz>0.0</iyz>
					<izz>2.9615624999999993e-05</izz>
				</inertia>
			</inertial>
			<collision name="collision">
				<geometry>
					<box>
						<size>0.06 0.045 0.06</size>
					</box>
				</geometry>
				<surface>
					<friction>
						<ode>
							<mu>0.6</mu>
							<mu2>0.6</mu2>
						</ode>
					</friction>
				</surface>
			</collision>
			<visual name="black">
				<geometry>
					<box>
						<size>0.06 0.045 0.06</size>
					</box>
				</geometry>
				<material>
					<diffuse>0 0 0 1</diffuse>
				</material>
			</visual>
			<visual name="orange">
				<pose>0.03 0.0 0.0 0.0 0.0 0.0</pose>
				<geometry>
					<box>
						<size>0.00055 0.04 0.055</size>
					</box>
				</geometry>
				<material>
					<diffuse>1.0 0.5 0.0 1.0</diffuse>
				</material>
			</visual>
			<visual name="blue">
				<pose>0.0 0.0225 0.0 0.0 0.0 0.0</pose>
				<geometry>
					<box>
						<size>0.055 0.0004 0.055</size>
					</box>
				</geometry>
				<material>
					<diffuse>0 0 1 1</diffuse>
				</material>
			</visual>
			<visual name="white">
				<pose>0.0 0.0 -0.03 0.0 0.0 0.0</pose>
				<geometry>
					<box>
						<size>0.055 0.04 0.00055</size>
					</box>
				</geometry>
				<material>
					<diffuse>1 1 1 1</diffuse>
				</material>
			</visual>
		</link>
		<joint name="ball_1_1_0" type="ball">
			<pose>-0.03005 -0.02255 0.03005 -0.0 -0.0 -0.0</pose>
			<parent>center</parent>
			<child>cubie_1_1_0</child>
			<axis>
				<dynamics>
					<damping>0.1</damping>
				</dynamics>
				<limit>
					<effort>0</effort>
				</limit>
			</axis>
		</joint>
		<link name="cubie_1_1_1">
			<pose>0.03005 0.02255 0.01505 0.0 0.0 0.0</pose>
			<inertial>
				<mass>0.03158999999999999</mass>
				<inertia>
					<ixx>7.700062499999997e-06</ixx>
					<ixy>0.0</ixy>
					<ixz>0.0</ixz>
					<iyy>1.1846249999999997e-05</iyy>
					<iyz>0.0</iyz>
					<izz>1.4807812499999997e-05</izz>
				</inertia>
			</inertial>
			<collision name="collision">
				<geometry>
					<box>
						<size>0.06 0.045 0.03</size>
					</box>
				</geometry>
				<surface>
					<friction>
						<ode>
							<mu>0.6</mu>
							<mu2>0.6</mu2>
						</ode>
					</friction>
				</surface>
			</collision>
			<visual name="black">
				<geometry>
					<box>
						<size>0.06 0.045 0.03</size>
					</box>
				</geometry>
				<material>
					<diffuse>0 0 0 1</diffuse>
				</material>
			</visual>
			<visual name="orange">
				<pose>0.03 0.0 0.0 0.0 0.0 0.0</pose>
				<geometry>
					<box>
						<size>0.00055 0.04 0.025</size>
					</box>
				</geometry>
				<material>
					<diffuse>1.0 0.5 0.0 1.0</diffuse>
				</material>
			</visual>
			<visual name="blue">
				<pose>0.0 0.0225 0.0 0.0 0.0 0.0</pose>
				<geometry>
					<box>
						<size>0.055 0.0004 0.025</size>
					</box>
				</geometry>
				<material>
					<diffuse>0 0 1 1</diffuse>
				</material>
			</visual>
			<visual name="yellow">
				<pose>0.0 0.0 0.015 0.0 0.0 0.0</pose>
				<geometry>
					<box>
						<size>0.055 0.04 0.00025</size>
					</box>
				</geometry>
				<material>
					<diffuse>1 1 0 1</diffuse>
				</material>
			</visual>
		</link>
		<joint name="ball_1_1_1" type="ball">
			<pose>-0.03005 -0.02255 -0.01505 -0.0 -0.0 -0.0</pose>
			<parent>center</parent>
			<child>cubie_1_1_1</child>
			<axis>
				<dynamics>
					<damping>0.1</damping>
				</dynamics>
				<limit>
					<effort>0</effort>
				</limit>
			</axis>
		</joint>
	</model>
</sdf>
