<?xml version="1.0" ?>
<sdf version="1.7">
	<model name="mirror_cube_2x2">
		<link name="center"/>
		<link name="cubie_0_0_0">
			<pose>-0.017550000000000003 -0.020050000000000002 -0.02255 0.0 0.0 0.0</pose>
			<inertial>
				<mass>0.024570000000000005</mass>
				<inertia>
					<ixx>7.422187500000001e-06</ixx>
					<ixy>0.0</ixy>
					<ixz>0.0</ixz>
					<iyy>6.654375000000002e-06</iyy>
					<iyz>0.0</iyz>
					<izz>5.784187500000001e-06</izz>
				</inertia>
			</inertial>
			<collision name="collision">
				<geometry>
					<box>
						<size>0.035 0.04 0.045</size>
					</box>
				</geometry>
				<surface>
					<friction>
						<ode>
							<mu>0.6</mu>
							<mu2>0.6</mu2>
						</ode>
					</friction>
				</surface>
			</collision>
			<visual name="black">
				<geometry>
					<box>
						<size>0.035 0.04 0.045</size>
					</box>
				</geometry>
				<material>
					<diffuse>0 0 0 1</diffuse>
				</material>
			</visual>
			<visual name="red">
				<pose>-0.0175 0.0 0.0 0.0 0.0 0.0</pose>
				<geometry>
					<box>
						<size>0.0003 0.035 0.04</size>
					</box>
				</geometry>
				<material>
					<diffuse>1 0 0 1</diffuse>
				</material>
			</visual>
			<visual name="green">
				<pose>0.0 -0.02 0.0 0.0 0.0 0.0</pose>
				<geometry>
					<box>
						<size>0.03 0.00035 0.04</size>
					</box>
				</geometry>
				<material>
					<diffuse>0 1 0 1</diffuse>
				</material>
			</visual>
			<visual name="white">
				<pose>0.0 0.0 -0.0225 0.0 0.0 0.0</pose>
				<geometry>
					<box>
						<size>0.03 0.035 0.0004</size>
					</box>
				</geometry>
				<material>
					<diffuse>1 1 1 1</diffuse>
				</material>
			</visual>
		</link>
		<joint name="ball_0_0_0" type="ball">
			<pose>0.017550000000000003 0.020050000000000002 0.02255 -0.0 -0.0 -0.0</pose>
			<parent>center</parent>
			<child>cubie_0_0_0</child>
			<axis>
				<dynamics>
					<damping>0.1</damping>
				</dynamics>
				<limit>
					<effort>0</effort>
				</limit>
			</axis>
		</joint>
		<link name="cubie_0_0_1">
			<pose>-0.017550000000000003 -0.020050000000000002 0.017550000000000003 0.0 0.0 0.0</pose>
			<inertial>
				<mass>0.019110000000000005</mass>
				<inertia>
					<ixx>4.498812500000002e-06</ixx>
					<ixy>0.0</ixy>
					<ixz>0.0</ixz>
					<iyy>3.901625000000002e-06</iyy>
					<iyz>0.0</iyz>
					<izz>4.498812500000002e-06</izz>
				</inertia>
			</inertial>
			<collision name="collision">
				<geometry>
					<box>
						<size>0.035 0.04 0.035</size>
					</box>
				</geometry>
				<surface>
					<friction>
						<ode>
							<mu>0.6</mu>
							<mu2>0.6</mu2>
						</ode>
					</friction>
				</surface>
			</collision>
			<visual name="black">
				<geometry>
					<box>
						<size>0.035 0.04 0.035</size>
					</box>
				</geometry>
				<material>
					<diffuse>0 0 0 1</diffuse>
				</material>
			</visual>
			<visual name="red">
				<pose>-0.0175 0.0 0.0 0.0 0.0 0.0</pose>
				<geometry>
					<box>
						<size>0.0003 0.035 0.03</size>
					</box>
				</geometry>
				<material>
					<diffuse>1 0 0 1</diffuse>
				</material>
			</visual>
			<visual name="green">
				<pose>0.0 -0.02 0.0 0.0 0.0 0.0</pose>
				<geometry>
					<box>
						<size>0.03 0.00035 0.03</size>
					</box>
				</geometry>
				<material>
					<diffuse>0 1 0 1</diffuse>
				</material>
			</visual>
			<visual name="yellow">
				<pose>0.0 0.0 0.0175 0.0 0.0 0.0</pose>
				<geometry>
					<box>
						<size>0.03 0.035 0.0003</size>
					</box>
				</geometry>
				<material>
					<diffuse>1 1 0 1</diffuse>
				</material>
			</visual>
		</link>
		<joint name="ball_0_0_1" type="ball">
			<pose>0.017550000000000003 0.020050000000000002 -0.017550000000000003 -0.0 -0.0 -0.0</pose>
			<parent>center</parent>
			<child>cubie_0_0_1</child>
			<axis>
				<dynamics>
					<damping>0.1</damping>
				</dynamics>
				<limit>
					<effort>0</effort>
				</limit>
			</axis>
		</joint>
		<link name="cubie_0_1_0">
			<pose>-0.017550000000000003 0.020050000000000002 -0.02255 0.0 0.0 0.0</pose>
			<inertial>
				<mass>0.024570000000000005</mass>
				<inertia>
					<ixx>7.422187500000001e-06</ixx>
					<ixy>0.0</ixy>
					<ixz>0.0</ixz>
					<iyy>6.654375000000002e-06</iyy>
					<iyz>0.0</iyz>
					<izz>5.784187500000001e-06</izz>
				</inertia>
			</inertial>
			<collision name="collision">
				<geometry>
					<box>
						<size>0.035 0.04 0.045</size>
					</box>
				</geometry>
				<surface>
					<friction>
						<ode>
							<mu>0.6</mu>
							<mu2>0.6</mu2>
						</ode>
					</friction>
				</surface>
			</collision>
			<visual name="black">
				<geometry>
					<box>
						<size>0.035 0.04 0.045</size>
					</box>
				</geometry>
				<material>
					<diffuse>0 0 0 1</diffuse>
				</material>
			</visual>
			<visual name="red">
				<pose>-0.0175 0.0 0.0 0.0 0.0 0.0</pose>
				<geometry>
					<box>
						<size>0.0003 0.035 0.04</size>
					</box>
				</geometry>
				<material>
					<diffuse>1 0 0 1</diffuse>
				</material>
			</visual>
			<visual name="blue">
				<pose>0.0 0.02 0.0 0.0 0.0 0.0</pose>
				<geometry>
					<box>
						<size>0.03 0.00035 0.04</size>
					</box>
				</geometry>
				<material>
					<diffuse>0 0 1 1</diffuse>
				</material>
			</visual>
			<visual name="white">
				<pose>0.0 0.0 -0.0225 0.0 0.0 0.0</pose>
				<geometry>
					<box>
						<size>0.03 0.035 0.0004</size>
					</box>
				</geometry>
				<material>
					<diffuse>1 1 1 1</diffuse>
				</material>
			</visual>
		</link>
		<joint name="ball_0_1_0" type="ball">
			<pose>0.017550000000000003 -0.020050000000000002 0.02255 -0.0 -0.0 -0.0</pose>
			<parent>center</parent>
			<child>cubie_0_1_0</child>
			<axis>
				<dynamics>
					<damping>0.1</damping>
				</dynamics>
				<limit>
					<effort>0</effort>
				</limit>
			</axis>
		</joint>
		<link name="cubie_0_1_1">
			<pose>-0.017550000000000003 0.020050000000000002 0.017550000000000003 0.0 0.0 0.0</pose>
			<inertial>
				<mass>0.019110000000000005</mass>
				<inertia>
					<ixx>4.498812500000002e-06</ixx>
					<ixy>0.0</ixy>
					<ixz>0.0</ixz>
					<iyy>3.901625000000002e-06</iyy>
					<iyz>0.0</iyz>
					<izz>4.498812500000002e-06</izz>
				</inertia>
			</inertial>
			<collision name="collision">
				<geometry>
					<box>
						<size>0.035 0.04 0.035</size>
					</box>
				</geometry>
				<surface>
					<friction>
						<ode>
							<mu>0.6</mu>
							<mu2>0.6</mu2>
						</ode>
					</friction>
				</surface>
			</collision>
			<visual name="black">
				<geometry>
					<box>
						<size>0.035 0.04 0.035</size>
					</box>
				</geometry>
				<material>
					<diffuse>0 0 0 1</diffuse>
				</material>
			</visual>
			<visual name="red">
				<pose>-0.0175 0.0 0.0 0.0 0.0 0.0</pose>
				<geometry>
					<box>
						<size>0.0003 0.035 0.03</size>
					</box>
				</geometry>
				<material>
					<diffuse>1 0 0 1</diffuse>
				</material>
			</visual>
			<visual name="blue">
				<pose>0.0 0.02 0.0 0.0 0.0 0.0</pose>
				<geometry>
					<box>
						<size>0.03 0.00035 0.03</size>
					</box>
				</geometry>
				<material>
					<diffuse>0 0 1 1</diffuse>
				</material>
			</visual>
			<visual name="yellow">
				<pose>0.0 0.0 0.0175 0.0 0.0 0.0</pose>
				<geometry>
					<box>
						<size>0.03 0.035 0.0003</size>
					</box>
				</geometry>
				<material>
					<diffuse>1 1 0 1</diffuse>
				</material>
			</visual>
		</link>
		<joint name="ball_0_1_1" type="ball">
			<pose>0.017550000000000003 -0.020050000000000002 -0.017550000000000003 -0.0 -0.0 -0.0</pose>
			<parent>center</parent>
			<child>cubie_0_1_1</child>
			<axis>
				<dynamics>
					<damping>0.1</damping>
				</dynamics>
				<limit>
					<effort>0</effort>
				</limit>
			</axis>
		</joint>
		<link name="cubie_1_0_0">
			<pose>0.02255 -0.020050000000000002 -0.02255 0.0 0.0 0.0</pose>
			<inertial>
				<mass>0.03158999999999999</mass>
				<inertia>
					<ixx>9.542812499999997e-06</ixx>
					<ixy>0.0</ixy>
					<ixz>0.0</ixz>
					<iyy>1.0661624999999996e-05</iyy>
					<iyz>0.0</iyz>
					<izz>9.542812499999997e-06</izz>
				</inertia>
			</inertial>
			<collision name="collision">
				<geometry>
					<box>
						<size>0.045 0.04 0.045</size>
					</box>
				</geometry>
				<surface>
					<friction>
						<ode>
							<mu>0.6</mu>
							<mu2>0.6</mu2>
						</ode>
					</friction>
				</surface>
			</collision>
			<visual name="black">
				<geometry>
					<box>
						<size>0.045 0.04 0.045</size>
					</box>
				</geometry>
				<material>
					<diffuse>0 0 0 1</diffuse>
				</material>
			</visual>
			<visual name="orange">
				<pose>0.0225 0.0 0.0 0.0 0.0 0.0</pose>
				<geometry>
					<box>
						<size>0.0004 0.035 0.04</size>
					</box>
				</geometry>
				<material>
					<diffuse>1.0 0.5 0.0 1.0</diffuse>
				</material>
			</visual>
			<visual name="green">
				<pose>0.0 -0.02 0.0 0.0 0.0 0.0</pose>
				<geometry>
					<box>
						<size>0.04 0.00035 0.04</size>
					</box>
				</geometry>
				<material>
					<diffuse>0 1 0 1</diffuse>
				</material>
			</visual>
			<visual name="white">
				<pose>0.0 0.0 -0.0225 0.0 0.0 0.0</pose>
				<geometry>
					<box>
						<size>0.04 0.035 0.0004</size>
					</box>
				</geometry>
				<material>
					<diffuse>1 1 1 1</diffuse>
				</material>
			</visual>
		</link>
		<joint name="ball_1_0_0" type="ball">
			<pose>-0.02255 0.020050000000000002 0.02255 -0.0 -0.0 -0.0</pose>
			<parent>center</parent>
			<child>cubie_1_0_0</child>
			<axis>
				<dynamics>
					<damping>0.1</damping>
				</dynamics>
				<limit>
					<effort>0</effort>
				</limit>
			</axis>
		</joint>
		<link name="cubie_1_0_1">
			<pose>0.02255 -0.020050000000000002 0.017550000000000003 0.0 0.0 0.0</pose>
			<inertial>
				<mass>0.02457</mass>
				<inertia>
					<ixx>5.784187500000001e-06</ixx>
					<ixy>0.0</ixy>
					<ixz>0.0</ixz>
					<iyy>6.654375000000002e-06</iyy>
					<iyz>0.0</iyz>
					<izz>7.422187500000001e-06</izz>
				</inertia>
			</inertial>
			<collision name="collision">
				<geometry>
					<box>
						<size>0.045 0.04 0.035</size>
					</box>
				</geometry>
				<surface>
					<friction>
						<ode>
							<mu>0.6</mu>
							<mu2>0.6</mu2>
						</ode>
					</friction>
				</surface>
			</collision>
			<visual name="black">
				<geometry>
					<box>
						<size>0.045 0.04 0.035</size>
					</box>
				</geometry>
				<material>
					<diffuse>0 0 0 1</diffuse>
				</material>
			</visual>
			<visual name="orange">
				<pose>0.0225 0.0 0.0 0.0 0.0 0.0</pose>
				<geometry>
					<box>
						<size>0.0004 0.035 0.03</size>
					</box>
				</geometry>
				<material>
					<diffuse>1.0 0.5 0.0 1.0</diffuse>
				</material>
			</visual>
			<visual name="green">
				<pose>0.0 -0.02 0.0 0.0 0.0 0.0</pose>
				<geometry>
					<box>
						<size>0.04 0.00035 0.03</size>
					</box>
				</geometry>
				<material>
					<diffuse>0 1 0 1</diffuse>
				</material>
			</visual>
			<visual name="yellow">
				<pose>0.0 0.0 0.0175 0.0 0.0 0.0</pose>
				<geometry>
					<box>
						<size>0.04 0.035 0.0003</size>
					</box>
				</geometry>
				<material>
					<diffuse>1 1 0 1</diffuse>
				</material>
			</visual>
		</link>
		<joint name="ball_1_0_1" type="ball">
			<pose>-0.02255 0.020050000000000002 -0.017550000000000003 -0.0 -0.0 -0.0</pose>
			<parent>center</parent>
			<child>cubie_1_0_1</child>
			<axis>
				<dynamics>
					<damping>0.1</damping>
				</dynamics>
				<limit>
					<effort>0</effort>
				</limit>
			</axis>
		</joint>
		<link name="cubie_1_1_0">
			<pose>0.02255 0.020050000000000002 -0.02255 0.0 0.0 0.0</pose>
			<inertial>
				<mass>0.03158999999999999</mass>
				<inertia>
					<ixx>9.542812499999997e-06</ixx>
					<ixy>0.0</ixy>
					<ixz>0.0</ixz>
					<iyy>1.0661624999999996e-05</iyy>
					<iyz>0.0</iyz>
					<izz>9.542812499999997e-06</izz>
				</inertia>
			</inertial>
			<collision name="collision">
				<geometry>
					<box>
						<size>0.045 0.04 0.045</size>
					</box>
				</geometry>
				<surface>
					<friction>
						<ode>
							<mu>0.6</mu>
							<mu2>0.6</mu2>
						</ode>
					</friction>
				</surface>
			</collision>
			<visual name="black">
				<geometry>
					<box>
						<size>0.045 0.04 0.045</size>
					</box>
				</geometry>
				<material>
					<diffuse>0 0 0 1</diffuse>
				</material>
			</visual>
			<visual name="orange">
				<pose>0.0225 0.0 0.0 0.0 0.0 0.0</pose>
				<geometry>
					<box>
						<size>0.0004 0.035 0.04</size>
					</box>
				</geometry>
				<material>
					<diffuse>1.0 0.5 0.0 1.0</diffuse>
				</material>
			</visual>
			<visual name="blue">
				<pose>0.0 0.02 0.0 0.0 0.0 0.0</pose>
				<geometry>
					<box>
						<size>0.04 0.00035 0.04</size>
					</box>
				</geometry>
				<material>
					<diffuse>0 0 1 1</diffuse>
				</material>
			</visual>
			<visual name="white">
				<pose>0.0 0.0 -0.0225 0.0 0.0 0.0</pose>
				<geometry>
					<box>
						<size>0.04 0.035 0.0004</size>
					</box>
				</geometry>
				<material>
					<diffuse>1 1 1 1</diffuse>
				</material>
			</visual>
		</link>
		<joint name="ball_1_1_0" type="ball">
			<pose>-0.02255 -0.020050000000000002 0.02255 -0.0 -0.0 -0.0</pose>
			<parent>center</parent>
			<child>cubie_1_1_0</child>
			<axis>
				<dynamics>
					<damping>0.1</damping>
				</dynamics>
				<limit>
					<effort>0</effort>
				</limit>
			</axis>
		</joint>
		<link name="cubie_1_1_1">
			<pose>0.02255 0.020050000000000002 0.017550000000000003 0.0 0.0 0.0</pose>
			<inertial>
				<mass>0.02457</mass>
				<inertia>
					<ixx>5.784187500000001e-06</ixx>
					<ixy>0.0</ixy>
					<ixz>0.0</ixz>
					<iyy>6.654375000000002e-06</iyy>
					<iyz>0.0</iyz>
					<izz>7.422187500000001e-06</izz>
				</inertia>
			</inertial>
			<collision name="collision">
				<geometry>
					<box>
						<size>0.045 0.04 0.035</size>
					</box>
				</geometry>
				<surface>
					<friction>
						<ode>
							<mu>0.6</mu>
							<mu2>0.6</mu2>
						</ode>
					</friction>
				</surface>
			</collision>
			<visual name="black">
				<geometry>
					<box>
						<size>0.045 0.04 0.035</size>
					</box>
				</geometry>
				<material>
					<diffuse>0 0 0 1</diffuse>
				</material>
			</visual>
			<visual name="orange">
				<pose>0.0225 0.0 0.0 0.0 0.0 0.0</pose>
				<geometry>
					<box>
						<size>0.0004 0.035 0.03</size>
					</box>
				</geometry>
				<material>
					<diffuse>1.0 0.5 0.0 1.0</diffuse>
				</material>
			</visual>
			<visual name="blue">
				<pose>0.0 0.02 0.0 0.0 0.0 0.0</pose>
				<geometry>
					<box>
						<size>0.04 0.00035 0.03</size>
					</box>
				</geometry>
				<material>
					<diffuse>0 0 1 1</diffuse>
				</material>
			</visual>
			<visual name="yellow">
				<pose>0.0 0.0 0.0175 0.0 0.0 0.0</pose>
				<geometry>
					<box>
						<size>0.04 0.035 0.0003</size>
					</box>
				</geometry>
				<material>
					<diffuse>1 1 0 1</diffuse>
				</material>
			</visual>
		</link>
		<joint name="ball_1_1_1" type="ball">
			<pose>-0.02255 -0.020050000000000002 -0.017550000000000003 -0.0 -0.0 -0.0</pose>
			<parent>center</parent>
			<child>cubie_1_1_1</child>
			<axis>
				<dynamics>
					<damping>0.1</damping>
				</dynamics>
				<limit>
					<effort>0</effort>
				</limit>
			</axis>
		</joint>
	</model>
</sdf>
