<?xml version="1.0" ?>
<sdf version="1.7">
	<model name="mirror_cube_2x2">
		<link name="center"/>
		<link name="cubie_0_0_0">
			<pose>-0.010050000000000002 -0.017550000000000003 -0.025050000000000003 0.0 0.0 0.0</pose>
			<inertial>
				<mass>0.013650000000000004</mass>
				<inertia>
					<ixx>4.237187500000002e-06</ixx>
					<ixy>0.0</ixy>
					<ixz>0.0</ixz>
					<iyy>3.2987500000000017e-06</iyy>
					<iyz>0.0</iyz>
					<izz>1.8484375000000009e-06</izz>
				</inertia>
			</inertial>
			<collision name="collision">
				<geometry>
					<box>
						<size>0.020000000000000004 0.035 0.05</size>
					</box>
				</geometry>
				<surface>
					<friction>
						<ode>
							<mu>0.6</mu>
							<mu2>0.6</mu2>
						</ode>
					</friction>
				</surface>
			</collision>
			<visual name="black">
				<geometry>
					<box>
						<size>0.020000000000000004 0.035 0.05</size>
					</box>
				</geometry>
				<material>
					<diffuse>0 0 0 1</diffuse>
				</material>
			</visual>
			<visual name="red">
				<pose>-0.010000000000000002 0.0 0.0 0.0 0.0 0.0</pose>
				<geometry>
					<box>
						<size>0.00015 0.03 0.045</size>
					</box>
				</geometry>
				<material>
					<diffuse>1 0 0 1</diffuse>
				</material>
			</visual>
			<visual name="green">
				<pose>0.0 -0.0175 0.0 0.0 0.0 0.0</pose>
				<geometry>
					<box>
						<size>0.015 0.0003 0.045</size>
					</box>
				</geometry>
				<material>
					<diffuse>0 1 0 1</diffuse>
				</material>
			</visual>
			<visual name="white">
				<pose>0.0 0.0 -0.025 0.0 0.0 0.0</pose>
				<geometry>
					<box>
						<size>0.015 0.03 0.00045</size>
					</box>
				</geometry>
				<material>
					<diffuse>1 1 1 1</diffuse>
				</material>
			</visual>
		</link>
		<joint name="ball_0_0_0" type="ball">
			<pose>0.010050000000000002 0.017550000000000003 0.025050000000000003 -0.0 -0.0 -0.0</pose>
			<parent>center</parent>
			<child>cubie_0_0_0</child>
			<axis>
				<dynamics>
					<damping>0.1</damping>
				</dynamics>
				<limit>
					<effort>0</effort>
				</limit>
			</axis>
		</joint>
		<link name="cubie_0_0_1">
			<pose>-0.010050000000000002 -0.017550000000000003 0.010050000000000002 0.0 0.0 0.0</pose>
			<inertial>
				<mass>0.005460000000000002</mass>
				<inertia>
					<ixx>7.393750000000004e-07</ixx>
					<ixy>0.0</ixy>
					<ixz>0.0</ixz>
					<iyy>3.640000000000003e-07</iyy>
					<iyz>0.0</iyz>
					<izz>7.393750000000004e-07</izz>
				</inertia>
			</inertial>
			<collision name="collision">
				<geometry>
					<box>
						<size>0.020000000000000004 0.035 0.020000000000000004</size>
					</box>
				</geometry>
				<surface>
					<friction>
						<ode>
							<mu>0.6</mu>
							<mu2>0.6</mu2>
						</ode>
					</friction>
				</surface>
			</collision>
			<visual name="black">
				<geometry>
					<box>
						<size>0.020000000000000004 0.035 0.020000000000000004</size>
					</box>
				</geometry>
				<material>
					<diffuse>0 0 0 1</diffuse>
				</material>
			</visual>
			<visual name="red">
				<pose>-0.010000000000000002 0.0 0.0 0.0 0.0 0.0</pose>
				<geometry>
					<box>
						<size>0.00015 0.03 0.015</size>
					</box>
				</geometry>
				<material>
					<diffuse>1 0 0 1</diffuse>
				</material>
			</visual>
			<visual name="green">
				<pose>0.0 -0.0175 0.0 0.0 0.0 0.0</pose>
				<geometry>
					<box>
						<size>0.015 0.0003 0.015</size>
					</box>
				</geometry>
				<material>
					<diffuse>0 1 0 1</diffuse>
				</material>
			</visual>
			<visual name="yellow">
				<pose>0.0 0.0 0.010000000000000002 0.0 0.0 0.0</pose>
				<geometry>
					<box>
						<size>0.015 0.03 0.00015</size>
					</box>
				</geometry>
				<material>
					<diffuse>1 1 0 1</diffuse>
				</material>
			</visual>
		</link>
		<joint name="ball_0_0_1" type="ball">
			<pose>0.010050000000000002 0.017550000000000003 -0.010050000000000002 -0.0 -0.0 -0.0</pose>
			<parent>center</parent>
			<child>cubie_0_0_1</child>
			<axis>
				<dynamics>
					<damping>0.1</damping>
				</dynamics>
				<limit>
					<effort>0</effort>
				</limit>
			</axis>
		</joint>
		<link name="cubie_0_1_0">
			<pose>-0.010050000000000002 0.017550000000000003 -0.025050000000000003 0.0 0.0 0.0</pose>
			<inertial>
				<mass>0.013650000000000004</mass>
				<inertia>
					<ixx>4.237187500000002e-06</ixx>
					<ixy>0.0</ixy>
					<ixz>0.0</ixz>
					<iyy>3.2987500000000017e-06</iyy>
					<iyz>0.0</iyz>
					<izz>1.8484375000000009e-06</izz>
				</inertia>
			</inertial>
			<collision name="collision">
				<geometry>
					<box>
						<size>0.020000000000000004 0.035 0.05</size>
					</box>
				</geometry>
				<surface>
					<friction>
						<ode>
							<mu>0.6</mu>
							<mu2>0.6</mu2>
						</ode>
					</friction>
				</surface>
			</collision>
			<visual name="black">
				<geometry>
					<box>
						<size>0.020000000000000004 0.035 0.05</size>
					</box>
				</geometry>
				<material>
					<diffuse>0 0 0 1</diffuse>
				</material>
			</visual>
			<visual name="red">
				<pose>-0.010000000000000002 0.0 0.0 0.0 0.0 0.0</pose>
				<geometry>
					<box>
						<size>0.00015 0.03 0.045</size>
					</box>
				</geometry>
				<material>
					<diffuse>1 0 0 1</diffuse>
				</material>
			</visual>
			<visual name="blue">
				<pose>0.0 0.0175 0.0 0.0 0.0 0.0</pose>
				<geometry>
					<box>
						<size>0.015 0.0003 0.045</size>
					</box>
				</geometry>
				<material>
					<diffuse>0 0 1 1</diffuse>
				</material>
			</visual>
			<visual name="white">
				<pose>0.0 0.0 -0.025 0.0 0.0 0.0</pose>
				<geometry>
					<box>
						<size>0.015 0.03 0.00045</size>
					</box>
				</geometry>
				<material>
					<diffuse>1 1 1 1</diffuse>
				</material>
			</visual>
		</link>
		<joint name="ball_0_1_0" type="ball">
			<pose>0.010050000000000002 -0.017550000000000003 0.025050000000000003 -0.0 -0.0 -0.0</pose>
			<parent>center</parent>
			<child>cubie_0_1_0</child>
			<axis>
				<dynamics>
					<damping>0.1</damping>
				</dynamics>
				<limit>
					<effort>0</effort>
				</limit>
			</axis>
		</joint>
		<link name="cubie_0_1_1">
			<pose>-0.010050000000000002 0.017550000000000003 0.010050000000000002 0.0 0.0 0.0</pose>
			<inertial>
				<mass>0.005460000000000002</mass>
				<inertia>
					<ixx>7.393750000000004e-07</ixx>
					<ixy>0.0</ixy>
					<ixz>0.0</ixz>
					<iyy>3.640000000000003e-07</iyy>
					<iyz>0.0</iyz>
					<izz>7.393750000000004e-07</izz>
				</inertia>
			</inertial>
			<collision name="collision">
				<geometry>
					<box>
						<size>0.020000000000000004 0.035 0.020000000000000004</size>
					</box>
				</geometry>
				<surface>
					<friction>
						<ode>
							<mu>0.6</mu>
							<mu2>0.6</mu2>
						</ode>
					</friction>
				</surface>
			</collision>
			<visual name="black">
				<geometry>
					<box>
						<size>0.020000000000000004 0.035 0.020000000000000004</size>
					</box>
				</geometry>
				<material>
					<diffuse>0 0 0 1</diffuse>
				</material>
			</visual>
			<visual name="red">
				<pose>-0.010000000000000002 0.0 0.0 0.0 0.0 0.0</pose>
				<geometry>
					<box>
						<size>0.00015 0.03 0.015</size>
					</box>
				</geometry>
				<material>
					<diffuse>1 0 0 1</diffuse>
				</material>
			</visual>
			<visual name="blue">
				<pose>0.0 0.0175 0.0 0.0 0.0 0.0</pose>
				<geometry>
					<box>
						<size>0.015 0.0003 0.015</size>
					</box>
				</geometry>
				<material>
					<diffuse>0 0 1 1</diffuse>
				</material>
			</visual>
			<visual name="yellow">
				<pose>0.0 0.0 0.010000000000000002 0.0 0.0 0.0</pose>
				<geometry>
					<box>
						<size>0.015 0.03 0.00015</size>
					</box>
				</geometry>
				<material>
					<diffuse>1 1 0 1</diffuse>
				</material>
			</visual>
		</link>
		<joint name="ball_0_1_1" type="ball">
			<pose>0.010050000000000002 -0.017550000000000003 -0.010050000000000002 -0.0 -0.0 -0.0</pose>
			<parent>center</parent>
			<child>cubie_0_1_1</child>
			<axis>
				<dynamics>
					<damping>0.1</damping>
				</dynamics>
				<limit>
					<effort>0</effort>
				</limit>
			</axis>
		</joint>
		<link name="cubie_1_0_0">
			<pose>0.025050000000000003 -0.017550000000000003 -0.025050000000000003 0.0 0.0 0.0</pose>
			<inertial>
				<mass>0.034125</mass>
				<inertia>
					<ixx>1.0592968750000005e-05</ixx>
					<ixy>0.0</ixy>
					<ixz>0.0</ixz>
					<iyy>1.4218750000000005e-05</iyy>
					<iyz>0.0</iyz>
					<izz>1.0592968750000005e-05</izz>
				</inertia>
			</inertial>
			<collision name="collision">
				<geometry>
					<box>
						<size>0.05 0.035 0.05</size>
					</box>
				</geometry>
				<surface>
					<friction>
						<ode>
							<mu>0.6</mu>
							<mu2>0.6</mu2>
						</ode>
					</friction>
				</surface>
			</collision>
			<visual name="black">
				<geometry>
					<box>
						<size>0.05 0.035 0.05</size>
					</box>
				</geometry>
				<material>
					<diffuse>0 0 0 1</diffuse>
				</material>
			</visual>
			<visual name="orange">
				<pose>0.025 0.0 0.0 0.0 0.0 0.0</pose>
				<geometry>
					<box>
						<size>0.00045 0.03 0.045</size>
					</box>
				</geometry>
				<material>
					<diffuse>1.0 0.5 0.0 1.0</diffuse>
				</material>
			</visual>
			<visual name="green">
				<pose>0.0 -0.0175 0.0 0.0 0.0 0.0</pose>
				<geometry>
					<box>
						<size>0.045 0.0003 0.045</size>
					</box>
				</geometry>
				<material>
					<diffuse>0 1 0 1</diffuse>
				</material>
			</visual>
			<visual name="white">
				<pose>0.0 0.0 -0.025 0.0 0.0 0.0</pose>
				<geometry>
					<box>
						<size>0.045 0.03 0.00045</size>
					</box>
				</geometry>
				<material>
					<diffuse>1 1 1 1</diffuse>
				</material>
			</visual>
		</link>
		<joint name="ball_1_0_0" type="ball">
			<pose>-0.025050000000000003 0.017550000000000003 0.025050000000000003 -0.0 -0.0 -0.0</pose>
			<parent>center</parent>
			<child>cubie_1_0_0</child>
			<axis>
				<dynamics>
					<damping>0.1</damping>
				</dynamics>
				<limit>
					<effort>0</effort>
				</limit>
			</axis>
		</joint>
		<link name="cubie_1_0_1">
			<pose>0.025050000000000003 -0.017550000000000003 0.010050000000000002 0.0 0.0 0.0</pose>
			<inertial>
				<mass>0.013650000000000004</mass>
				<inertia>
					<ixx>1.8484375000000009e-06</ixx>
					<ixy>0.0</ixy>
					<ixz>0.0</ixz>
					<iyy>3.2987500000000017e-06</iyy>
					<iyz>0.0</iyz>
					<izz>4.237187500000002e-06</izz>
				</inertia>
			</inertial>
			<collision name="collision">
				<geometry>
					<box>
						<size>0.05 0.035 0.020000000000000004</size>
					</box>
				</geometry>
				<surface>
					<friction>
						<ode>
							<mu>0.6</mu>
							<mu2>0.6</mu2>
						</ode>
					</friction>
				</surface>
			</collision>
			<visual name="black">
				<geometry>
					<box>
						<size>0.05 0.035 0.020000000000000004</size>
					</box>
				</geometry>
				<material>
					<diffuse>0 0 0 1</diffuse>
				</material>
			</visual>
			<visual name="orange">
				<pose>0.025 0.0 0.0 0.0 0.0 0.0</pose>
				<geometry>
					<box>
						<size>0.00045 0.03 0.015</size>
					</box>
				</geometry>
				<material>
					<diffuse>1.0 0.5 0.0 1.0</diffuse>
				</material>
			</visual>
			<visual name="green">
				<pose>0.0 -0.0175 0.0 0.0 0.0 0.0</pose>
				<geometry>
					<box>
						<size>0.045 0.0003 0.015</size>
					</box>
				</geometry>
				<material>
					<diffuse>0 1 0 1</diffuse>
				</material>
			</visual>
			<visual name="yellow">
				<pose>0.0 0.0 0.010000000000000002 0.0 0.0 0.0</pose>
				<geometry>
					<box>
						<size>0.045 0.03 0.00015</size>
					</box>
				</geometry>
				<material>
					<diffuse>1 1 0 1</diffuse>
				</material>
			</visual>
		</link>
		<joint name="ball_1_0_1" type="ball">
			<pose>-0.025050000000000003 0.017550000000000003 -0.010050000000000002 -0.0 -0.0 -0.0</pose>
			<parent>center</parent>
			<child>cubie_1_0_1</child>
			<axis>
				<dynamics>
					<damping>0.1</damping>
				</dynamics>
				<limit>
					<effort>0</effort>
				</limit>
			</axis>
		</joint>
		<link name="cubie_1_1_0">
			<pose>0.025050000000000003 0.017550000000000003 -0.025050000000000003 0.0 0.0 0.0</pose>
			<inertial>
				<mass>0.034125</mass>
				<inertia>
					<ixx>1.0592968750000005e-05</ixx>
					<ixy>0.0</ixy>
					<ixz>0.0</ixz>
					<iyy>1.4218750000000005e-05</iyy>
					<iyz>0.0</iyz>
					<izz>1.0592968750000005e-05</izz>
				</inertia>
			</inertial>
			<collision name="collision">
				<geometry>
					<box>
						<size>0.05 0.035 0.05</size>
					</box>
				</geometry>
				<surface>
					<friction>
						<ode>
							<mu>0.6</mu>
							<mu2>0.6</mu2>
						</ode>
					</friction>
				</surface>
			</collision>
			<visual name="black">
				<geometry>
					<box>
						<size>0.05 0.035 0.05</size>
					</box>
				</geometry>
				<material>
					<diffuse>0 0 0 1</diffuse>
				</material>
			</visual>
			<visual name="orange">
				<pose>0.025 0.0 0.0 0.0 0.0 0.0</pose>
				<geometry>
					<box>
						<size>0.00045 0.03 0.045</size>
					</box>
				</geometry>
				<material>
					<diffuse>1.0 0.5 0.0 1.0</diffuse>
				</material>
			</visual>
			<visual name="blue">
				<pose>0.0 0.0175 0.0 0.0 0.0 0.0</pose>
				<geometry>
					<box>
						<size>0.045 0.0003 0.045</size>
					</box>
				</geometry>
				<material>
					<diffuse>0 0 1 1</diffuse>
				</material>
			</visual>
			<visual name="white">
				<pose>0.0 0.0 -0.025 0.0 0.0 0.0</pose>
				<geometry>
					<box>
						<size>0.045 0.03 0.00045</size>
					</box>
				</geometry>
				<material>
					<diffuse>1 1 1 1</diffuse>
				</material>
			</visual>
		</link>
		<joint name="ball_1_1_0" type="ball">
			<pose>-0.025050000000000003 -0.017550000000000003 0.025050000000000003 -0.0 -0.0 -0.0</pose>
			<parent>center</parent>
			<child>cubie_1_1_0</child>
			<axis>
				<dynamics>
					<damping>0.1</damping>
				</dynamics>
				<limit>
					<effort>0</effort>
				</limit>
			</axis>
		</joint>
		<link name="cubie_1_1_1">
			<pose>0.025050000000000003 0.017550000000000003 0.010050000000000002 0.0 0.0 0.0</pose>
			<inertial>
				<mass>0.013650000000000004</mass>
				<inertia>
					<ixx>1.8484375000000009e-06</ixx>
					<ixy>0.0</ixy>
					<ixz>0.0</ixz>
					<iyy>3.2987500000000017e-06</iyy>
					<iyz>0.0</iyz>
					<izz>4.237187500000002e-06</izz>
				</inertia>
			</inertial>
			<collision name="collision">
				<geometry>
					<box>
						<size>0.05 0.035 0.020000000000000004</size>
					</box>
				</geometry>
				<surface>
					<friction>
						<ode>
							<mu>0.6</mu>
							<mu2>0.6</mu2>
						</ode>
					</friction>
				</surface>
			</collision>
			<visual name="black">
				<geometry>
					<box>
						<size>0.05 0.035 0.020000000000000004</size>
					</box>
				</geometry>
				<material>
					<diffuse>0 0 0 1</diffuse>
				</material>
			</visual>
			<visual name="orange">
				<pose>0.025 0.0 0.0 0.0 0.0 0.0</pose>
				<geometry>
					<box>
						<size>0.00045 0.03 0.015</size>
					</box>
				</geometry>
				<material>
					<diffuse>1.0 0.5 0.0 1.0</diffuse>
				</material>
			</visual>
			<visual name="blue">
				<pose>0.0 0.0175 0.0 0.0 0.0 0.0</pose>
				<geometry>
					<box>
						<size>0.045 0.0003 0.015</size>
					</box>
				</geometry>
				<material>
					<diffuse>0 0 1 1</diffuse>
				</material>
			</visual>
			<visual name="yellow">
				<pose>0.0 0.0 0.010000000000000002 0.0 0.0 0.0</pose>
				<geometry>
					<box>
						<size>0.045 0.03 0.00015</size>
					</box>
				</geometry>
				<material>
					<diffuse>1 1 0 1</diffuse>
				</material>
			</visual>
		</link>
		<joint name="ball_1_1_1" type="ball">
			<pose>-0.025050000000000003 -0.017550000000000003 -0.010050000000000002 -0.0 -0.0 -0.0</pose>
			<parent>center</parent>
			<child>cubie_1_1_1</child>
			<axis>
				<dynamics>
					<damping>0.1</damping>
				</dynamics>
				<limit>
					<effort>0</effort>
				</limit>
			</axis>
		</joint>
	</model>
</sdf>
