<?xml version="1.0" ?>
<sdf version="1.7">
	<model name="mirror_cube_2x2">
		<link name="center"/>
		<link name="cubie_0_0_0">
			<pose>-0.010005 -0.015005 -0.020005000000000002 0.0 0.0 0.0</pose>
			<inertial>
				<mass>0.009359999999999999</mass>
				<inertia>
					<ixx>1.9499999999999995e-06</ixx>
					<ixy>0.0</ixy>
					<ixz>0.0</ixz>
					<iyy>1.5599999999999999e-06</iyy>
					<iyz>0.0</iyz>
					<izz>1.0139999999999997e-06</izz>
				</inertia>
			</inertial>
			<collision name="collision">
				<geometry>
					<box>
						<size>0.02 0.03 0.04</size>
					</box>
				</geometry>
				<surface>
					<friction>
						<ode>
							<mu>0.001</mu>
							<mu2>0.001</mu2>
						</ode>
					</friction>
				</surface>
			</collision>
			<visual name="black">
				<geometry>
					<box>
						<size>0.02 0.03 0.04</size>
					</box>
				</geometry>
				<material>
					<diffuse>0 0 0 1</diffuse>
				</material>
			</visual>
			<visual name="red">
				<pose>-0.01 0.0 0.0 0.0 0.0 0.0</pose>
				<geometry>
					<box>
						<size>0.00015 0.025 0.035</size>
					</box>
				</geometry>
				<material>
					<diffuse>1 0 0 1</diffuse>
				</material>
			</visual>
			<visual name="green">
				<pose>0.0 -0.015 0.0 0.0 0.0 0.0</pose>
				<geometry>
					<box>
						<size>0.015 0.00025 0.035</size>
					</box>
				</geometry>
				<material>
					<diffuse>0 1 0 1</diffuse>
				</material>
			</visual>
			<visual name="white">
				<pose>0.0 0.0 -0.02 0.0 0.0 0.0</pose>
				<geometry>
					<box>
						<size>0.015 0.025 0.00035</size>
					</box>
				</geometry>
				<material>
					<diffuse>1 1 1 1</diffuse>
				</material>
			</visual>
		</link>
		<joint name="ball_0_0_0" type="ball">
			<pose>0.010005 0.015005 0.020005000000000002 -0.0 -0.0 -0.0</pose>
			<parent>center</parent>
			<child>cubie_0_0_0</child>
			<axis>
				<dynamics>
					<damping>0.1</damping>
				</dynamics>
				<limit>
					<effort>0</effort>
				</limit>
			</axis>
		</joint>
		<link name="cubie_0_0_1">
			<pose>-0.010005 -0.015005 0.010004999999999998 0.0 0.0 0.0</pose>
			<inertial>
				<mass>0.004679999999999998</mass>
				<inertia>
					<ixx>5.069999999999999e-07</ixx>
					<ixy>0.0</ixy>
					<ixz>0.0</ixz>
					<iyy>3.119999999999999e-07</iyy>
					<iyz>0.0</iyz>
					<izz>5.069999999999999e-07</izz>
				</inertia>
			</inertial>
			<collision name="collision">
				<geometry>
					<box>
						<size>0.02 0.03 0.019999999999999997</size>
					</box>
				</geometry>
				<surface>
					<friction>
						<ode>
							<mu>0.001</mu>
							<mu2>0.001</mu2>
						</ode>
					</friction>
				</surface>
			</collision>
			<visual name="black">
				<geometry>
					<box>
						<size>0.02 0.03 0.019999999999999997</size>
					</box>
				</geometry>
				<material>
					<diffuse>0 0 0 1</diffuse>
				</material>
			</visual>
			<visual name="red">
				<pose>-0.01 0.0 0.0 0.0 0.0 0.0</pose>
				<geometry>
					<box>
						<size>0.00015 0.025 0.015</size>
					</box>
				</geometry>
				<material>
					<diffuse>1 0 0 1</diffuse>
				</material>
			</visual>
			<visual name="green">
				<pose>0.0 -0.015 0.0 0.0 0.0 0.0</pose>
				<geometry>
					<box>
						<size>0.015 0.00025 0.015</size>
					</box>
				</geometry>
				<material>
					<diffuse>0 1 0 1</diffuse>
				</material>
			</visual>
			<visual name="yellow">
				<pose>0.0 0.0 0.009999999999999998 0.0 0.0 0.0</pose>
				<geometry>
					<box>
						<size>0.015 0.025 0.00015</size>
					</box>
				</geometry>
				<material>
					<diffuse>1 1 0 1</diffuse>
				</material>
			</visual>
		</link>
		<joint name="ball_0_0_1" type="ball">
			<pose>0.010005 0.015005 -0.010004999999999998 -0.0 -0.0 -0.0</pose>
			<parent>center</parent>
			<child>cubie_0_0_1</child>
			<axis>
				<dynamics>
					<damping>0.1</damping>
				</dynamics>
				<limit>
					<effort>0</effort>
				</limit>
			</axis>
		</joint>
		<link name="cubie_0_1_0">
			<pose>-0.010005 0.015005 -0.020005000000000002 0.0 0.0 0.0</pose>
			<inertial>
				<mass>0.009359999999999999</mass>
				<inertia>
					<ixx>1.9499999999999995e-06</ixx>
					<ixy>0.0</ixy>
					<ixz>0.0</ixz>
					<iyy>1.5599999999999999e-06</iyy>
					<iyz>0.0</iyz>
					<izz>1.0139999999999997e-06</izz>
				</inertia>
			</inertial>
			<collision name="collision">
				<geometry>
					<box>
						<size>0.02 0.03 0.04</size>
					</box>
				</geometry>
				<surface>
					<friction>
						<ode>
							<mu>0.001</mu>
							<mu2>0.001</mu2>
						</ode>
					</friction>
				</surface>
			</collision>
			<visual name="black">
				<geometry>
					<box>
						<size>0.02 0.03 0.04</size>
					</box>
				</geometry>
				<material>
					<diffuse>0 0 0 1</diffuse>
				</material>
			</visual>
			<visual name="red">
				<pose>-0.01 0.0 0.0 0.0 0.0 0.0</pose>
				<geometry>
					<box>
						<size>0.00015 0.025 0.035</size>
					</box>
				</geometry>
				<material>
					<diffuse>1 0 0 1</diffuse>
				</material>
			</visual>
			<visual name="blue">
				<pose>0.0 0.015 0.0 0.0 0.0 0.0</pose>
				<geometry>
					<box>
						<size>0.015 0.00025 0.035</size>
					</box>
				</geometry>
				<material>
					<diffuse>0 0 1 1</diffuse>
				</material>
			</visual>
			<visual name="white">
				<pose>0.0 0.0 -0.02 0.0 0.0 0.0</pose>
				<geometry>
					<box>
						<size>0.015 0.025 0.00035</size>
					</box>
				</geometry>
				<material>
					<diffuse>1 1 1 1</diffuse>
				</material>
			</visual>
		</link>
		<joint name="ball_0_1_0" type="ball">
			<pose>0.010005 -0.015005 0.020005000000000002 -0.0 -0.0 -0.0</pose>
			<parent>center</parent>
			<child>cubie_0_1_0</child>
			<axis>
				<dynamics>
					<damping>0.1</damping>
				</dynamics>
				<limit>
					<effort>0</effort>
				</limit>
			</axis>
		</joint>
		<link name="cubie_0_1_1">
			<pose>-0.010005 0.015005 0.010004999999999998 0.0 0.0 0.0</pose>
			<inertial>
				<mass>0.004679999999999998</mass>
				<inertia>
					<ixx>5.069999999999999e-07</ixx>
					<ixy>0.0</ixy>
					<ixz>0.0</ixz>
					<iyy>3.119999999999999e-07</iyy>
					<iyz>0.0</iyz>
					<izz>5.069999999999999e-07</izz>
				</inertia>
			</inertial>
			<collision name="collision">
				<geometry>
					<box>
						<size>0.02 0.03 0.019999999999999997</size>
					</box>
				</geometry>
				<surface>
					<friction>
						<ode>
							<mu>0.001</mu>
							<mu2>0.001</mu2>
						</ode>
					</friction>
				</surface>
			</collision>
			<visual name="black">
				<geometry>
					<box>
						<size>0.02 0.03 0.019999999999999997</size>
					</box>
				</geometry>
				<material>
					<diffuse>0 0 0 1</diffuse>
				</material>
			</visual>
			<visual name="red">
				<pose>-0.01 0.0 0.0 0.0 0.0 0.0</pose>
				<geometry>
					<box>
						<size>0.00015 0.025 0.015</size>
					</box>
				</geometry>
				<material>
					<diffuse>1 0 0 1</diffuse>
				</material>
			</visual>
			<visual name="blue">
				<pose>0.0 0.015 0.0 0.0 0.0 0.0</pose>
				<geometry>
					<box>
						<size>0.015 0.00025 0.015</size>
					</box>
				</geometry>
				<material>
					<diffuse>0 0 1 1</diffuse>
				</material>
			</visual>
			<visual name="yellow">
				<pose>0.0 0.0 0.009999999999999998 0.0 0.0 0.0</pose>
				<geometry>
					<box>
						<size>0.015 0.025 0.00015</size>
					</box>
				</geometry>
				<material>
					<diffuse>1 1 0 1</diffuse>
				</material>
			</visual>
		</link>
		<joint name="ball_0_1_1" type="ball">
			<pose>0.010005 -0.015005 -0.010004999999999998 -0.0 -0.0 -0.0</pose>
			<parent>center</parent>
			<child>cubie_0_1_1</child>
			<axis>
				<dynamics>
					<damping>0.1</damping>
				</dynamics>
				<limit>
					<effort>0</effort>
				</limit>
			</axis>
		</joint>
		<link name="cubie_1_0_0">
			<pose>0.020005 -0.015005 -0.020005000000000002 0.0 0.0 0.0</pose>
			<inertial>
				<mass>0.018719999999999994</mass>
				<inertia>
					<ixx>3.899999999999999e-06</ixx>
					<ixy>0.0</ixy>
					<ixz>0.0</ixz>
					<iyy>4.991999999999998e-06</iyy>
					<iyz>0.0</iyz>
					<izz>3.899999999999998e-06</izz>
				</inertia>
			</inertial>
			<collision name="collision">
				<geometry>
					<box>
						<size>0.039999999999999994 0.03 0.04</size>
					</box>
				</geometry>
				<surface>
					<friction>
						<ode>
							<mu>0.001</mu>
							<mu2>0.001</mu2>
						</ode>
					</friction>
				</surface>
			</collision>
			<visual name="black">
				<geometry>
					<box>
						<size>0.039999999999999994 0.03 0.04</size>
					</box>
				</geometry>
				<material>
					<diffuse>0 0 0 1</diffuse>
				</material>
			</visual>
			<visual name="orange">
				<pose>0.019999999999999997 0.0 0.0 0.0 0.0 0.0</pose>
				<geometry>
					<box>
						<size>0.00035 0.025 0.035</size>
					</box>
				</geometry>
				<material>
					<diffuse>1.0 0.5 0.0 1.0</diffuse>
				</material>
			</visual>
			<visual name="green">
				<pose>0.0 -0.015 0.0 0.0 0.0 0.0</pose>
				<geometry>
					<box>
						<size>0.035 0.00025 0.035</size>
					</box>
				</geometry>
				<material>
					<diffuse>0 1 0 1</diffuse>
				</material>
			</visual>
			<visual name="white">
				<pose>0.0 0.0 -0.02 0.0 0.0 0.0</pose>
				<geometry>
					<box>
						<size>0.035 0.025 0.00035</size>
					</box>
				</geometry>
				<material>
					<diffuse>1 1 1 1</diffuse>
				</material>
			</visual>
		</link>
		<joint name="ball_1_0_0" type="ball">
			<pose>-0.020005 0.015005 0.020005000000000002 -0.0 -0.0 -0.0</pose>
			<parent>center</parent>
			<child>cubie_1_0_0</child>
			<axis>
				<dynamics>
					<damping>0.1</damping>
				</dynamics>
				<limit>
					<effort>0</effort>
				</limit>
			</axis>
		</joint>
		<link name="cubie_1_0_1">
			<pose>0.020005 -0.015005 0.010004999999999998 0.0 0.0 0.0</pose>
			<inertial>
				<mass>0.009359999999999997</mass>
				<inertia>
					<ixx>1.0139999999999997e-06</ixx>
					<ixy>0.0</ixy>
					<ixz>0.0</ixz>
					<iyy>1.5599999999999988e-06</iyy>
					<iyz>0.0</iyz>
					<izz>1.949999999999999e-06</izz>
				</inertia>
			</inertial>
			<collision name="collision">
				<geometry>
					<box>
						<size>0.039999999999999994 0.03 0.019999999999999997</size>
					</box>
				</geometry>
				<surface>
					<friction>
						<ode>
							<mu>0.001</mu>
							<mu2>0.001</mu2>
						</ode>
					</friction>
				</surface>
			</collision>
			<visual name="black">
				<geometry>
					<box>
						<size>0.039999999999999994 0.03 0.019999999999999997</size>
					</box>
				</geometry>
				<material>
					<diffuse>0 0 0 1</diffuse>
				</material>
			</visual>
			<visual name="orange">
				<pose>0.019999999999999997 0.0 0.0 0.0 0.0 0.0</pose>
				<geometry>
					<box>
						<size>0.00035 0.025 0.015</size>
					</box>
				</geometry>
				<material>
					<diffuse>1.0 0.5 0.0 1.0</diffuse>
				</material>
			</visual>
			<visual name="green">
				<pose>0.0 -0.015 0.0 0.0 0.0 0.0</pose>
				<geometry>
					<box>
						<size>0.035 0.00025 0.015</size>
					</box>
				</geometry>
				<material>
					<diffuse>0 1 0 1</diffuse>
				</material>
			</visual>
			<visual name="yellow">
				<pose>0.0 0.0 0.009999999999999998 0.0 0.0 0.0</pose>
				<geometry>
					<box>
						<size>0.035 0.025 0.00015</size>
					</box>
				</geometry>
				<material>
					<diffuse>1 1 0 1</diffuse>
				</material>
			</visual>
		</link>
		<joint name="ball_1_0_1" type="ball">
			<pose>-0.020005 0.015005 -0.010004999999999998 -0.0 -0.0 -0.0</pose>
			<parent>center</parent>
			<child>cubie_1_0_1</child>
			<axis>
				<dynamics>
					<damping>0.1</damping>
				</dynamics>
				<limit>
					<effort>0</effort>
				</limit>
			</axis>
		</joint>
		<link name="cubie_1_1_0">
			<pose>0.020005 0.015005 -0.020005000000000002 0.0 0.0 0.0</pose>
			<inertial>
				<mass>0.018719999999999994</mass>
				<inertia>
					<ixx>3.899999999999999e-06</ixx>
					<ixy>0.0</ixy>
					<ixz>0.0</ixz>
					<iyy>4.991999999999998e-06</iyy>
					<iyz>0.0</iyz>
					<izz>3.899999999999998e-06</izz>
				</inertia>
			</inertial>
			<collision name="collision">
				<geometry>
					<box>
						<size>0.039999999999999994 0.03 0.04</size>
					</box>
				</geometry>
				<surface>
					<friction>
						<ode>
							<mu>0.001</mu>
							<mu2>0.001</mu2>
						</ode>
					</friction>
				</surface>
			</collision>
			<visual name="black">
				<geometry>
					<box>
						<size>0.039999999999999994 0.03 0.04</size>
					</box>
				</geometry>
				<material>
					<diffuse>0 0 0 1</diffuse>
				</material>
			</visual>
			<visual name="orange">
				<pose>0.019999999999999997 0.0 0.0 0.0 0.0 0.0</pose>
				<geometry>
					<box>
						<size>0.00035 0.025 0.035</size>
					</box>
				</geometry>
				<material>
					<diffuse>1.0 0.5 0.0 1.0</diffuse>
				</material>
			</visual>
			<visual name="blue">
				<pose>0.0 0.015 0.0 0.0 0.0 0.0</pose>
				<geometry>
					<box>
						<size>0.035 0.00025 0.035</size>
					</box>
				</geometry>
				<material>
					<diffuse>0 0 1 1</diffuse>
				</material>
			</visual>
			<visual name="white">
				<pose>0.0 0.0 -0.02 0.0 0.0 0.0</pose>
				<geometry>
					<box>
						<size>0.035 0.025 0.00035</size>
					</box>
				</geometry>
				<material>
					<diffuse>1 1 1 1</diffuse>
				</material>
			</visual>
		</link>
		<joint name="ball_1_1_0" type="ball">
			<pose>-0.020005 -0.015005 0.020005000000000002 -0.0 -0.0 -0.0</pose>
			<parent>center</parent>
			<child>cubie_1_1_0</child>
			<axis>
				<dynamics>
					<damping>0.1</damping>
				</dynamics>
				<limit>
					<effort>0</effort>
				</limit>
			</axis>
		</joint>
		<link name="cubie_1_1_1">
			<pose>0.020005 0.015005 0.010004999999999998 0.0 0.0 0.0</pose>
			<inertial>
				<mass>0.009359999999999997</mass>
				<inertia>
					<ixx>1.0139999999999997e-06</ixx>
					<ixy>0.0</ixy>
					<ixz>0.0</ixz>
					<iyy>1.5599999999999988e-06</iyy>
					<iyz>0.0</iyz>
					<izz>1.949999999999999e-06</izz>
				</inertia>
			</inertial>
			<collision name="collision">
				<geometry>
					<box>
						<size>0.039999999999999994 0.03 0.019999999999999997</size>
					</box>
				</geometry>
				<surface>
					<friction>
						<ode>
							<mu>0.001</mu>
							<mu2>0.001</mu2>
						</ode>
					</friction>
				</surface>
			</collision>
			<visual name="black">
				<geometry>
					<box>
						<size>0.039999999999999994 0.03 0.019999999999999997</size>
					</box>
				</geometry>
				<material>
					<diffuse>0 0 0 1</diffuse>
				</material>
			</visual>
			<visual name="orange">
				<pose>0.019999999999999997 0.0 0.0 0.0 0.0 0.0</pose>
				<geometry>
					<box>
						<size>0.00035 0.025 0.015</size>
					</box>
				</geometry>
				<material>
					<diffuse>1.0 0.5 0.0 1.0</diffuse>
				</material>
			</visual>
			<visual name="blue">
				<pose>0.0 0.015 0.0 0.0 0.0 0.0</pose>
				<geometry>
					<box>
						<size>0.035 0.00025 0.015</size>
					</box>
				</geometry>
				<material>
					<diffuse>0 0 1 1</diffuse>
				</material>
			</visual>
			<visual name="yellow">
				<pose>0.0 0.0 0.009999999999999998 0.0 0.0 0.0</pose>
				<geometry>
					<box>
						<size>0.035 0.025 0.00015</size>
					</box>
				</geometry>
				<material>
					<diffuse>1 1 0 1</diffuse>
				</material>
			</visual>
		</link>
		<joint name="ball_1_1_1" type="ball">
			<pose>-0.020005 -0.015005 -0.010004999999999998 -0.0 -0.0 -0.0</pose>
			<parent>center</parent>
			<child>cubie_1_1_1</child>
			<axis>
				<dynamics>
					<damping>0.1</damping>
				</dynamics>
				<limit>
					<effort>0</effort>
				</limit>
			</axis>
		</joint>
	</model>
</sdf>
