<?xml version="1.0" ?>
<sdf version="1.7">
	<model name="mirror_cube_2x2">
		<link name="center_mirror_1"/>
		<link name="cubie_0_0_0">
			<pose>-0.0202 -0.0152 -0.0252 0.0 0.0 0.0</pose>
			<inertial>
				<mass>0.023399999999999997</mass>
				<inertia>
					<ixx>6.629999999999999e-06</ixx>
					<ixy>0.0</ixy>
					<ixz>0.0</ixz>
					<iyy>7.994999999999999e-06</iyy>
					<iyz>0.0</iyz>
					<izz>4.874999999999999e-06</izz>
				</inertia>
			</inertial>
			<collision name="collision">
				<geometry>
					<box>
						<size>0.04 0.03 0.05</size>
					</box>
				</geometry>
				<surface>
					<friction>
						<ode>
							<mu>0</mu>
							<mu2>0</mu2>
						</ode>
					</friction>
				</surface>
			</collision>
			<visual name="black">
				<geometry>
					<box>
						<size>0.04 0.03 0.05</size>
					</box>
				</geometry>
				<material>
					<diffuse>0 0 0 1</diffuse>
				</material>
			</visual>
			<visual name="red">
				<pose>-0.02 0.0 0.0 0.0 0.0 0.0</pose>
				<geometry>
					<box>
						<size>0.00035 0.025 0.045</size>
					</box>
				</geometry>
				<material>
					<diffuse>1 0 0 1</diffuse>
				</material>
			</visual>
			<visual name="green">
				<pose>0.0 -0.015 0.0 0.0 0.0 0.0</pose>
				<geometry>
					<box>
						<size>0.035 0.00025 0.045</size>
					</box>
				</geometry>
				<material>
					<diffuse>0 1 0 1</diffuse>
				</material>
			</visual>
			<visual name="white">
				<pose>0.0 0.0 -0.025 0.0 0.0 0.0</pose>
				<geometry>
					<box>
						<size>0.035 0.025 0.00045</size>
					</box>
				</geometry>
				<material>
					<diffuse>1 1 1 1</diffuse>
				</material>
			</visual>
		</link>
		<joint name="ball_0_0_0" type="ball">
			<pose>0.0202 0.0152 0.0252 -0.0 -0.0 -0.0</pose>
			<parent>center_mirror_1</parent>
			<child>cubie_0_0_0</child>
			<axis>
				<dynamics>
					<damping>0.1</damping>
				</dynamics>
				<limit>
					<effort>0</effort>
				</limit>
			</axis>
		</joint>
		<link name="cubie_0_0_1">
			<pose>-0.0202 -0.0152 0.005199999999999997 0.0 0.0 0.0</pose>
			<inertial>
				<mass>0.0046799999999999975</mass>
				<inertia>
					<ixx>3.899999999999997e-07</ixx>
					<ixy>0.0</ixy>
					<ixz>0.0</ixz>
					<iyy>6.629999999999996e-07</iyy>
					<iyz>0.0</iyz>
					<izz>9.749999999999996e-07</izz>
				</inertia>
			</inertial>
			<collision name="collision">
				<geometry>
					<box>
						<size>0.04 0.03 0.009999999999999995</size>
					</box>
				</geometry>
				<surface>
					<friction>
						<ode>
							<mu>0</mu>
							<mu2>0</mu2>
						</ode>
					</friction>
				</surface>
			</collision>
			<visual name="black">
				<geometry>
					<box>
						<size>0.04 0.03 0.009999999999999995</size>
					</box>
				</geometry>
				<material>
					<diffuse>0 0 0 1</diffuse>
				</material>
			</visual>
			<visual name="red">
				<pose>-0.02 0.0 0.0 0.0 0.0 0.0</pose>
				<geometry>
					<box>
						<size>0.00035 0.025 0.005</size>
					</box>
				</geometry>
				<material>
					<diffuse>1 0 0 1</diffuse>
				</material>
			</visual>
			<visual name="green">
				<pose>0.0 -0.015 0.0 0.0 0.0 0.0</pose>
				<geometry>
					<box>
						<size>0.035 0.00025 0.005</size>
					</box>
				</geometry>
				<material>
					<diffuse>0 1 0 1</diffuse>
				</material>
			</visual>
			<visual name="yellow">
				<pose>0.0 0.0 0.0049999999999999975 0.0 0.0 0.0</pose>
				<geometry>
					<box>
						<size>0.035 0.025 5e-05</size>
					</box>
				</geometry>
				<material>
					<diffuse>1 1 0 1</diffuse>
				</material>
			</visual>
		</link>
		<joint name="ball_0_0_1" type="ball">
			<pose>0.0202 0.0152 -0.005199999999999997 -0.0 -0.0 -0.0</pose>
			<parent>center_mirror_1</parent>
			<child>cubie_0_0_1</child>
			<axis>
				<dynamics>
					<damping>0.1</damping>
				</dynamics>
				<limit>
					<effort>0</effort>
				</limit>
			</axis>
		</joint>
		<link name="cubie_0_1_0">
			<pose>-0.0202 0.0152 -0.0252 0.0 0.0 0.0</pose>
			<inertial>
				<mass>0.023399999999999997</mass>
				<inertia>
					<ixx>6.629999999999999e-06</ixx>
					<ixy>0.0</ixy>
					<ixz>0.0</ixz>
					<iyy>7.994999999999999e-06</iyy>
					<iyz>0.0</iyz>
					<izz>4.874999999999999e-06</izz>
				</inertia>
			</inertial>
			<collision name="collision">
				<geometry>
					<box>
						<size>0.04 0.03 0.05</size>
					</box>
				</geometry>
				<surface>
					<friction>
						<ode>
							<mu>0</mu>
							<mu2>0</mu2>
						</ode>
					</friction>
				</surface>
			</collision>
			<visual name="black">
				<geometry>
					<box>
						<size>0.04 0.03 0.05</size>
					</box>
				</geometry>
				<material>
					<diffuse>0 0 0 1</diffuse>
				</material>
			</visual>
			<visual name="red">
				<pose>-0.02 0.0 0.0 0.0 0.0 0.0</pose>
				<geometry>
					<box>
						<size>0.00035 0.025 0.045</size>
					</box>
				</geometry>
				<material>
					<diffuse>1 0 0 1</diffuse>
				</material>
			</visual>
			<visual name="blue">
				<pose>0.0 0.015 0.0 0.0 0.0 0.0</pose>
				<geometry>
					<box>
						<size>0.035 0.00025 0.045</size>
					</box>
				</geometry>
				<material>
					<diffuse>0 0 1 1</diffuse>
				</material>
			</visual>
			<visual name="white">
				<pose>0.0 0.0 -0.025 0.0 0.0 0.0</pose>
				<geometry>
					<box>
						<size>0.035 0.025 0.00045</size>
					</box>
				</geometry>
				<material>
					<diffuse>1 1 1 1</diffuse>
				</material>
			</visual>
		</link>
		<joint name="ball_0_1_0" type="ball">
			<pose>0.0202 -0.0152 0.0252 -0.0 -0.0 -0.0</pose>
			<parent>center_mirror_1</parent>
			<child>cubie_0_1_0</child>
			<axis>
				<dynamics>
					<damping>0.1</damping>
				</dynamics>
				<limit>
					<effort>0</effort>
				</limit>
			</axis>
		</joint>
		<link name="cubie_0_1_1">
			<pose>-0.0202 0.0152 0.005199999999999997 0.0 0.0 0.0</pose>
			<inertial>
				<mass>0.0046799999999999975</mass>
				<inertia>
					<ixx>3.899999999999997e-07</ixx>
					<ixy>0.0</ixy>
					<ixz>0.0</ixz>
					<iyy>6.629999999999996e-07</iyy>
					<iyz>0.0</iyz>
					<izz>9.749999999999996e-07</izz>
				</inertia>
			</inertial>
			<collision name="collision">
				<geometry>
					<box>
						<size>0.04 0.03 0.009999999999999995</size>
					</box>
				</geometry>
				<surface>
					<friction>
						<ode>
							<mu>0</mu>
							<mu2>0</mu2>
						</ode>
					</friction>
				</surface>
			</collision>
			<visual name="black">
				<geometry>
					<box>
						<size>0.04 0.03 0.009999999999999995</size>
					</box>
				</geometry>
				<material>
					<diffuse>0 0 0 1</diffuse>
				</material>
			</visual>
			<visual name="red">
				<pose>-0.02 0.0 0.0 0.0 0.0 0.0</pose>
				<geometry>
					<box>
						<size>0.00035 0.025 0.005</size>
					</box>
				</geometry>
				<material>
					<diffuse>1 0 0 1</diffuse>
				</material>
			</visual>
			<visual name="blue">
				<pose>0.0 0.015 0.0 0.0 0.0 0.0</pose>
				<geometry>
					<box>
						<size>0.035 0.00025 0.005</size>
					</box>
				</geometry>
				<material>
					<diffuse>0 0 1 1</diffuse>
				</material>
			</visual>
			<visual name="yellow">
				<pose>0.0 0.0 0.0049999999999999975 0.0 0.0 0.0</pose>
				<geometry>
					<box>
						<size>0.035 0.025 5e-05</size>
					</box>
				</geometry>
				<material>
					<diffuse>1 1 0 1</diffuse>
				</material>
			</visual>
		</link>
		<joint name="ball_0_1_1" type="ball">
			<pose>0.0202 -0.0152 -0.005199999999999997 -0.0 -0.0 -0.0</pose>
			<parent>center_mirror_1</parent>
			<child>cubie_0_1_1</child>
			<axis>
				<dynamics>
					<damping>0.1</damping>
				</dynamics>
				<limit>
					<effort>0</effort>
				</limit>
			</axis>
		</joint>
		<link name="cubie_1_0_0">
			<pose>0.010199999999999999 -0.0152 -0.0252 0.0 0.0 0.0</pose>
			<inertial>
				<mass>0.011699999999999997</mass>
				<inertia>
					<ixx>3.314999999999999e-06</ixx>
					<ixy>0.0</ixy>
					<ixz>0.0</ixz>
					<iyy>2.8274999999999996e-06</iyy>
					<iyz>0.0</iyz>
					<izz>1.2674999999999995e-06</izz>
				</inertia>
			</inertial>
			<collision name="collision">
				<geometry>
					<box>
						<size>0.019999999999999997 0.03 0.05</size>
					</box>
				</geometry>
				<surface>
					<friction>
						<ode>
							<mu>0</mu>
							<mu2>0</mu2>
						</ode>
					</friction>
				</surface>
			</collision>
			<visual name="black">
				<geometry>
					<box>
						<size>0.019999999999999997 0.03 0.05</size>
					</box>
				</geometry>
				<material>
					<diffuse>0 0 0 1</diffuse>
				</material>
			</visual>
			<visual name="orange">
				<pose>0.009999999999999998 0.0 0.0 0.0 0.0 0.0</pose>
				<geometry>
					<box>
						<size>0.00015 0.025 0.045</size>
					</box>
				</geometry>
				<material>
					<diffuse>1.0 0.5 0.0 1.0</diffuse>
				</material>
			</visual>
			<visual name="green">
				<pose>0.0 -0.015 0.0 0.0 0.0 0.0</pose>
				<geometry>
					<box>
						<size>0.015 0.00025 0.045</size>
					</box>
				</geometry>
				<material>
					<diffuse>0 1 0 1</diffuse>
				</material>
			</visual>
			<visual name="white">
				<pose>0.0 0.0 -0.025 0.0 0.0 0.0</pose>
				<geometry>
					<box>
						<size>0.015 0.025 0.00045</size>
					</box>
				</geometry>
				<material>
					<diffuse>1 1 1 1</diffuse>
				</material>
			</visual>
		</link>
		<joint name="ball_1_0_0" type="ball">
			<pose>-0.010199999999999999 0.0152 0.0252 -0.0 -0.0 -0.0</pose>
			<parent>center_mirror_1</parent>
			<child>cubie_1_0_0</child>
			<axis>
				<dynamics>
					<damping>0.1</damping>
				</dynamics>
				<limit>
					<effort>0</effort>
				</limit>
			</axis>
		</joint>
		<link name="cubie_1_0_1">
			<pose>0.010199999999999999 -0.0152 0.005199999999999997 0.0 0.0 0.0</pose>
			<inertial>
				<mass>0.002339999999999998</mass>
				<inertia>
					<ixx>1.949999999999998e-07</ixx>
					<ixy>0.0</ixy>
					<ixz>0.0</ixz>
					<iyy>9.749999999999987e-08</iyy>
					<iyz>0.0</iyz>
					<izz>2.534999999999998e-07</izz>
				</inertia>
			</inertial>
			<collision name="collision">
				<geometry>
					<box>
						<size>0.019999999999999997 0.03 0.009999999999999995</size>
					</box>
				</geometry>
				<surface>
					<friction>
						<ode>
							<mu>0</mu>
							<mu2>0</mu2>
						</ode>
					</friction>
				</surface>
			</collision>
			<visual name="black">
				<geometry>
					<box>
						<size>0.019999999999999997 0.03 0.009999999999999995</size>
					</box>
				</geometry>
				<material>
					<diffuse>0 0 0 1</diffuse>
				</material>
			</visual>
			<visual name="orange">
				<pose>0.009999999999999998 0.0 0.0 0.0 0.0 0.0</pose>
				<geometry>
					<box>
						<size>0.00015 0.025 0.005</size>
					</box>
				</geometry>
				<material>
					<diffuse>1.0 0.5 0.0 1.0</diffuse>
				</material>
			</visual>
			<visual name="green">
				<pose>0.0 -0.015 0.0 0.0 0.0 0.0</pose>
				<geometry>
					<box>
						<size>0.015 0.00025 0.005</size>
					</box>
				</geometry>
				<material>
					<diffuse>0 1 0 1</diffuse>
				</material>
			</visual>
			<visual name="yellow">
				<pose>0.0 0.0 0.0049999999999999975 0.0 0.0 0.0</pose>
				<geometry>
					<box>
						<size>0.015 0.025 5e-05</size>
					</box>
				</geometry>
				<material>
					<diffuse>1 1 0 1</diffuse>
				</material>
			</visual>
		</link>
		<joint name="ball_1_0_1" type="ball">
			<pose>-0.010199999999999999 0.0152 -0.005199999999999997 -0.0 -0.0 -0.0</pose>
			<parent>center_mirror_1</parent>
			<child>cubie_1_0_1</child>
			<axis>
				<dynamics>
					<damping>0.1</damping>
				</dynamics>
				<limit>
					<effort>0</effort>
				</limit>
			</axis>
		</joint>
		<link name="cubie_1_1_0">
			<pose>0.010199999999999999 0.0152 -0.0252 0.0 0.0 0.0</pose>
			<inertial>
				<mass>0.011699999999999997</mass>
				<inertia>
					<ixx>3.314999999999999e-06</ixx>
					<ixy>0.0</ixy>
					<ixz>0.0</ixz>
					<iyy>2.8274999999999996e-06</iyy>
					<iyz>0.0</iyz>
					<izz>1.2674999999999995e-06</izz>
				</inertia>
			</inertial>
			<collision name="collision">
				<geometry>
					<box>
						<size>0.019999999999999997 0.03 0.05</size>
					</box>
				</geometry>
				<surface>
					<friction>
						<ode>
							<mu>0</mu>
							<mu2>0</mu2>
						</ode>
					</friction>
				</surface>
			</collision>
			<visual name="black">
				<geometry>
					<box>
						<size>0.019999999999999997 0.03 0.05</size>
					</box>
				</geometry>
				<material>
					<diffuse>0 0 0 1</diffuse>
				</material>
			</visual>
			<visual name="orange">
				<pose>0.009999999999999998 0.0 0.0 0.0 0.0 0.0</pose>
				<geometry>
					<box>
						<size>0.00015 0.025 0.045</size>
					</box>
				</geometry>
				<material>
					<diffuse>1.0 0.5 0.0 1.0</diffuse>
				</material>
			</visual>
			<visual name="blue">
				<pose>0.0 0.015 0.0 0.0 0.0 0.0</pose>
				<geometry>
					<box>
						<size>0.015 0.00025 0.045</size>
					</box>
				</geometry>
				<material>
					<diffuse>0 0 1 1</diffuse>
				</material>
			</visual>
			<visual name="white">
				<pose>0.0 0.0 -0.025 0.0 0.0 0.0</pose>
				<geometry>
					<box>
						<size>0.015 0.025 0.00045</size>
					</box>
				</geometry>
				<material>
					<diffuse>1 1 1 1</diffuse>
				</material>
			</visual>
		</link>
		<joint name="ball_1_1_0" type="ball">
			<pose>-0.010199999999999999 -0.0152 0.0252 -0.0 -0.0 -0.0</pose>
			<parent>center_mirror_1</parent>
			<child>cubie_1_1_0</child>
			<axis>
				<dynamics>
					<damping>0.1</damping>
				</dynamics>
				<limit>
					<effort>0</effort>
				</limit>
			</axis>
		</joint>
		<link name="cubie_1_1_1">
			<pose>0.010199999999999999 0.0152 0.005199999999999997 0.0 0.0 0.0</pose>
			<inertial>
				<mass>0.002339999999999998</mass>
				<inertia>
					<ixx>1.949999999999998e-07</ixx>
					<ixy>0.0</ixy>
					<ixz>0.0</ixz>
					<iyy>9.749999999999987e-08</iyy>
					<iyz>0.0</iyz>
					<izz>2.534999999999998e-07</izz>
				</inertia>
			</inertial>
			<collision name="collision">
				<geometry>
					<box>
						<size>0.019999999999999997 0.03 0.009999999999999995</size>
					</box>
				</geometry>
				<surface>
					<friction>
						<ode>
							<mu>0</mu>
							<mu2>0</mu2>
						</ode>
					</friction>
				</surface>
			</collision>
			<visual name="black">
				<geometry>
					<box>
						<size>0.019999999999999997 0.03 0.009999999999999995</size>
					</box>
				</geometry>
				<material>
					<diffuse>0 0 0 1</diffuse>
				</material>
			</visual>
			<visual name="orange">
				<pose>0.009999999999999998 0.0 0.0 0.0 0.0 0.0</pose>
				<geometry>
					<box>
						<size>0.00015 0.025 0.005</size>
					</box>
				</geometry>
				<material>
					<diffuse>1.0 0.5 0.0 1.0</diffuse>
				</material>
			</visual>
			<visual name="blue">
				<pose>0.0 0.015 0.0 0.0 0.0 0.0</pose>
				<geometry>
					<box>
						<size>0.015 0.00025 0.005</size>
					</box>
				</geometry>
				<material>
					<diffuse>0 0 1 1</diffuse>
				</material>
			</visual>
			<visual name="yellow">
				<pose>0.0 0.0 0.0049999999999999975 0.0 0.0 0.0</pose>
				<geometry>
					<box>
						<size>0.015 0.025 5e-05</size>
					</box>
				</geometry>
				<material>
					<diffuse>1 1 0 1</diffuse>
				</material>
			</visual>
		</link>
		<joint name="ball_1_1_1" type="ball">
			<pose>-0.010199999999999999 -0.0152 -0.005199999999999997 -0.0 -0.0 -0.0</pose>
			<parent>center_mirror_1</parent>
			<child>cubie_1_1_1</child>
			<axis>
				<dynamics>
					<damping>0.1</damping>
				</dynamics>
				<limit>
					<effort>0</effort>
				</limit>
			</axis>
		</joint>
	</model>
</sdf>
