<?xml version="1.0" ?>
<sdf version="1.7">
	<model name="mirror_cube_2x2">
		<link name="center"/>
		<link name="cubie_0_0_0">
			<pose>-0.14755 -0.15005 -0.15255 0.0 0.0 0.0</pose>
			<inertial>
				<mass>10.527075</mass>
				<inertia>
					<ixx>0.16055982515624997</ixx>
					<ixy>0.0</ixy>
					<ixz>0.0</ixz>
					<iyy>0.15794998781249997</iyy>
					<iyz>0.0</iyz>
					<izz>0.15529628765624998</izz>
				</inertia>
			</inertial>
			<collision name="collision">
				<geometry>
					<box>
						<size>0.295 0.3 0.305</size>
					</box>
				</geometry>
				<surface>
					<friction>
						<ode>
							<mu>0.6</mu>
							<mu2>0.6</mu2>
						</ode>
					</friction>
				</surface>
			</collision>
			<visual name="black">
				<geometry>
					<box>
						<size>0.295 0.3 0.305</size>
					</box>
				</geometry>
				<material>
					<diffuse>0 0 0 1</diffuse>
				</material>
			</visual>
			<visual name="red">
				<pose>-0.1475 0.0 0.0 0.0 0.0 0.0</pose>
				<geometry>
					<box>
						<size>0.0029 0.295 0.3</size>
					</box>
				</geometry>
				<material>
					<diffuse>1 0 0 1</diffuse>
				</material>
			</visual>
			<visual name="green">
				<pose>0.0 -0.15 0.0 0.0 0.0 0.0</pose>
				<geometry>
					<box>
						<size>0.29 0.00295 0.3</size>
					</box>
				</geometry>
				<material>
					<diffuse>0 1 0 1</diffuse>
				</material>
			</visual>
			<visual name="white">
				<pose>0.0 0.0 -0.1525 0.0 0.0 0.0</pose>
				<geometry>
					<box>
						<size>0.29 0.295 0.003</size>
					</box>
				</geometry>
				<material>
					<diffuse>1 1 1 1</diffuse>
				</material>
			</visual>
		</link>
		<joint name="ball_0_0_0" type="ball">
			<pose>0.14755 0.15005 0.15255 -0.0 -0.0 -0.0</pose>
			<parent>center</parent>
			<child>cubie_0_0_0</child>
			<axis>
				<dynamics>
					<damping>0.1</damping>
				</dynamics>
				<limit>
					<effort>0</effort>
				</limit>
			</axis>
		</joint>
		<link name="cubie_0_0_1">
			<pose>-0.14755 -0.15005 0.14755 0.0 0.0 0.0</pose>
			<inertial>
				<mass>10.181925</mass>
				<inertia>
					<ixx>0.15020460609374997</ixx>
					<ixy>0.0</ixy>
					<ixz>0.0</ixz>
					<iyy>0.14768033718749998</iyy>
					<iyz>0.0</iyz>
					<izz>0.15020460609374997</izz>
				</inertia>
			</inertial>
			<collision name="collision">
				<geometry>
					<box>
						<size>0.295 0.3 0.295</size>
					</box>
				</geometry>
				<surface>
					<friction>
						<ode>
							<mu>0.6</mu>
							<mu2>0.6</mu2>
						</ode>
					</friction>
				</surface>
			</collision>
			<visual name="black">
				<geometry>
					<box>
						<size>0.295 0.3 0.295</size>
					</box>
				</geometry>
				<material>
					<diffuse>0 0 0 1</diffuse>
				</material>
			</visual>
			<visual name="red">
				<pose>-0.1475 0.0 0.0 0.0 0.0 0.0</pose>
				<geometry>
					<box>
						<size>0.0029 0.295 0.29</size>
					</box>
				</geometry>
				<material>
					<diffuse>1 0 0 1</diffuse>
				</material>
			</visual>
			<visual name="green">
				<pose>0.0 -0.15 0.0 0.0 0.0 0.0</pose>
				<geometry>
					<box>
						<size>0.29 0.00295 0.29</size>
					</box>
				</geometry>
				<material>
					<diffuse>0 1 0 1</diffuse>
				</material>
			</visual>
			<visual name="yellow">
				<pose>0.0 0.0 0.1475 0.0 0.0 0.0</pose>
				<geometry>
					<box>
						<size>0.29 0.295 0.0029</size>
					</box>
				</geometry>
				<material>
					<diffuse>1 1 0 1</diffuse>
				</material>
			</visual>
		</link>
		<joint name="ball_0_0_1" type="ball">
			<pose>0.14755 0.15005 -0.14755 -0.0 -0.0 -0.0</pose>
			<parent>center</parent>
			<child>cubie_0_0_1</child>
			<axis>
				<dynamics>
					<damping>0.1</damping>
				</dynamics>
				<limit>
					<effort>0</effort>
				</limit>
			</axis>
		</joint>
		<link name="cubie_0_1_0">
			<pose>-0.14755 0.15005 -0.15255 0.0 0.0 0.0</pose>
			<inertial>
				<mass>10.527075</mass>
				<inertia>
					<ixx>0.16055982515624997</ixx>
					<ixy>0.0</ixy>
					<ixz>0.0</ixz>
					<iyy>0.15794998781249997</iyy>
					<iyz>0.0</iyz>
					<izz>0.15529628765624998</izz>
				</inertia>
			</inertial>
			<collision name="collision">
				<geometry>
					<box>
						<size>0.295 0.3 0.305</size>
					</box>
				</geometry>
				<surface>
					<friction>
						<ode>
							<mu>0.6</mu>
							<mu2>0.6</mu2>
						</ode>
					</friction>
				</surface>
			</collision>
			<visual name="black">
				<geometry>
					<box>
						<size>0.295 0.3 0.305</size>
					</box>
				</geometry>
				<material>
					<diffuse>0 0 0 1</diffuse>
				</material>
			</visual>
			<visual name="red">
				<pose>-0.1475 0.0 0.0 0.0 0.0 0.0</pose>
				<geometry>
					<box>
						<size>0.0029 0.295 0.3</size>
					</box>
				</geometry>
				<material>
					<diffuse>1 0 0 1</diffuse>
				</material>
			</visual>
			<visual name="blue">
				<pose>0.0 0.15 0.0 0.0 0.0 0.0</pose>
				<geometry>
					<box>
						<size>0.29 0.00295 0.3</size>
					</box>
				</geometry>
				<material>
					<diffuse>0 0 1 1</diffuse>
				</material>
			</visual>
			<visual name="white">
				<pose>0.0 0.0 -0.1525 0.0 0.0 0.0</pose>
				<geometry>
					<box>
						<size>0.29 0.295 0.003</size>
					</box>
				</geometry>
				<material>
					<diffuse>1 1 1 1</diffuse>
				</material>
			</visual>
		</link>
		<joint name="ball_0_1_0" type="ball">
			<pose>0.14755 -0.15005 0.15255 -0.0 -0.0 -0.0</pose>
			<parent>center</parent>
			<child>cubie_0_1_0</child>
			<axis>
				<dynamics>
					<damping>0.1</damping>
				</dynamics>
				<limit>
					<effort>0</effort>
				</limit>
			</axis>
		</joint>
		<link name="cubie_0_1_1">
			<pose>-0.14755 0.15005 0.14755 0.0 0.0 0.0</pose>
			<inertial>
				<mass>10.181925</mass>
				<inertia>
					<ixx>0.15020460609374997</ixx>
					<ixy>0.0</ixy>
					<ixz>0.0</ixz>
					<iyy>0.14768033718749998</iyy>
					<iyz>0.0</iyz>
					<izz>0.15020460609374997</izz>
				</inertia>
			</inertial>
			<collision name="collision">
				<geometry>
					<box>
						<size>0.295 0.3 0.295</size>
					</box>
				</geometry>
				<surface>
					<friction>
						<ode>
							<mu>0.6</mu>
							<mu2>0.6</mu2>
						</ode>
					</friction>
				</surface>
			</collision>
			<visual name="black">
				<geometry>
					<box>
						<size>0.295 0.3 0.295</size>
					</box>
				</geometry>
				<material>
					<diffuse>0 0 0 1</diffuse>
				</material>
			</visual>
			<visual name="red">
				<pose>-0.1475 0.0 0.0 0.0 0.0 0.0</pose>
				<geometry>
					<box>
						<size>0.0029 0.295 0.29</size>
					</box>
				</geometry>
				<material>
					<diffuse>1 0 0 1</diffuse>
				</material>
			</visual>
			<visual name="blue">
				<pose>0.0 0.15 0.0 0.0 0.0 0.0</pose>
				<geometry>
					<box>
						<size>0.29 0.00295 0.29</size>
					</box>
				</geometry>
				<material>
					<diffuse>0 0 1 1</diffuse>
				</material>
			</visual>
			<visual name="yellow">
				<pose>0.0 0.0 0.1475 0.0 0.0 0.0</pose>
				<geometry>
					<box>
						<size>0.29 0.295 0.0029</size>
					</box>
				</geometry>
				<material>
					<diffuse>1 1 0 1</diffuse>
				</material>
			</visual>
		</link>
		<joint name="ball_0_1_1" type="ball">
			<pose>0.14755 -0.15005 -0.14755 -0.0 -0.0 -0.0</pose>
			<parent>center</parent>
			<child>cubie_0_1_1</child>
			<axis>
				<dynamics>
					<damping>0.1</damping>
				</dynamics>
				<limit>
					<effort>0</effort>
				</limit>
			</axis>
		</joint>
		<link name="cubie_1_0_0">
			<pose>0.15255 -0.15005 -0.15255 0.0 0.0 0.0</pose>
			<inertial>
				<mass>10.883925</mass>
				<inertia>
					<ixx>0.16600253109375</ixx>
					<ixy>0.0</ixy>
					<ixz>0.0</ixz>
					<iyy>0.16874618718749998</iyy>
					<iyz>0.0</iyz>
					<izz>0.16600253109375</izz>
				</inertia>
			</inertial>
			<collision name="collision">
				<geometry>
					<box>
						<size>0.305 0.3 0.305</size>
					</box>
				</geometry>
				<surface>
					<friction>
						<ode>
							<mu>0.6</mu>
							<mu2>0.6</mu2>
						</ode>
					</friction>
				</surface>
			</collision>
			<visual name="black">
				<geometry>
					<box>
						<size>0.305 0.3 0.305</size>
					</box>
				</geometry>
				<material>
					<diffuse>0 0 0 1</diffuse>
				</material>
			</visual>
			<visual name="orange">
				<pose>0.1525 0.0 0.0 0.0 0.0 0.0</pose>
				<geometry>
					<box>
						<size>0.003 0.295 0.3</size>
					</box>
				</geometry>
				<material>
					<diffuse>1.0 0.5 0.0 1.0</diffuse>
				</material>
			</visual>
			<visual name="green">
				<pose>0.0 -0.15 0.0 0.0 0.0 0.0</pose>
				<geometry>
					<box>
						<size>0.3 0.00295 0.3</size>
					</box>
				</geometry>
				<material>
					<diffuse>0 1 0 1</diffuse>
				</material>
			</visual>
			<visual name="white">
				<pose>0.0 0.0 -0.1525 0.0 0.0 0.0</pose>
				<geometry>
					<box>
						<size>0.3 0.295 0.003</size>
					</box>
				</geometry>
				<material>
					<diffuse>1 1 1 1</diffuse>
				</material>
			</visual>
		</link>
		<joint name="ball_1_0_0" type="ball">
			<pose>-0.15255 0.15005 0.15255 -0.0 -0.0 -0.0</pose>
			<parent>center</parent>
			<child>cubie_1_0_0</child>
			<axis>
				<dynamics>
					<damping>0.1</damping>
				</dynamics>
				<limit>
					<effort>0</effort>
				</limit>
			</axis>
		</joint>
		<link name="cubie_1_0_1">
			<pose>0.15255 -0.15005 0.14755 0.0 0.0 0.0</pose>
			<inertial>
				<mass>10.527075</mass>
				<inertia>
					<ixx>0.15529628765624998</ixx>
					<ixy>0.0</ixy>
					<ixz>0.0</ixz>
					<iyy>0.15794998781249997</iyy>
					<iyz>0.0</iyz>
					<izz>0.16055982515624997</izz>
				</inertia>
			</inertial>
			<collision name="collision">
				<geometry>
					<box>
						<size>0.305 0.3 0.295</size>
					</box>
				</geometry>
				<surface>
					<friction>
						<ode>
							<mu>0.6</mu>
							<mu2>0.6</mu2>
						</ode>
					</friction>
				</surface>
			</collision>
			<visual name="black">
				<geometry>
					<box>
						<size>0.305 0.3 0.295</size>
					</box>
				</geometry>
				<material>
					<diffuse>0 0 0 1</diffuse>
				</material>
			</visual>
			<visual name="orange">
				<pose>0.1525 0.0 0.0 0.0 0.0 0.0</pose>
				<geometry>
					<box>
						<size>0.003 0.295 0.29</size>
					</box>
				</geometry>
				<material>
					<diffuse>1.0 0.5 0.0 1.0</diffuse>
				</material>
			</visual>
			<visual name="green">
				<pose>0.0 -0.15 0.0 0.0 0.0 0.0</pose>
				<geometry>
					<box>
						<size>0.3 0.00295 0.29</size>
					</box>
				</geometry>
				<material>
					<diffuse>0 1 0 1</diffuse>
				</material>
			</visual>
			<visual name="yellow">
				<pose>0.0 0.0 0.1475 0.0 0.0 0.0</pose>
				<geometry>
					<box>
						<size>0.3 0.295 0.0029</size>
					</box>
				</geometry>
				<material>
					<diffuse>1 1 0 1</diffuse>
				</material>
			</visual>
		</link>
		<joint name="ball_1_0_1" type="ball">
			<pose>-0.15255 0.15005 -0.14755 -0.0 -0.0 -0.0</pose>
			<parent>center</parent>
			<child>cubie_1_0_1</child>
			<axis>
				<dynamics>
					<damping>0.1</damping>
				</dynamics>
				<limit>
					<effort>0</effort>
				</limit>
			</axis>
		</joint>
		<link name="cubie_1_1_0">
			<pose>0.15255 0.15005 -0.15255 0.0 0.0 0.0</pose>
			<inertial>
				<mass>10.883925</mass>
				<inertia>
					<ixx>0.16600253109375</ixx>
					<ixy>0.0</ixy>
					<ixz>0.0</ixz>
					<iyy>0.16874618718749998</iyy>
					<iyz>0.0</iyz>
					<izz>0.16600253109375</izz>
				</inertia>
			</inertial>
			<collision name="collision">
				<geometry>
					<box>
						<size>0.305 0.3 0.305</size>
					</box>
				</geometry>
				<surface>
					<friction>
						<ode>
							<mu>0.6</mu>
							<mu2>0.6</mu2>
						</ode>
					</friction>
				</surface>
			</collision>
			<visual name="black">
				<geometry>
					<box>
						<size>0.305 0.3 0.305</size>
					</box>
				</geometry>
				<material>
					<diffuse>0 0 0 1</diffuse>
				</material>
			</visual>
			<visual name="orange">
				<pose>0.1525 0.0 0.0 0.0 0.0 0.0</pose>
				<geometry>
					<box>
						<size>0.003 0.295 0.3</size>
					</box>
				</geometry>
				<material>
					<diffuse>1.0 0.5 0.0 1.0</diffuse>
				</material>
			</visual>
			<visual name="blue">
				<pose>0.0 0.15 0.0 0.0 0.0 0.0</pose>
				<geometry>
					<box>
						<size>0.3 0.00295 0.3</size>
					</box>
				</geometry>
				<material>
					<diffuse>0 0 1 1</diffuse>
				</material>
			</visual>
			<visual name="white">
				<pose>0.0 0.0 -0.1525 0.0 0.0 0.0</pose>
				<geometry>
					<box>
						<size>0.3 0.295 0.003</size>
					</box>
				</geometry>
				<material>
					<diffuse>1 1 1 1</diffuse>
				</material>
			</visual>
		</link>
		<joint name="ball_1_1_0" type="ball">
			<pose>-0.15255 -0.15005 0.15255 -0.0 -0.0 -0.0</pose>
			<parent>center</parent>
			<child>cubie_1_1_0</child>
			<axis>
				<dynamics>
					<damping>0.1</damping>
				</dynamics>
				<limit>
					<effort>0</effort>
				</limit>
			</axis>
		</joint>
		<link name="cubie_1_1_1">
			<pose>0.15255 0.15005 0.14755 0.0 0.0 0.0</pose>
			<inertial>
				<mass>10.527075</mass>
				<inertia>
					<ixx>0.15529628765624998</ixx>
					<ixy>0.0</ixy>
					<ixz>0.0</ixz>
					<iyy>0.15794998781249997</iyy>
					<iyz>0.0</iyz>
					<izz>0.16055982515624997</izz>
				</inertia>
			</inertial>
			<collision name="collision">
				<geometry>
					<box>
						<size>0.305 0.3 0.295</size>
					</box>
				</geometry>
				<surface>
					<friction>
						<ode>
							<mu>0.6</mu>
							<mu2>0.6</mu2>
						</ode>
					</friction>
				</surface>
			</collision>
			<visual name="black">
				<geometry>
					<box>
						<size>0.305 0.3 0.295</size>
					</box>
				</geometry>
				<material>
					<diffuse>0 0 0 1</diffuse>
				</material>
			</visual>
			<visual name="orange">
				<pose>0.1525 0.0 0.0 0.0 0.0 0.0</pose>
				<geometry>
					<box>
						<size>0.003 0.295 0.29</size>
					</box>
				</geometry>
				<material>
					<diffuse>1.0 0.5 0.0 1.0</diffuse>
				</material>
			</visual>
			<visual name="blue">
				<pose>0.0 0.15 0.0 0.0 0.0 0.0</pose>
				<geometry>
					<box>
						<size>0.3 0.00295 0.29</size>
					</box>
				</geometry>
				<material>
					<diffuse>0 0 1 1</diffuse>
				</material>
			</visual>
			<visual name="yellow">
				<pose>0.0 0.0 0.1475 0.0 0.0 0.0</pose>
				<geometry>
					<box>
						<size>0.3 0.295 0.0029</size>
					</box>
				</geometry>
				<material>
					<diffuse>1 1 0 1</diffuse>
				</material>
			</visual>
		</link>
		<joint name="ball_1_1_1" type="ball">
			<pose>-0.15255 -0.15005 -0.14755 -0.0 -0.0 -0.0</pose>
			<parent>center</parent>
			<child>cubie_1_1_1</child>
			<axis>
				<dynamics>
					<damping>0.1</damping>
				</dynamics>
				<limit>
					<effort>0</effort>
				</limit>
			</axis>
		</joint>
	</model>
</sdf>
