<?xml version="1.0" ?>
<sdf version="1.7">
	<model name="mirror_cube_2x2">
		<link name="center"/>
		<link name="cubie_0_0_0">
			<pose>-0.012549999999999999 -0.01505 -0.01755 0.0 0.0 0.0</pose>
			<inertial>
				<mass>0.010237499999999998</mass>
				<inertia>
					<ixx>1.8128906249999994e-06</ixx>
					<ixy>0.0</ixy>
					<ixz>0.0</ixz>
					<iyy>1.5782812499999993e-06</iyy>
					<iyz>0.0</iyz>
					<izz>1.3010156249999997e-06</izz>
				</inertia>
			</inertial>
			<collision name="collision">
				<geometry>
					<box>
						<size>0.024999999999999998 0.03 0.034999999999999996</size>
					</box>
				</geometry>
				<surface>
					<friction>
						<ode>
							<mu>0.6</mu>
							<mu2>0.6</mu2>
						</ode>
					</friction>
				</surface>
			</collision>
			<visual name="black">
				<geometry>
					<box>
						<size>0.024999999999999998 0.03 0.034999999999999996</size>
					</box>
				</geometry>
				<material>
					<diffuse>0 0 0 1</diffuse>
				</material>
			</visual>
			<visual name="red">
				<pose>-0.012499999999999999 0.0 0.0 0.0 0.0 0.0</pose>
				<geometry>
					<box>
						<size>0.0002 0.025 0.03</size>
					</box>
				</geometry>
				<material>
					<diffuse>1 0 0 1</diffuse>
				</material>
			</visual>
			<visual name="green">
				<pose>0.0 -0.015 0.0 0.0 0.0 0.0</pose>
				<geometry>
					<box>
						<size>0.02 0.00025 0.03</size>
					</box>
				</geometry>
				<material>
					<diffuse>0 1 0 1</diffuse>
				</material>
			</visual>
			<visual name="white">
				<pose>0.0 0.0 -0.017499999999999998 0.0 0.0 0.0</pose>
				<geometry>
					<box>
						<size>0.02 0.025 0.0003</size>
					</box>
				</geometry>
				<material>
					<diffuse>1 1 1 1</diffuse>
				</material>
			</visual>
		</link>
		<joint name="ball_0_0_0" type="ball">
			<pose>0.012549999999999999 0.01505 0.01755 -0.0 -0.0 -0.0</pose>
			<parent>center</parent>
			<child>cubie_0_0_0</child>
			<axis>
				<dynamics>
					<damping>0.1</damping>
				</dynamics>
				<limit>
					<effort>0</effort>
				</limit>
			</axis>
		</joint>
		<link name="cubie_0_0_1">
			<pose>-0.012549999999999999 -0.01505 0.01255 0.0 0.0 0.0</pose>
			<inertial>
				<mass>0.0073124999999999996</mass>
				<inertia>
					<ixx>9.29296875e-07</ixx>
					<ixy>0.0</ixy>
					<ixz>0.0</ixz>
					<iyy>7.6171875e-07</iyy>
					<iyz>0.0</iyz>
					<izz>9.292968749999999e-07</izz>
				</inertia>
			</inertial>
			<collision name="collision">
				<geometry>
					<box>
						<size>0.024999999999999998 0.03 0.025</size>
					</box>
				</geometry>
				<surface>
					<friction>
						<ode>
							<mu>0.6</mu>
							<mu2>0.6</mu2>
						</ode>
					</friction>
				</surface>
			</collision>
			<visual name="black">
				<geometry>
					<box>
						<size>0.024999999999999998 0.03 0.025</size>
					</box>
				</geometry>
				<material>
					<diffuse>0 0 0 1</diffuse>
				</material>
			</visual>
			<visual name="red">
				<pose>-0.012499999999999999 0.0 0.0 0.0 0.0 0.0</pose>
				<geometry>
					<box>
						<size>0.0002 0.025 0.02</size>
					</box>
				</geometry>
				<material>
					<diffuse>1 0 0 1</diffuse>
				</material>
			</visual>
			<visual name="green">
				<pose>0.0 -0.015 0.0 0.0 0.0 0.0</pose>
				<geometry>
					<box>
						<size>0.02 0.00025 0.02</size>
					</box>
				</geometry>
				<material>
					<diffuse>0 1 0 1</diffuse>
				</material>
			</visual>
			<visual name="yellow">
				<pose>0.0 0.0 0.0125 0.0 0.0 0.0</pose>
				<geometry>
					<box>
						<size>0.02 0.025 0.0002</size>
					</box>
				</geometry>
				<material>
					<diffuse>1 1 0 1</diffuse>
				</material>
			</visual>
		</link>
		<joint name="ball_0_0_1" type="ball">
			<pose>0.012549999999999999 0.01505 -0.01255 -0.0 -0.0 -0.0</pose>
			<parent>center</parent>
			<child>cubie_0_0_1</child>
			<axis>
				<dynamics>
					<damping>0.1</damping>
				</dynamics>
				<limit>
					<effort>0</effort>
				</limit>
			</axis>
		</joint>
		<link name="cubie_0_1_0">
			<pose>-0.012549999999999999 0.01505 -0.01755 0.0 0.0 0.0</pose>
			<inertial>
				<mass>0.010237499999999998</mass>
				<inertia>
					<ixx>1.8128906249999994e-06</ixx>
					<ixy>0.0</ixy>
					<ixz>0.0</ixz>
					<iyy>1.5782812499999993e-06</iyy>
					<iyz>0.0</iyz>
					<izz>1.3010156249999997e-06</izz>
				</inertia>
			</inertial>
			<collision name="collision">
				<geometry>
					<box>
						<size>0.024999999999999998 0.03 0.034999999999999996</size>
					</box>
				</geometry>
				<surface>
					<friction>
						<ode>
							<mu>0.6</mu>
							<mu2>0.6</mu2>
						</ode>
					</friction>
				</surface>
			</collision>
			<visual name="black">
				<geometry>
					<box>
						<size>0.024999999999999998 0.03 0.034999999999999996</size>
					</box>
				</geometry>
				<material>
					<diffuse>0 0 0 1</diffuse>
				</material>
			</visual>
			<visual name="red">
				<pose>-0.012499999999999999 0.0 0.0 0.0 0.0 0.0</pose>
				<geometry>
					<box>
						<size>0.0002 0.025 0.03</size>
					</box>
				</geometry>
				<material>
					<diffuse>1 0 0 1</diffuse>
				</material>
			</visual>
			<visual name="blue">
				<pose>0.0 0.015 0.0 0.0 0.0 0.0</pose>
				<geometry>
					<box>
						<size>0.02 0.00025 0.03</size>
					</box>
				</geometry>
				<material>
					<diffuse>0 0 1 1</diffuse>
				</material>
			</visual>
			<visual name="white">
				<pose>0.0 0.0 -0.017499999999999998 0.0 0.0 0.0</pose>
				<geometry>
					<box>
						<size>0.02 0.025 0.0003</size>
					</box>
				</geometry>
				<material>
					<diffuse>1 1 1 1</diffuse>
				</material>
			</visual>
		</link>
		<joint name="ball_0_1_0" type="ball">
			<pose>0.012549999999999999 -0.01505 0.01755 -0.0 -0.0 -0.0</pose>
			<parent>center</parent>
			<child>cubie_0_1_0</child>
			<axis>
				<dynamics>
					<damping>0.1</damping>
				</dynamics>
				<limit>
					<effort>0</effort>
				</limit>
			</axis>
		</joint>
		<link name="cubie_0_1_1">
			<pose>-0.012549999999999999 0.01505 0.01255 0.0 0.0 0.0</pose>
			<inertial>
				<mass>0.0073124999999999996</mass>
				<inertia>
					<ixx>9.29296875e-07</ixx>
					<ixy>0.0</ixy>
					<ixz>0.0</ixz>
					<iyy>7.6171875e-07</iyy>
					<iyz>0.0</iyz>
					<izz>9.292968749999999e-07</izz>
				</inertia>
			</inertial>
			<collision name="collision">
				<geometry>
					<box>
						<size>0.024999999999999998 0.03 0.025</size>
					</box>
				</geometry>
				<surface>
					<friction>
						<ode>
							<mu>0.6</mu>
							<mu2>0.6</mu2>
						</ode>
					</friction>
				</surface>
			</collision>
			<visual name="black">
				<geometry>
					<box>
						<size>0.024999999999999998 0.03 0.025</size>
					</box>
				</geometry>
				<material>
					<diffuse>0 0 0 1</diffuse>
				</material>
			</visual>
			<visual name="red">
				<pose>-0.012499999999999999 0.0 0.0 0.0 0.0 0.0</pose>
				<geometry>
					<box>
						<size>0.0002 0.025 0.02</size>
					</box>
				</geometry>
				<material>
					<diffuse>1 0 0 1</diffuse>
				</material>
			</visual>
			<visual name="blue">
				<pose>0.0 0.015 0.0 0.0 0.0 0.0</pose>
				<geometry>
					<box>
						<size>0.02 0.00025 0.02</size>
					</box>
				</geometry>
				<material>
					<diffuse>0 0 1 1</diffuse>
				</material>
			</visual>
			<visual name="yellow">
				<pose>0.0 0.0 0.0125 0.0 0.0 0.0</pose>
				<geometry>
					<box>
						<size>0.02 0.025 0.0002</size>
					</box>
				</geometry>
				<material>
					<diffuse>1 1 0 1</diffuse>
				</material>
			</visual>
		</link>
		<joint name="ball_0_1_1" type="ball">
			<pose>0.012549999999999999 -0.01505 -0.01255 -0.0 -0.0 -0.0</pose>
			<parent>center</parent>
			<child>cubie_0_1_1</child>
			<axis>
				<dynamics>
					<damping>0.1</damping>
				</dynamics>
				<limit>
					<effort>0</effort>
				</limit>
			</axis>
		</joint>
		<link name="cubie_1_0_0">
			<pose>0.017550000000000003 -0.01505 -0.01755 0.0 0.0 0.0</pose>
			<inertial>
				<mass>0.0143325</mass>
				<inertia>
					<ixx>2.5380468749999996e-06</ixx>
					<ixy>0.0</ixy>
					<ixz>0.0</ixz>
					<iyy>2.9262187499999997e-06</iyy>
					<iyz>0.0</iyz>
					<izz>2.538046875e-06</izz>
				</inertia>
			</inertial>
			<collision name="collision">
				<geometry>
					<box>
						<size>0.035 0.03 0.034999999999999996</size>
					</box>
				</geometry>
				<surface>
					<friction>
						<ode>
							<mu>0.6</mu>
							<mu2>0.6</mu2>
						</ode>
					</friction>
				</surface>
			</collision>
			<visual name="black">
				<geometry>
					<box>
						<size>0.035 0.03 0.034999999999999996</size>
					</box>
				</geometry>
				<material>
					<diffuse>0 0 0 1</diffuse>
				</material>
			</visual>
			<visual name="orange">
				<pose>0.0175 0.0 0.0 0.0 0.0 0.0</pose>
				<geometry>
					<box>
						<size>0.0003 0.025 0.03</size>
					</box>
				</geometry>
				<material>
					<diffuse>1.0 0.5 0.0 1.0</diffuse>
				</material>
			</visual>
			<visual name="green">
				<pose>0.0 -0.015 0.0 0.0 0.0 0.0</pose>
				<geometry>
					<box>
						<size>0.03 0.00025 0.03</size>
					</box>
				</geometry>
				<material>
					<diffuse>0 1 0 1</diffuse>
				</material>
			</visual>
			<visual name="white">
				<pose>0.0 0.0 -0.017499999999999998 0.0 0.0 0.0</pose>
				<geometry>
					<box>
						<size>0.03 0.025 0.0003</size>
					</box>
				</geometry>
				<material>
					<diffuse>1 1 1 1</diffuse>
				</material>
			</visual>
		</link>
		<joint name="ball_1_0_0" type="ball">
			<pose>-0.017550000000000003 0.01505 0.01755 -0.0 -0.0 -0.0</pose>
			<parent>center</parent>
			<child>cubie_1_0_0</child>
			<axis>
				<dynamics>
					<damping>0.1</damping>
				</dynamics>
				<limit>
					<effort>0</effort>
				</limit>
			</axis>
		</joint>
		<link name="cubie_1_0_1">
			<pose>0.017550000000000003 -0.01505 0.01255 0.0 0.0 0.0</pose>
			<inertial>
				<mass>0.010237500000000002</mass>
				<inertia>
					<ixx>1.3010156250000004e-06</ixx>
					<ixy>0.0</ixy>
					<ixz>0.0</ixz>
					<iyy>1.5782812500000006e-06</iyy>
					<iyz>0.0</iyz>
					<izz>1.8128906250000004e-06</izz>
				</inertia>
			</inertial>
			<collision name="collision">
				<geometry>
					<box>
						<size>0.035 0.03 0.025</size>
					</box>
				</geometry>
				<surface>
					<friction>
						<ode>
							<mu>0.6</mu>
							<mu2>0.6</mu2>
						</ode>
					</friction>
				</surface>
			</collision>
			<visual name="black">
				<geometry>
					<box>
						<size>0.035 0.03 0.025</size>
					</box>
				</geometry>
				<material>
					<diffuse>0 0 0 1</diffuse>
				</material>
			</visual>
			<visual name="orange">
				<pose>0.0175 0.0 0.0 0.0 0.0 0.0</pose>
				<geometry>
					<box>
						<size>0.0003 0.025 0.02</size>
					</box>
				</geometry>
				<material>
					<diffuse>1.0 0.5 0.0 1.0</diffuse>
				</material>
			</visual>
			<visual name="green">
				<pose>0.0 -0.015 0.0 0.0 0.0 0.0</pose>
				<geometry>
					<box>
						<size>0.03 0.00025 0.02</size>
					</box>
				</geometry>
				<material>
					<diffuse>0 1 0 1</diffuse>
				</material>
			</visual>
			<visual name="yellow">
				<pose>0.0 0.0 0.0125 0.0 0.0 0.0</pose>
				<geometry>
					<box>
						<size>0.03 0.025 0.0002</size>
					</box>
				</geometry>
				<material>
					<diffuse>1 1 0 1</diffuse>
				</material>
			</visual>
		</link>
		<joint name="ball_1_0_1" type="ball">
			<pose>-0.017550000000000003 0.01505 -0.01255 -0.0 -0.0 -0.0</pose>
			<parent>center</parent>
			<child>cubie_1_0_1</child>
			<axis>
				<dynamics>
					<damping>0.1</damping>
				</dynamics>
				<limit>
					<effort>0</effort>
				</limit>
			</axis>
		</joint>
		<link name="cubie_1_1_0">
			<pose>0.017550000000000003 0.01505 -0.01755 0.0 0.0 0.0</pose>
			<inertial>
				<mass>0.0143325</mass>
				<inertia>
					<ixx>2.5380468749999996e-06</ixx>
					<ixy>0.0</ixy>
					<ixz>0.0</ixz>
					<iyy>2.9262187499999997e-06</iyy>
					<iyz>0.0</iyz>
					<izz>2.538046875e-06</izz>
				</inertia>
			</inertial>
			<collision name="collision">
				<geometry>
					<box>
						<size>0.035 0.03 0.034999999999999996</size>
					</box>
				</geometry>
				<surface>
					<friction>
						<ode>
							<mu>0.6</mu>
							<mu2>0.6</mu2>
						</ode>
					</friction>
				</surface>
			</collision>
			<visual name="black">
				<geometry>
					<box>
						<size>0.035 0.03 0.034999999999999996</size>
					</box>
				</geometry>
				<material>
					<diffuse>0 0 0 1</diffuse>
				</material>
			</visual>
			<visual name="orange">
				<pose>0.0175 0.0 0.0 0.0 0.0 0.0</pose>
				<geometry>
					<box>
						<size>0.0003 0.025 0.03</size>
					</box>
				</geometry>
				<material>
					<diffuse>1.0 0.5 0.0 1.0</diffuse>
				</material>
			</visual>
			<visual name="blue">
				<pose>0.0 0.015 0.0 0.0 0.0 0.0</pose>
				<geometry>
					<box>
						<size>0.03 0.00025 0.03</size>
					</box>
				</geometry>
				<material>
					<diffuse>0 0 1 1</diffuse>
				</material>
			</visual>
			<visual name="white">
				<pose>0.0 0.0 -0.017499999999999998 0.0 0.0 0.0</pose>
				<geometry>
					<box>
						<size>0.03 0.025 0.0003</size>
					</box>
				</geometry>
				<material>
					<diffuse>1 1 1 1</diffuse>
				</material>
			</visual>
		</link>
		<joint name="ball_1_1_0" type="ball">
			<pose>-0.017550000000000003 -0.01505 0.01755 -0.0 -0.0 -0.0</pose>
			<parent>center</parent>
			<child>cubie_1_1_0</child>
			<axis>
				<dynamics>
					<damping>0.1</damping>
				</dynamics>
				<limit>
					<effort>0</effort>
				</limit>
			</axis>
		</joint>
		<link name="cubie_1_1_1">
			<pose>0.017550000000000003 0.01505 0.01255 0.0 0.0 0.0</pose>
			<inertial>
				<mass>0.010237500000000002</mass>
				<inertia>
					<ixx>1.3010156250000004e-06</ixx>
					<ixy>0.0</ixy>
					<ixz>0.0</ixz>
					<iyy>1.5782812500000006e-06</iyy>
					<iyz>0.0</iyz>
					<izz>1.8128906250000004e-06</izz>
				</inertia>
			</inertial>
			<collision name="collision">
				<geometry>
					<box>
						<size>0.035 0.03 0.025</size>
					</box>
				</geometry>
				<surface>
					<friction>
						<ode>
							<mu>0.6</mu>
							<mu2>0.6</mu2>
						</ode>
					</friction>
				</surface>
			</collision>
			<visual name="black">
				<geometry>
					<box>
						<size>0.035 0.03 0.025</size>
					</box>
				</geometry>
				<material>
					<diffuse>0 0 0 1</diffuse>
				</material>
			</visual>
			<visual name="orange">
				<pose>0.0175 0.0 0.0 0.0 0.0 0.0</pose>
				<geometry>
					<box>
						<size>0.0003 0.025 0.02</size>
					</box>
				</geometry>
				<material>
					<diffuse>1.0 0.5 0.0 1.0</diffuse>
				</material>
			</visual>
			<visual name="blue">
				<pose>0.0 0.015 0.0 0.0 0.0 0.0</pose>
				<geometry>
					<box>
						<size>0.03 0.00025 0.02</size>
					</box>
				</geometry>
				<material>
					<diffuse>0 0 1 1</diffuse>
				</material>
			</visual>
			<visual name="yellow">
				<pose>0.0 0.0 0.0125 0.0 0.0 0.0</pose>
				<geometry>
					<box>
						<size>0.03 0.025 0.0002</size>
					</box>
				</geometry>
				<material>
					<diffuse>1 1 0 1</diffuse>
				</material>
			</visual>
		</link>
		<joint name="ball_1_1_1" type="ball">
			<pose>-0.017550000000000003 -0.01505 -0.01255 -0.0 -0.0 -0.0</pose>
			<parent>center</parent>
			<child>cubie_1_1_1</child>
			<axis>
				<dynamics>
					<damping>0.1</damping>
				</dynamics>
				<limit>
					<effort>0</effort>
				</limit>
			</axis>
		</joint>
	</model>
</sdf>
