<?xml version="1.0" ?>
<sdf version="1.7">
	<model name="mirror_cube_2x2">
		<link name="center"/>
		<link name="cubie_0_0_0">
			<pose>-0.025 -0.025 -0.025 0.0 0.0 0.0</pose>
			<inertial>
				<mass>166.27687752661225</mass>
				<inertia>
					<ixx>0.06928203230275512</ixx>
					<ixy>0.0</ixy>
					<ixz>0.0</ixz>
					<iyy>0.06928203230275512</iyy>
					<iyz>0.0</iyz>
					<izz>0.06928203230275512</izz>
				</inertia>
			</inertial>
			<collision name="collision">
				<geometry>
					<box>
						<size>0.05 0.05 0.05</size>
					</box>
				</geometry>
			</collision>
			<visual name="silver">
				<geometry>
					<box>
						<size>0.05 0.05 0.05</size>
					</box>
				</geometry>
				<material>
					<diffuse>0.7529411764705882 0.7529411764705882 0.7529411764705882 1.0</diffuse>
				</material>
			</visual>
		</link>
		<joint name="ball_0_0_0" type="ball">
			<pose>0.025 0.025 0.025 -0.0 -0.0 -0.0</pose>
			<parent>center</parent>
			<child>cubie_0_0_0</child>
			<axis>
				<dynamics>
					<damping>0.1</damping>
				</dynamics>
				<limit>
					<effort>0</effort>
				</limit>
			</axis>
		</joint>
		<link name="cubie_0_0_1">
			<pose>-0.025 -0.025 0.025 0.0 0.0 0.0</pose>
			<inertial>
				<mass>166.27687752661225</mass>
				<inertia>
					<ixx>0.06928203230275512</ixx>
					<ixy>0.0</ixy>
					<ixz>0.0</ixz>
					<iyy>0.06928203230275512</iyy>
					<iyz>0.0</iyz>
					<izz>0.06928203230275512</izz>
				</inertia>
			</inertial>
			<collision name="collision">
				<geometry>
					<box>
						<size>0.05 0.05 0.05</size>
					</box>
				</geometry>
			</collision>
			<visual name="silver">
				<geometry>
					<box>
						<size>0.05 0.05 0.05</size>
					</box>
				</geometry>
				<material>
					<diffuse>0.7529411764705882 0.7529411764705882 0.7529411764705882 1.0</diffuse>
				</material>
			</visual>
		</link>
		<joint name="ball_0_0_1" type="ball">
			<pose>0.025 0.025 -0.025 -0.0 -0.0 -0.0</pose>
			<parent>center</parent>
			<child>cubie_0_0_1</child>
			<axis>
				<dynamics>
					<damping>0.1</damping>
				</dynamics>
				<limit>
					<effort>0</effort>
				</limit>
			</axis>
		</joint>
		<link name="cubie_0_1_0">
			<pose>-0.025 0.025 -0.025 0.0 0.0 0.0</pose>
			<inertial>
				<mass>166.27687752661225</mass>
				<inertia>
					<ixx>0.06928203230275512</ixx>
					<ixy>0.0</ixy>
					<ixz>0.0</ixz>
					<iyy>0.06928203230275512</iyy>
					<iyz>0.0</iyz>
					<izz>0.06928203230275512</izz>
				</inertia>
			</inertial>
			<collision name="collision">
				<geometry>
					<box>
						<size>0.05 0.05 0.05</size>
					</box>
				</geometry>
			</collision>
			<visual name="silver">
				<geometry>
					<box>
						<size>0.05 0.05 0.05</size>
					</box>
				</geometry>
				<material>
					<diffuse>0.7529411764705882 0.7529411764705882 0.7529411764705882 1.0</diffuse>
				</material>
			</visual>
		</link>
		<joint name="ball_0_1_0" type="ball">
			<pose>0.025 -0.025 0.025 -0.0 -0.0 -0.0</pose>
			<parent>center</parent>
			<child>cubie_0_1_0</child>
			<axis>
				<dynamics>
					<damping>0.1</damping>
				</dynamics>
				<limit>
					<effort>0</effort>
				</limit>
			</axis>
		</joint>
		<link name="cubie_0_1_1">
			<pose>-0.025 0.025 0.025 0.0 0.0 0.0</pose>
			<inertial>
				<mass>166.27687752661225</mass>
				<inertia>
					<ixx>0.06928203230275512</ixx>
					<ixy>0.0</ixy>
					<ixz>0.0</ixz>
					<iyy>0.06928203230275512</iyy>
					<iyz>0.0</iyz>
					<izz>0.06928203230275512</izz>
				</inertia>
			</inertial>
			<collision name="collision">
				<geometry>
					<box>
						<size>0.05 0.05 0.05</size>
					</box>
				</geometry>
			</collision>
			<visual name="silver">
				<geometry>
					<box>
						<size>0.05 0.05 0.05</size>
					</box>
				</geometry>
				<material>
					<diffuse>0.7529411764705882 0.7529411764705882 0.7529411764705882 1.0</diffuse>
				</material>
			</visual>
		</link>
		<joint name="ball_0_1_1" type="ball">
			<pose>0.025 -0.025 -0.025 -0.0 -0.0 -0.0</pose>
			<parent>center</parent>
			<child>cubie_0_1_1</child>
			<axis>
				<dynamics>
					<damping>0.1</damping>
				</dynamics>
				<limit>
					<effort>0</effort>
				</limit>
			</axis>
		</joint>
		<link name="cubie_1_0_0">
			<pose>0.025 -0.025 -0.025 0.0 0.0 0.0</pose>
			<inertial>
				<mass>166.27687752661225</mass>
				<inertia>
					<ixx>0.06928203230275512</ixx>
					<ixy>0.0</ixy>
					<ixz>0.0</ixz>
					<iyy>0.06928203230275512</iyy>
					<iyz>0.0</iyz>
					<izz>0.06928203230275512</izz>
				</inertia>
			</inertial>
			<collision name="collision">
				<geometry>
					<box>
						<size>0.05 0.05 0.05</size>
					</box>
				</geometry>
			</collision>
			<visual name="silver">
				<geometry>
					<box>
						<size>0.05 0.05 0.05</size>
					</box>
				</geometry>
				<material>
					<diffuse>0.7529411764705882 0.7529411764705882 0.7529411764705882 1.0</diffuse>
				</material>
			</visual>
		</link>
		<joint name="ball_1_0_0" type="ball">
			<pose>-0.025 0.025 0.025 -0.0 -0.0 -0.0</pose>
			<parent>center</parent>
			<child>cubie_1_0_0</child>
			<axis>
				<dynamics>
					<damping>0.1</damping>
				</dynamics>
				<limit>
					<effort>0</effort>
				</limit>
			</axis>
		</joint>
		<link name="cubie_1_0_1">
			<pose>0.025 -0.025 0.025 0.0 0.0 0.0</pose>
			<inertial>
				<mass>166.27687752661225</mass>
				<inertia>
					<ixx>0.06928203230275512</ixx>
					<ixy>0.0</ixy>
					<ixz>0.0</ixz>
					<iyy>0.06928203230275512</iyy>
					<iyz>0.0</iyz>
					<izz>0.06928203230275512</izz>
				</inertia>
			</inertial>
			<collision name="collision">
				<geometry>
					<box>
						<size>0.05 0.05 0.05</size>
					</box>
				</geometry>
			</collision>
			<visual name="silver">
				<geometry>
					<box>
						<size>0.05 0.05 0.05</size>
					</box>
				</geometry>
				<material>
					<diffuse>0.7529411764705882 0.7529411764705882 0.7529411764705882 1.0</diffuse>
				</material>
			</visual>
		</link>
		<joint name="ball_1_0_1" type="ball">
			<pose>-0.025 0.025 -0.025 -0.0 -0.0 -0.0</pose>
			<parent>center</parent>
			<child>cubie_1_0_1</child>
			<axis>
				<dynamics>
					<damping>0.1</damping>
				</dynamics>
				<limit>
					<effort>0</effort>
				</limit>
			</axis>
		</joint>
		<link name="cubie_1_1_0">
			<pose>0.025 0.025 -0.025 0.0 0.0 0.0</pose>
			<inertial>
				<mass>166.27687752661225</mass>
				<inertia>
					<ixx>0.06928203230275512</ixx>
					<ixy>0.0</ixy>
					<ixz>0.0</ixz>
					<iyy>0.06928203230275512</iyy>
					<iyz>0.0</iyz>
					<izz>0.06928203230275512</izz>
				</inertia>
			</inertial>
			<collision name="collision">
				<geometry>
					<box>
						<size>0.05 0.05 0.05</size>
					</box>
				</geometry>
			</collision>
			<visual name="silver">
				<geometry>
					<box>
						<size>0.05 0.05 0.05</size>
					</box>
				</geometry>
				<material>
					<diffuse>0.7529411764705882 0.7529411764705882 0.7529411764705882 1.0</diffuse>
				</material>
			</visual>
		</link>
		<joint name="ball_1_1_0" type="ball">
			<pose>-0.025 -0.025 0.025 -0.0 -0.0 -0.0</pose>
			<parent>center</parent>
			<child>cubie_1_1_0</child>
			<axis>
				<dynamics>
					<damping>0.1</damping>
				</dynamics>
				<limit>
					<effort>0</effort>
				</limit>
			</axis>
		</joint>
		<link name="cubie_1_1_1">
			<pose>0.025 0.025 0.025 0.0 0.0 0.0</pose>
			<inertial>
				<mass>166.27687752661225</mass>
				<inertia>
					<ixx>0.06928203230275512</ixx>
					<ixy>0.0</ixy>
					<ixz>0.0</ixz>
					<iyy>0.06928203230275512</iyy>
					<iyz>0.0</iyz>
					<izz>0.06928203230275512</izz>
				</inertia>
			</inertial>
			<collision name="collision">
				<geometry>
					<box>
						<size>0.05 0.05 0.05</size>
					</box>
				</geometry>
			</collision>
			<visual name="silver">
				<geometry>
					<box>
						<size>0.05 0.05 0.05</size>
					</box>
				</geometry>
				<material>
					<diffuse>0.7529411764705882 0.7529411764705882 0.7529411764705882 1.0</diffuse>
				</material>
			</visual>
		</link>
		<joint name="ball_1_1_1" type="ball">
			<pose>-0.025 -0.025 -0.025 -0.0 -0.0 -0.0</pose>
			<parent>center</parent>
			<child>cubie_1_1_1</child>
			<axis>
				<dynamics>
					<damping>0.1</damping>
				</dynamics>
				<limit>
					<effort>0</effort>
				</limit>
			</axis>
		</joint>
	</model>
</sdf>
